Workbook

Sheet DealScope pricing unit economic
A1: DealScope pricing unit economics
A2: DealScope — Pricing and sensitivity · Growth
A4: Variable / dimension | B4: Customer monthly earned revenue | C4: Customer monthly delivered audits | D4: Revenue per delivered audit | E4: Unit gross profit | F4: Unit gross margin | G4: Unit contribution profit | H4: Unit contribution margin
A5: Annual deal-team | B5: =IF(EXACT("Annual deal-team","Annual deal-team"),('Model inputs'!B45/12+MAX('Model inputs'!B14*'Model inputs'!B7-'Model inputs'!B24/12,0)*'Model inputs'!B32)*(1-'Model inputs'!B37),('Model inputs'!B45/12+'Model inputs'!B9*'Model inputs'!B14)*(1-'Model inputs'!B37)) -> 4000 | C5: ='Model inputs'!B14*IF(IF(EXACT("Annual deal-team","Annual deal-team"),IF('Model inputs'!B7="","",'Model inputs'!B7),1)="",0,IF(EXACT("Annual deal-team","Annual deal-team"),IF('Model inputs'!B7="","",'Model inputs'!B7),1)) -> 4 | D5: =IFERROR('DealScope pricing unit economic'!B5/'DealScope pricing unit economic'!C5,"") -> 1000 | E5: ='DealScope pricing unit economic'!D5-'Model inputs'!B18 -> 905.35 | F5: =IFERROR('DealScope pricing unit economic'!E5/'DealScope pricing unit economic'!D5,"") -> 0.90535 | G5: ='DealScope pricing unit economic'!E5-'DealScope pricing unit economic'!D5*'Model inputs'!B38-IFERROR('Model inputs'!B42*'Model inputs'!B41/'DealScope pricing unit economic'!C5,0) -> 867.85 | H5: =IFERROR('DealScope pricing unit economic'!G5/'DealScope pricing unit economic'!D5,"") -> 0.86785
A6: Hybrid | B6: =IF(EXACT("Hybrid","Annual deal-team"),('Model inputs'!B46/12+MAX('Model inputs'!B14*'Model inputs'!B7-'Model inputs'!B25/12,0)*'Model inputs'!B33)*(1-'Model inputs'!B37),('Model inputs'!B46/12+'Model inputs'!B10*'Model inputs'!B14)*(1-'Model inputs'!B37)) -> 4500 | C6: ='Model inputs'!B14*IF(IF(EXACT("Hybrid","Annual deal-team"),IF('Model inputs'!B7="","",'Model inputs'!B7),1)="",0,IF(EXACT("Hybrid","Annual deal-team"),IF('Model inputs'!B7="","",'Model inputs'!B7),1)) -> 4 | D6: =IFERROR('DealScope pricing unit economic'!B6/'DealScope pricing unit economic'!C6,"") -> 1125 | E6: ='DealScope pricing unit economic'!D6-'Model inputs'!B18 -> 1030.35 | F6: =IFERROR('DealScope pricing unit economic'!E6/'DealScope pricing unit economic'!D6,"") -> 0.91586667 | G6: ='DealScope pricing unit economic'!E6-'DealScope pricing unit economic'!D6*'Model inputs'!B38-IFERROR('Model inputs'!B42*'Model inputs'!B41/'DealScope pricing unit economic'!C6,0) -> 989.1 | H6: =IFERROR('DealScope pricing unit economic'!G6/'DealScope pricing unit economic'!D6,"") -> 0.8792
A7: Per audit — base | B7: =IF(EXACT("Per audit — base","Annual deal-team"),('Model inputs'!B47/12+MAX('Model inputs'!B14*'Model inputs'!B7-'Model inputs'!B26/12,0)*'Model inputs'!B34)*(1-'Model inputs'!B37),('Model inputs'!B47/12+'Model inputs'!B11*'Model inputs'!B14)*(1-'Model inputs'!B37)) -> 6000 | C7: ='Model inputs'!B14*IF(IF(EXACT("Per audit — base","Annual deal-team"),IF('Model inputs'!B7="","",'Model inputs'!B7),1)="",0,IF(EXACT("Per audit — base","Annual deal-team"),IF('Model inputs'!B7="","",'Model inputs'!B7),1)) -> 4 | D7: =IFERROR('DealScope pricing unit economic'!B7/'DealScope pricing unit economic'!C7,"") -> 1500 | E7: ='DealScope pricing unit economic'!D7-'Model inputs'!B18 -> 1405.35 | F7: =IFERROR('DealScope pricing unit economic'!E7/'DealScope pricing unit economic'!D7,"") -> 0.9369 | G7: ='DealScope pricing unit economic'!E7-'DealScope pricing unit economic'!D7*'Model inputs'!B38-IFERROR('Model inputs'!B42*'Model inputs'!B41/'DealScope pricing unit economic'!C7,0) -> 1352.85 | H7: =IFERROR('DealScope pricing unit economic'!G7/'DealScope pricing unit economic'!D7,"") -> 0.9019
A8: Per audit — high | B8: =IF(EXACT("Per audit — high","Annual deal-team"),('Model inputs'!B48/12+MAX('Model inputs'!B14*'Model inputs'!B7-'Model inputs'!B27/12,0)*'Model inputs'!B35)*(1-'Model inputs'!B37),('Model inputs'!B48/12+'Model inputs'!B12*'Model inputs'!B14)*(1-'Model inputs'!B37)) -> 12000 | C8: ='Model inputs'!B14*IF(IF(EXACT("Per audit — high","Annual deal-team"),IF('Model inputs'!B7="","",'Model inputs'!B7),1)="",0,IF(EXACT("Per audit — high","Annual deal-team"),IF('Model inputs'!B7="","",'Model inputs'!B7),1)) -> 4 | D8: =IFERROR('DealScope pricing unit economic'!B8/'DealScope pricing unit economic'!C8,"") -> 3000 | E8: ='DealScope pricing unit economic'!D8-'Model inputs'!B18 -> 2905.35 | F8: =IFERROR('DealScope pricing unit economic'!E8/'DealScope pricing unit economic'!D8,"") -> 0.96845 | G8: ='DealScope pricing unit economic'!E8-'DealScope pricing unit economic'!D8*'Model inputs'!B38-IFERROR('Model inputs'!B42*'Model inputs'!B41/'DealScope pricing unit economic'!C8,0) -> 2807.85 | H8: =IFERROR('DealScope pricing unit economic'!G8/'DealScope pricing unit economic'!D8,"") -> 0.93595
A9: Per audit — low | B9: =IF(EXACT("Per audit — low","Annual deal-team"),('Model inputs'!B49/12+MAX('Model inputs'!B14*'Model inputs'!B7-'Model inputs'!B28/12,0)*'Model inputs'!B36)*(1-'Model inputs'!B37),('Model inputs'!B49/12+'Model inputs'!B13*'Model inputs'!B14)*(1-'Model inputs'!B37)) -> 3000 | C9: ='Model inputs'!B14*IF(IF(EXACT("Per audit — low","Annual deal-team"),IF('Model inputs'!B7="","",'Model inputs'!B7),1)="",0,IF(EXACT("Per audit — low","Annual deal-team"),IF('Model inputs'!B7="","",'Model inputs'!B7),1)) -> 4 | D9: =IFERROR('DealScope pricing unit economic'!B9/'DealScope pricing unit economic'!C9,"") -> 750 | E9: ='DealScope pricing unit economic'!D9-'Model inputs'!B18 -> 655.35 | F9: =IFERROR('DealScope pricing unit economic'!E9/'DealScope pricing unit economic'!D9,"") -> 0.8738 | G9: ='DealScope pricing unit economic'!E9-'DealScope pricing unit economic'!D9*'Model inputs'!B38-IFERROR('Model inputs'!B42*'Model inputs'!B41/'DealScope pricing unit economic'!C9,0) -> 625.35 | H9: =IFERROR('DealScope pricing unit economic'!G9/'DealScope pricing unit economic'!D9,"") -> 0.8338

Sheet DealScope sensitivity controls
A1: DealScope sensitivity controls
A2: DealScope — Pricing and sensitivity · Growth
A4: Variable / dimension | B4: Sensitivity audit frequency | C4: Sensitivity discount | D4: Sensitivity data multiplier | E4: Sensitivity dollars per credit | F4: Sensitivity delay months | G4: Sensitivity allowance utilization | H4: Allowance only switch
A5: Baseline | B5: =IF('Model inputs'!B14="","",'Model inputs'!B14) -> 4 | C5: =IF('Model inputs'!B37="","",'Model inputs'!B37) -> 0 | D5: =1 -> 1 | E5: =IF('Model inputs'!B16="","",'Model inputs'!B16) -> 0.1 | F5: =IF('Model inputs'!B40="","",'Model inputs'!B40) -> 0 | G5: =1 -> 1 | H5: =0 -> 0
A6: Audits 2/month | B6: =2 -> 2 | C6: =IF('Model inputs'!B37="","",'Model inputs'!B37) -> 0 | D6: =1 -> 1 | E6: =IF('Model inputs'!B16="","",'Model inputs'!B16) -> 0.1 | F6: =IF('Model inputs'!B40="","",'Model inputs'!B40) -> 0 | G6: =1 -> 1 | H6: =0 -> 0
A7: Audits 3/month | B7: =3 -> 3 | C7: =IF('Model inputs'!B37="","",'Model inputs'!B37) -> 0 | D7: =1 -> 1 | E7: =IF('Model inputs'!B16="","",'Model inputs'!B16) -> 0.1 | F7: =IF('Model inputs'!B40="","",'Model inputs'!B40) -> 0 | G7: =1 -> 1 | H7: =0 -> 0
A8: Audits 4/month | B8: =4 -> 4 | C8: =IF('Model inputs'!B37="","",'Model inputs'!B37) -> 0 | D8: =1 -> 1 | E8: =IF('Model inputs'!B16="","",'Model inputs'!B16) -> 0.1 | F8: =IF('Model inputs'!B40="","",'Model inputs'!B40) -> 0 | G8: =1 -> 1 | H8: =0 -> 0
A9: Discount 0% | B9: =IF('Model inputs'!B14="","",'Model inputs'!B14) -> 4 | C9: =0 -> 0 | D9: =1 -> 1 | E9: =IF('Model inputs'!B16="","",'Model inputs'!B16) -> 0.1 | F9: =IF('Model inputs'!B40="","",'Model inputs'!B40) -> 0 | G9: =1 -> 1 | H9: =0 -> 0
A10: Discount 20% | B10: =IF('Model inputs'!B14="","",'Model inputs'!B14) -> 4 | C10: =0.2 -> 0.2 | D10: =1 -> 1 | E10: =IF('Model inputs'!B16="","",'Model inputs'!B16) -> 0.1 | F10: =IF('Model inputs'!B40="","",'Model inputs'!B40) -> 0 | G10: =1 -> 1 | H10: =0 -> 0
A11: Discount 40% | B11: =IF('Model inputs'!B14="","",'Model inputs'!B14) -> 4 | C11: =0.4 -> 0.4 | D11: =1 -> 1 | E11: =IF('Model inputs'!B16="","",'Model inputs'!B16) -> 0.1 | F11: =IF('Model inputs'!B40="","",'Model inputs'!B40) -> 0 | G11: =1 -> 1 | H11: =0 -> 0
A12: Data cost x1 | B12: =IF('Model inputs'!B14="","",'Model inputs'!B14) -> 4 | C12: =IF('Model inputs'!B37="","",'Model inputs'!B37) -> 0 | D12: =1 -> 1 | E12: =IF('Model inputs'!B16="","",'Model inputs'!B16) -> 0.1 | F12: =IF('Model inputs'!B40="","",'Model inputs'!B40) -> 0 | G12: =1 -> 1 | H12: =0 -> 0
A13: Data cost x2 | B13: =IF('Model inputs'!B14="","",'Model inputs'!B14) -> 4 | C13: =IF('Model inputs'!B37="","",'Model inputs'!B37) -> 0 | D13: =2 -> 2 | E13: =IF('Model inputs'!B16="","",'Model inputs'!B16) -> 0.1 | F13: =IF('Model inputs'!B40="","",'Model inputs'!B40) -> 0 | G13: =1 -> 1 | H13: =0 -> 0
A14: Data cost x3 | B14: =IF('Model inputs'!B14="","",'Model inputs'!B14) -> 4 | C14: =IF('Model inputs'!B37="","",'Model inputs'!B37) -> 0 | D14: =3 -> 3 | E14: =IF('Model inputs'!B16="","",'Model inputs'!B16) -> 0.1 | F14: =IF('Model inputs'!B40="","",'Model inputs'!B40) -> 0 | G14: =1 -> 1 | H14: =0 -> 0
A15: Credit rate $0.05 | B15: =IF('Model inputs'!B14="","",'Model inputs'!B14) -> 4 | C15: =IF('Model inputs'!B37="","",'Model inputs'!B37) -> 0 | D15: =1 -> 1 | E15: =0.05 -> 0.05 | F15: =IF('Model inputs'!B40="","",'Model inputs'!B40) -> 0 | G15: =1 -> 1 | H15: =0 -> 0
A16: Credit rate $0.10 | B16: =IF('Model inputs'!B14="","",'Model inputs'!B14) -> 4 | C16: =IF('Model inputs'!B37="","",'Model inputs'!B37) -> 0 | D16: =1 -> 1 | E16: =0.1 -> 0.1 | F16: =IF('Model inputs'!B40="","",'Model inputs'!B40) -> 0 | G16: =1 -> 1 | H16: =0 -> 0
A17: Credit rate $0.25 | B17: =IF('Model inputs'!B14="","",'Model inputs'!B14) -> 4 | C17: =IF('Model inputs'!B37="","",'Model inputs'!B37) -> 0 | D17: =1 -> 1 | E17: =0.25 -> 0.25 | F17: =IF('Model inputs'!B40="","",'Model inputs'!B40) -> 0 | G17: =1 -> 1 | H17: =0 -> 0
A18: Sales delay 0 months | B18: =IF('Model inputs'!B14="","",'Model inputs'!B14) -> 4 | C18: =IF('Model inputs'!B37="","",'Model inputs'!B37) -> 0 | D18: =1 -> 1 | E18: =IF('Model inputs'!B16="","",'Model inputs'!B16) -> 0.1 | F18: =0 -> 0 | G18: =1 -> 1 | H18: =0 -> 0
A19: Sales delay 2 months | B19: =IF('Model inputs'!B14="","",'Model inputs'!B14) -> 4 | C19: =IF('Model inputs'!B37="","",'Model inputs'!B37) -> 0 | D19: =1 -> 1 | E19: =IF('Model inputs'!B16="","",'Model inputs'!B16) -> 0.1 | F19: =2 -> 2 | G19: =1 -> 1 | H19: =0 -> 0
A20: Sales delay 4 months | B20: =IF('Model inputs'!B14="","",'Model inputs'!B14) -> 4 | C20: =IF('Model inputs'!B37="","",'Model inputs'!B37) -> 0 | D20: =1 -> 1 | E20: =IF('Model inputs'!B16="","",'Model inputs'!B16) -> 0.1 | F20: =4 -> 4 | G20: =1 -> 1 | H20: =0 -> 0
A21: Annual allowance utilization 50% | B21: =IF('Model inputs'!B14="","",'Model inputs'!B14) -> 4 | C21: =IF('Model inputs'!B37="","",'Model inputs'!B37) -> 0 | D21: =1 -> 1 | E21: =IF('Model inputs'!B16="","",'Model inputs'!B16) -> 0.1 | F21: =IF('Model inputs'!B40="","",'Model inputs'!B40) -> 0 | G21: =0.5 -> 0.5 | H21: =1 -> 1
A22: Annual allowance utilization 75% | B22: =IF('Model inputs'!B14="","",'Model inputs'!B14) -> 4 | C22: =IF('Model inputs'!B37="","",'Model inputs'!B37) -> 0 | D22: =1 -> 1 | E22: =IF('Model inputs'!B16="","",'Model inputs'!B16) -> 0.1 | F22: =IF('Model inputs'!B40="","",'Model inputs'!B40) -> 0 | G22: =0.75 -> 0.75 | H22: =1 -> 1
A23: Annual allowance utilization 100% | B23: =IF('Model inputs'!B14="","",'Model inputs'!B14) -> 4 | C23: =IF('Model inputs'!B37="","",'Model inputs'!B37) -> 0 | D23: =1 -> 1 | E23: =IF('Model inputs'!B16="","",'Model inputs'!B16) -> 0.1 | F23: =IF('Model inputs'!B40="","",'Model inputs'!B40) -> 0 | G23: =1 -> 1 | H23: =1 -> 1

Sheet DealScope sensitivity compariso
A1: DealScope sensitivity comparisons
A2: DealScope — Pricing and sensitivity · Growth
A4: Variable / dimension | B4: Sensitivity delivered frequency | C4: Sensitivity customer monthly revenue | D4: Sensitivity delivery cost per audit | E4: Sensitivity revenue per audit | F4: Sensitivity gross margin | G4: Sensitivity contribution margin | H4: Sensitivity customer months | I4: Sensitivity 12-month earned revenue | J4: Sensitivity 12-month operating profit
A5: Annual deal-team | B5: ="" | C5: ="" | D5: ="" | E5: ="" | F5: ="" | G5: ="" | H5: ="" | I5: ="" | J5: =""
A6: Annual allowance utilization 100% | B6: =IF(IF(IF(ISERROR('DealScope sensitivity controls'!H23=1),'DealScope sensitivity controls'!H23=1,IF('DealScope sensitivity controls'!H23="","",'DealScope sensitivity controls'!H23=1))="",FALSE,IF(ISERROR('DealScope sensitivity controls'!H23=1),'DealScope sensitivity controls'!H23=1,IF('DealScope sensitivity controls'!H23="","",'DealScope sensitivity controls'!H23=1))),'Model inputs'!B6/12*'DealScope sensitivity controls'!G23,IF('DealScope sensitivity controls'!B23="","",'DealScope sensitivity controls'!B23)) -> 2 | C6: =IF(EXACT("Annual deal-team","Annual deal-team"),('Model inputs'!B45/12+MAX('DealScope sensitivity compariso'!B6-'Model inputs'!B24/12,0)*'Model inputs'!B32)*(1-'DealScope sensitivity controls'!C23),('Model inputs'!B45/12+'Model inputs'!B9*'DealScope sensitivity compariso'!B6)*(1-'DealScope sensitivity controls'!C23)) -> 2000 | D6: ='Model inputs'!B15*'DealScope sensitivity controls'!E23*'DealScope sensitivity controls'!D23*'Model inputs'!B17+'Model inputs'!B30+'Model inputs'!B39+'Model inputs'!B19 -> 94.65 | E6: =IFERROR('DealScope sensitivity compariso'!C6/'DealScope sensitivity compariso'!B6,"") -> 1000 | F6: =IFERROR(('DealScope sensitivity compariso'!E6-'DealScope sensitivity compariso'!D6)/'DealScope sensitivity compariso'!E6,"") -> 0.90535 | G6: =IFERROR(('DealScope sensitivity compariso'!C6*(1-'Model inputs'!B38)-'DealScope sensitivity compariso'!B6*'DealScope sensitivity compariso'!D6-'Model inputs'!B42*'Model inputs'!B41)/'DealScope sensitivity compariso'!C6,"") -> 0.86035 | H6: ='Model inputs'!B75+IF(IF(IF(IF(ISERROR('Model inputs'!B29=1),'Model inputs'!B29=1,IF('Model inputs'!B29="","",'Model inputs'!B29=1))="",FALSE,IF(ISERROR('Model inputs'!B29=1),'Model inputs'!B29=1,IF('Model inputs'!B29="","",'Model inputs'!B29=1))),'Model inputs'!B43*MIN(MAX((11-'DealScope sensitivity controls'!F23)/'Model inputs'!B21,0),1),IF(IF(IF(ISERROR(11>'DealScope sensitivity controls'!F23),11>'DealScope sensitivity controls'!F23,IF('DealScope sensitivity controls'!F23="","",11>'DealScope sensitivity controls'!F23))="",FALSE,IF(ISERROR(11>'DealScope sensitivity controls'!F23),11>'DealScope sensitivity controls'!F23,IF('DealScope sensitivity controls'!F23="","",11>'DealScope sensitivity controls'!F23))),IF('Model inputs'!B43="","",'Model inputs'!B43),0))="",0,IF(IF(IF(ISERROR('Model inputs'!B29=1),'Model inputs'!B29=1,IF('Model inputs'!B29="","",'Model inputs'!B29=1))="",FALSE,IF(ISERROR('Model inputs'!B29=1),'Model inputs'!B29=1,IF('Model inputs'!B29="","",'Model inputs'!B29=1))),'Model inputs'!B43*MIN(MAX((11-'DealScope sensitivity controls'!F23)/'Model inputs'!B21,0),1),IF(IF(IF(ISERROR(11>'DealScope sensitivity controls'!F23),11>'DealScope sensitivity controls'!F23,IF('DealScope sensitivity controls'!F23="","",11>'DealScope sensitivity controls'!F23))="",FALSE,IF(ISERROR(11>'DealScope sensitivity controls'!F23),11>'DealScope sensitivity controls'!F23,IF('DealScope sensitivity controls'!F23="","",11>'DealScope sensitivity controls'!F23))),IF('Model inputs'!B43="","",'Model inputs'!B43),0)))+IF(IF(IF(IF(ISERROR('Model inputs'!B29=1),'Model inputs'!B29=1,IF('Model inputs'!B29="","",'Model inputs'!B29=1))="",FALSE,IF(ISERROR('Model inputs'!B29=1),'Model inputs'!B29=1,IF('Model inputs'!B29="","",'Model inputs'!B29=1))),'Model inputs'!B43*MIN(MAX((12-'DealScope sensitivity controls'!F23)/'Model inputs'!B21,0),1),IF(IF(IF(ISERROR(12>'DealScope sensitivity controls'!F23),12>'DealScope sensitivity controls'!F23,IF('DealScope sensitivity controls'!F23="","",12>'DealScope sensitivity controls'!F23))="",FALSE,IF(ISERROR(12>'DealScope sensitivity controls'!F23),12>'DealScope sensitivity controls'!F23,IF('DealScope sensitivity controls'!F23="","",12>'DealScope sensitivity controls'!F23))),IF('Model inputs'!B43="","",'Model inputs'!B43),0))="",0,IF(IF(IF(ISERROR('Model inputs'!B29=1),'Model inputs'!B29=1,IF('Model inputs'!B29="","",'Model inputs'!B29=1))="",FALSE,IF(ISERROR('Model inputs'!B29=1),'Model inputs'!B29=1,IF('Model inputs'!B29="","",'Model inputs'!B29=1))),'Model inputs'!B43*MIN(MAX((12-'DealScope sensitivity controls'!F23)/'Model inputs'!B21,0),1),IF(IF(IF(ISERROR(12>'DealScope sensitivity controls'!F23),12>'DealScope sensitivity controls'!F23,IF('DealScope sensitivity controls'!F23="","",12>'DealScope sensitivity controls'!F23))="",FALSE,IF(ISERROR(12>'DealScope sensitivity controls'!F23),12>'DealScope sensitivity controls'!F23,IF('DealScope sensitivity controls'!F23="","",12>'DealScope sensitivity controls'!F23))),IF('Model inputs'!B43="","",'Model inputs'!B43),0))) -> 97.5 | I6: ='DealScope sensitivity compariso'!H6*'DealScope sensitivity compariso'!C6 -> 195000 | J6: ='DealScope sensitivity compariso'!I6*(1-'Model inputs'!B38)-'DealScope sensitivity compariso'!H6*('DealScope sensitivity compariso'!B6*'DealScope sensitivity compariso'!D6+'Model inputs'!B42*'Model inputs'!B41)-SUM('Model inputs'!B76,'Model inputs'!B77) -> 155268.25
A7: Annual allowance utilization 50% | B7: =IF(IF(IF(ISERROR('DealScope sensitivity controls'!H21=1),'DealScope sensitivity controls'!H21=1,IF('DealScope sensitivity controls'!H21="","",'DealScope sensitivity controls'!H21=1))="",FALSE,IF(ISERROR('DealScope sensitivity controls'!H21=1),'DealScope sensitivity controls'!H21=1,IF('DealScope sensitivity controls'!H21="","",'DealScope sensitivity controls'!H21=1))),'Model inputs'!B6/12*'DealScope sensitivity controls'!G21,IF('DealScope sensitivity controls'!B21="","",'DealScope sensitivity controls'!B21)) -> 1 | C7: =IF(EXACT("Annual deal-team","Annual deal-team"),('Model inputs'!B45/12+MAX('DealScope sensitivity compariso'!B7-'Model inputs'!B24/12,0)*'Model inputs'!B32)*(1-'DealScope sensitivity controls'!C21),('Model inputs'!B45/12+'Model inputs'!B9*'DealScope sensitivity compariso'!B7)*(1-'DealScope sensitivity controls'!C21)) -> 2000 | D7: ='Model inputs'!B15*'DealScope sensitivity controls'!E21*'DealScope sensitivity controls'!D21*'Model inputs'!B17+'Model inputs'!B30+'Model inputs'!B39+'Model inputs'!B19 -> 94.65 | E7: =IFERROR('DealScope sensitivity compariso'!C7/'DealScope sensitivity compariso'!B7,"") -> 2000 | F7: =IFERROR(('DealScope sensitivity compariso'!E7-'DealScope sensitivity compariso'!D7)/'DealScope sensitivity compariso'!E7,"") -> 0.952675 | G7: =IFERROR(('DealScope sensitivity compariso'!C7*(1-'Model inputs'!B38)-'DealScope sensitivity compariso'!B7*'DealScope sensitivity compariso'!D7-'Model inputs'!B42*'Model inputs'!B41)/'DealScope sensitivity compariso'!C7,"") -> 0.907675 | H7: ='Model inputs'!B82+IF(IF(IF(IF(ISERROR('Model inputs'!B29=1),'Model inputs'!B29=1,IF('Model inputs'!B29="","",'Model inputs'!B29=1))="",FALSE,IF(ISERROR('Model inputs'!B29=1),'Model inputs'!B29=1,IF('Model inputs'!B29="","",'Model inputs'!B29=1))),'Model inputs'!B43*MIN(MAX((11-'DealScope sensitivity controls'!F21)/'Model inputs'!B21,0),1),IF(IF(IF(ISERROR(11>'DealScope sensitivity controls'!F21),11>'DealScope sensitivity controls'!F21,IF('DealScope sensitivity controls'!F21="","",11>'DealScope sensitivity controls'!F21))="",FALSE,IF(ISERROR(11>'DealScope sensitivity controls'!F21),11>'DealScope sensitivity controls'!F21,IF('DealScope sensitivity controls'!F21="","",11>'DealScope sensitivity controls'!F21))),IF('Model inputs'!B43="","",'Model inputs'!B43),0))="",0,IF(IF(IF(ISERROR('Model inputs'!B29=1),'Model inputs'!B29=1,IF('Model inputs'!B29="","",'Model inputs'!B29=1))="",FALSE,IF(ISERROR('Model inputs'!B29=1),'Model inputs'!B29=1,IF('Model inputs'!B29="","",'Model inputs'!B29=1))),'Model inputs'!B43*MIN(MAX((11-'DealScope sensitivity controls'!F21)/'Model inputs'!B21,0),1),IF(IF(IF(ISERROR(11>'DealScope sensitivity controls'!F21),11>'DealScope sensitivity controls'!F21,IF('DealScope sensitivity controls'!F21="","",11>'DealScope sensitivity controls'!F21))="",FALSE,IF(ISERROR(11>'DealScope sensitivity controls'!F21),11>'DealScope sensitivity controls'!F21,IF('DealScope sensitivity controls'!F21="","",11>'DealScope sensitivity controls'!F21))),IF('Model inputs'!B43="","",'Model inputs'!B43),0)))+IF(IF(IF(IF(ISERROR('Model inputs'!B29=1),'Model inputs'!B29=1,IF('Model inputs'!B29="","",'Model inputs'!B29=1))="",FALSE,IF(ISERROR('Model inputs'!B29=1),'Model inputs'!B29=1,IF('Model inputs'!B29="","",'Model inputs'!B29=1))),'Model inputs'!B43*MIN(MAX((12-'DealScope sensitivity controls'!F21)/'Model inputs'!B21,0),1),IF(IF(IF(ISERROR(12>'DealScope sensitivity controls'!F21),12>'DealScope sensitivity controls'!F21,IF('DealScope sensitivity controls'!F21="","",12>'DealScope sensitivity controls'!F21))="",FALSE,IF(ISERROR(12>'DealScope sensitivity controls'!F21),12>'DealScope sensitivity controls'!F21,IF('DealScope sensitivity controls'!F21="","",12>'DealScope sensitivity controls'!F21))),IF('Model inputs'!B43="","",'Model inputs'!B43),0))="",0,IF(IF(IF(ISERROR('Model inputs'!B29=1),'Model inputs'!B29=1,IF('Model inputs'!B29="","",'Model inputs'!B29=1))="",FALSE,IF(ISERROR('Model inputs'!B29=1),'Model inputs'!B29=1,IF('Model inputs'!B29="","",'Model inputs'!B29=1))),'Model inputs'!B43*MIN(MAX((12-'DealScope sensitivity controls'!F21)/'Model inputs'!B21,0),1),IF(IF(IF(ISERROR(12>'DealScope sensitivity controls'!F21),12>'DealScope sensitivity controls'!F21,IF('DealScope sensitivity controls'!F21="","",12>'DealScope sensitivity controls'!F21))="",FALSE,IF(ISERROR(12>'DealScope sensitivity controls'!F21),12>'DealScope sensitivity controls'!F21,IF('DealScope sensitivity controls'!F21="","",12>'DealScope sensitivity controls'!F21))),IF('Model inputs'!B43="","",'Model inputs'!B43),0))) -> 97.5 | I7: ='DealScope sensitivity compariso'!H7*'DealScope sensitivity compariso'!C7 -> 195000 | J7: ='DealScope sensitivity compariso'!I7*(1-'Model inputs'!B38)-'DealScope sensitivity compariso'!H7*('DealScope sensitivity compariso'!B7*'DealScope sensitivity compariso'!D7+'Model inputs'!B42*'Model inputs'!B41)-SUM('Model inputs'!B76,'Model inputs'!B77) -> 164496.62
A8: Annual allowance utilization 75% | B8: =IF(IF(IF(ISERROR('DealScope sensitivity controls'!H22=1),'DealScope sensitivity controls'!H22=1,IF('DealScope sensitivity controls'!H22="","",'DealScope sensitivity controls'!H22=1))="",FALSE,IF(ISERROR('DealScope sensitivity controls'!H22=1),'DealScope sensitivity controls'!H22=1,IF('DealScope sensitivity controls'!H22="","",'DealScope sensitivity controls'!H22=1))),'Model inputs'!B6/12*'DealScope sensitivity controls'!G22,IF('DealScope sensitivity controls'!B22="","",'DealScope sensitivity controls'!B22)) -> 1.5 | C8: =IF(EXACT("Annual deal-team","Annual deal-team"),('Model inputs'!B45/12+MAX('DealScope sensitivity compariso'!B8-'Model inputs'!B24/12,0)*'Model inputs'!B32)*(1-'DealScope sensitivity controls'!C22),('Model inputs'!B45/12+'Model inputs'!B9*'DealScope sensitivity compariso'!B8)*(1-'DealScope sensitivity controls'!C22)) -> 2000 | D8: ='Model inputs'!B15*'DealScope sensitivity controls'!E22*'DealScope sensitivity controls'!D22*'Model inputs'!B17+'Model inputs'!B30+'Model inputs'!B39+'Model inputs'!B19 -> 94.65 | E8: =IFERROR('DealScope sensitivity compariso'!C8/'DealScope sensitivity compariso'!B8,"") -> 1333.3333 | F8: =IFERROR(('DealScope sensitivity compariso'!E8-'DealScope sensitivity compariso'!D8)/'DealScope sensitivity compariso'!E8,"") -> 0.9290125 | G8: =IFERROR(('DealScope sensitivity compariso'!C8*(1-'Model inputs'!B38)-'DealScope sensitivity compariso'!B8*'DealScope sensitivity compariso'!D8-'Model inputs'!B42*'Model inputs'!B41)/'DealScope sensitivity compariso'!C8,"") -> 0.8840125 | H8: ='Model inputs'!B87+IF(IF(IF(IF(ISERROR('Model inputs'!B29=1),'Model inputs'!B29=1,IF('Model inputs'!B29="","",'Model inputs'!B29=1))="",FALSE,IF(ISERROR('Model inputs'!B29=1),'Model inputs'!B29=1,IF('Model inputs'!B29="","",'Model inputs'!B29=1))),'Model inputs'!B43*MIN(MAX((11-'DealScope sensitivity controls'!F22)/'Model inputs'!B21,0),1),IF(IF(IF(ISERROR(11>'DealScope sensitivity controls'!F22),11>'DealScope sensitivity controls'!F22,IF('DealScope sensitivity controls'!F22="","",11>'DealScope sensitivity controls'!F22))="",FALSE,IF(ISERROR(11>'DealScope sensitivity controls'!F22),11>'DealScope sensitivity controls'!F22,IF('DealScope sensitivity controls'!F22="","",11>'DealScope sensitivity controls'!F22))),IF('Model inputs'!B43="","",'Model inputs'!B43),0))="",0,IF(IF(IF(ISERROR('Model inputs'!B29=1),'Model inputs'!B29=1,IF('Model inputs'!B29="","",'Model inputs'!B29=1))="",FALSE,IF(ISERROR('Model inputs'!B29=1),'Model inputs'!B29=1,IF('Model inputs'!B29="","",'Model inputs'!B29=1))),'Model inputs'!B43*MIN(MAX((11-'DealScope sensitivity controls'!F22)/'Model inputs'!B21,0),1),IF(IF(IF(ISERROR(11>'DealScope sensitivity controls'!F22),11>'DealScope sensitivity controls'!F22,IF('DealScope sensitivity controls'!F22="","",11>'DealScope sensitivity controls'!F22))="",FALSE,IF(ISERROR(11>'DealScope sensitivity controls'!F22),11>'DealScope sensitivity controls'!F22,IF('DealScope sensitivity controls'!F22="","",11>'DealScope sensitivity controls'!F22))),IF('Model inputs'!B43="","",'Model inputs'!B43),0)))+IF(IF(IF(IF(ISERROR('Model inputs'!B29=1),'Model inputs'!B29=1,IF('Model inputs'!B29="","",'Model inputs'!B29=1))="",FALSE,IF(ISERROR('Model inputs'!B29=1),'Model inputs'!B29=1,IF('Model inputs'!B29="","",'Model inputs'!B29=1))),'Model inputs'!B43*MIN(MAX((12-'DealScope sensitivity controls'!F22)/'Model inputs'!B21,0),1),IF(IF(IF(ISERROR(12>'DealScope sensitivity controls'!F22),12>'DealScope sensitivity controls'!F22,IF('DealScope sensitivity controls'!F22="","",12>'DealScope sensitivity controls'!F22))="",FALSE,IF(ISERROR(12>'DealScope sensitivity controls'!F22),12>'DealScope sensitivity controls'!F22,IF('DealScope sensitivity controls'!F22="","",12>'DealScope sensitivity controls'!F22))),IF('Model inputs'!B43="","",'Model inputs'!B43),0))="",0,IF(IF(IF(ISERROR('Model inputs'!B29=1),'Model inputs'!B29=1,IF('Model inputs'!B29="","",'Model inputs'!B29=1))="",FALSE,IF(ISERROR('Model inputs'!B29=1),'Model inputs'!B29=1,IF('Model inputs'!B29="","",'Model inputs'!B29=1))),'Model inputs'!B43*MIN(MAX((12-'DealScope sensitivity controls'!F22)/'Model inputs'!B21,0),1),IF(IF(IF(ISERROR(12>'DealScope sensitivity controls'!F22),12>'DealScope sensitivity controls'!F22,IF('DealScope sensitivity controls'!F22="","",12>'DealScope sensitivity controls'!F22))="",FALSE,IF(ISERROR(12>'DealScope sensitivity controls'!F22),12>'DealScope sensitivity controls'!F22,IF('DealScope sensitivity controls'!F22="","",12>'DealScope sensitivity controls'!F22))),IF('Model inputs'!B43="","",'Model inputs'!B43),0))) -> 97.5 | I8: ='DealScope sensitivity compariso'!H8*'DealScope sensitivity compariso'!C8 -> 195000 | J8: ='DealScope sensitivity compariso'!I8*(1-'Model inputs'!B38)-'DealScope sensitivity compariso'!H8*('DealScope sensitivity compariso'!B8*'DealScope sensitivity compariso'!D8+'Model inputs'!B42*'Model inputs'!B41)-SUM('Model inputs'!B76,'Model inputs'!B77) -> 159882.44
A9: Audits 2/month | B9: =IF(IF(IF(ISERROR('DealScope sensitivity controls'!H6=1),'DealScope sensitivity controls'!H6=1,IF('DealScope sensitivity controls'!H6="","",'DealScope sensitivity controls'!H6=1))="",FALSE,IF(ISERROR('DealScope sensitivity controls'!H6=1),'DealScope sensitivity controls'!H6=1,IF('DealScope sensitivity controls'!H6="","",'DealScope sensitivity controls'!H6=1))),'Model inputs'!B6/12*'DealScope sensitivity controls'!G6,IF('DealScope sensitivity controls'!B6="","",'DealScope sensitivity controls'!B6)) -> 2 | C9: =IF(EXACT("Annual deal-team","Annual deal-team"),('Model inputs'!B45/12+MAX('DealScope sensitivity compariso'!B9-'Model inputs'!B24/12,0)*'Model inputs'!B32)*(1-'DealScope sensitivity controls'!C6),('Model inputs'!B45/12+'Model inputs'!B9*'DealScope sensitivity compariso'!B9)*(1-'DealScope sensitivity controls'!C6)) -> 2000 | D9: ='Model inputs'!B15*'DealScope sensitivity controls'!E6*'DealScope sensitivity controls'!D6*'Model inputs'!B17+'Model inputs'!B30+'Model inputs'!B39+'Model inputs'!B19 -> 94.65 | E9: =IFERROR('DealScope sensitivity compariso'!C9/'DealScope sensitivity compariso'!B9,"") -> 1000 | F9: =IFERROR(('DealScope sensitivity compariso'!E9-'DealScope sensitivity compariso'!D9)/'DealScope sensitivity compariso'!E9,"") -> 0.90535 | G9: =IFERROR(('DealScope sensitivity compariso'!C9*(1-'Model inputs'!B38)-'DealScope sensitivity compariso'!B9*'DealScope sensitivity compariso'!D9-'Model inputs'!B42*'Model inputs'!B41)/'DealScope sensitivity compariso'!C9,"") -> 0.86035 | H9: ='Model inputs'!B92+IF(IF(IF(IF(ISERROR('Model inputs'!B29=1),'Model inputs'!B29=1,IF('Model inputs'!B29="","",'Model inputs'!B29=1))="",FALSE,IF(ISERROR('Model inputs'!B29=1),'Model inputs'!B29=1,IF('Model inputs'!B29="","",'Model inputs'!B29=1))),'Model inputs'!B43*MIN(MAX((11-'DealScope sensitivity controls'!F6)/'Model inputs'!B21,0),1),IF(IF(IF(ISERROR(11>'DealScope sensitivity controls'!F6),11>'DealScope sensitivity controls'!F6,IF('DealScope sensitivity controls'!F6="","",11>'DealScope sensitivity controls'!F6))="",FALSE,IF(ISERROR(11>'DealScope sensitivity controls'!F6),11>'DealScope sensitivity controls'!F6,IF('DealScope sensitivity controls'!F6="","",11>'DealScope sensitivity controls'!F6))),IF('Model inputs'!B43="","",'Model inputs'!B43),0))="",0,IF(IF(IF(ISERROR('Model inputs'!B29=1),'Model inputs'!B29=1,IF('Model inputs'!B29="","",'Model inputs'!B29=1))="",FALSE,IF(ISERROR('Model inputs'!B29=1),'Model inputs'!B29=1,IF('Model inputs'!B29="","",'Model inputs'!B29=1))),'Model inputs'!B43*MIN(MAX((11-'DealScope sensitivity controls'!F6)/'Model inputs'!B21,0),1),IF(IF(IF(ISERROR(11>'DealScope sensitivity controls'!F6),11>'DealScope sensitivity controls'!F6,IF('DealScope sensitivity controls'!F6="","",11>'DealScope sensitivity controls'!F6))="",FALSE,IF(ISERROR(11>'DealScope sensitivity controls'!F6),11>'DealScope sensitivity controls'!F6,IF('DealScope sensitivity controls'!F6="","",11>'DealScope sensitivity controls'!F6))),IF('Model inputs'!B43="","",'Model inputs'!B43),0)))+IF(IF(IF(IF(ISERROR('Model inputs'!B29=1),'Model inputs'!B29=1,IF('Model inputs'!B29="","",'Model inputs'!B29=1))="",FALSE,IF(ISERROR('Model inputs'!B29=1),'Model inputs'!B29=1,IF('Model inputs'!B29="","",'Model inputs'!B29=1))),'Model inputs'!B43*MIN(MAX((12-'DealScope sensitivity controls'!F6)/'Model inputs'!B21,0),1),IF(IF(IF(ISERROR(12>'DealScope sensitivity controls'!F6),12>'DealScope sensitivity controls'!F6,IF('DealScope sensitivity controls'!F6="","",12>'DealScope sensitivity controls'!F6))="",FALSE,IF(ISERROR(12>'DealScope sensitivity controls'!F6),12>'DealScope sensitivity controls'!F6,IF('DealScope sensitivity controls'!F6="","",12>'DealScope sensitivity controls'!F6))),IF('Model inputs'!B43="","",'Model inputs'!B43),0))="",0,IF(IF(IF(ISERROR('Model inputs'!B29=1),'Model inputs'!B29=1,IF('Model inputs'!B29="","",'Model inputs'!B29=1))="",FALSE,IF(ISERROR('Model inputs'!B29=1),'Model inputs'!B29=1,IF('Model inputs'!B29="","",'Model inputs'!B29=1))),'Model inputs'!B43*MIN(MAX((12-'DealScope sensitivity controls'!F6)/'Model inputs'!B21,0),1),IF(IF(IF(ISERROR(12>'DealScope sensitivity controls'!F6),12>'DealScope sensitivity controls'!F6,IF('DealScope sensitivity controls'!F6="","",12>'DealScope sensitivity controls'!F6))="",FALSE,IF(ISERROR(12>'DealScope sensitivity controls'!F6),12>'DealScope sensitivity controls'!F6,IF('DealScope sensitivity controls'!F6="","",12>'DealScope sensitivity controls'!F6))),IF('Model inputs'!B43="","",'Model inputs'!B43),0))) -> 97.5 | I9: ='DealScope sensitivity compariso'!H9*'DealScope sensitivity compariso'!C9 -> 195000 | J9: ='DealScope sensitivity compariso'!I9*(1-'Model inputs'!B38)-'DealScope sensitivity compariso'!H9*('DealScope sensitivity compariso'!B9*'DealScope sensitivity compariso'!D9+'Model inputs'!B42*'Model inputs'!B41)-SUM('Model inputs'!B76,'Model inputs'!B77) -> 155268.25
A10: Audits 3/month | B10: =IF(IF(IF(ISERROR('DealScope sensitivity controls'!H7=1),'DealScope sensitivity controls'!H7=1,IF('DealScope sensitivity controls'!H7="","",'DealScope sensitivity controls'!H7=1))="",FALSE,IF(ISERROR('DealScope sensitivity controls'!H7=1),'DealScope sensitivity controls'!H7=1,IF('DealScope sensitivity controls'!H7="","",'DealScope sensitivity controls'!H7=1))),'Model inputs'!B6/12*'DealScope sensitivity controls'!G7,IF('DealScope sensitivity controls'!B7="","",'DealScope sensitivity controls'!B7)) -> 3 | C10: =IF(EXACT("Annual deal-team","Annual deal-team"),('Model inputs'!B45/12+MAX('DealScope sensitivity compariso'!B10-'Model inputs'!B24/12,0)*'Model inputs'!B32)*(1-'DealScope sensitivity controls'!C7),('Model inputs'!B45/12+'Model inputs'!B9*'DealScope sensitivity compariso'!B10)*(1-'DealScope sensitivity controls'!C7)) -> 3000 | D10: ='Model inputs'!B15*'DealScope sensitivity controls'!E7*'DealScope sensitivity controls'!D7*'Model inputs'!B17+'Model inputs'!B30+'Model inputs'!B39+'Model inputs'!B19 -> 94.65 | E10: =IFERROR('DealScope sensitivity compariso'!C10/'DealScope sensitivity compariso'!B10,"") -> 1000 | F10: =IFERROR(('DealScope sensitivity compariso'!E10-'DealScope sensitivity compariso'!D10)/'DealScope sensitivity compariso'!E10,"") -> 0.90535 | G10: =IFERROR(('DealScope sensitivity compariso'!C10*(1-'Model inputs'!B38)-'DealScope sensitivity compariso'!B10*'DealScope sensitivity compariso'!D10-'Model inputs'!B42*'Model inputs'!B41)/'DealScope sensitivity compariso'!C10,"") -> 0.86535 | H10: ='Model inputs'!B97+IF(IF(IF(IF(ISERROR('Model inputs'!B29=1),'Model inputs'!B29=1,IF('Model inputs'!B29="","",'Model inputs'!B29=1))="",FALSE,IF(ISERROR('Model inputs'!B29=1),'Model inputs'!B29=1,IF('Model inputs'!B29="","",'Model inputs'!B29=1))),'Model inputs'!B43*MIN(MAX((11-'DealScope sensitivity controls'!F7)/'Model inputs'!B21,0),1),IF(IF(IF(ISERROR(11>'DealScope sensitivity controls'!F7),11>'DealScope sensitivity controls'!F7,IF('DealScope sensitivity controls'!F7="","",11>'DealScope sensitivity controls'!F7))="",FALSE,IF(ISERROR(11>'DealScope sensitivity controls'!F7),11>'DealScope sensitivity controls'!F7,IF('DealScope sensitivity controls'!F7="","",11>'DealScope sensitivity controls'!F7))),IF('Model inputs'!B43="","",'Model inputs'!B43),0))="",0,IF(IF(IF(ISERROR('Model inputs'!B29=1),'Model inputs'!B29=1,IF('Model inputs'!B29="","",'Model inputs'!B29=1))="",FALSE,IF(ISERROR('Model inputs'!B29=1),'Model inputs'!B29=1,IF('Model inputs'!B29="","",'Model inputs'!B29=1))),'Model inputs'!B43*MIN(MAX((11-'DealScope sensitivity controls'!F7)/'Model inputs'!B21,0),1),IF(IF(IF(ISERROR(11>'DealScope sensitivity controls'!F7),11>'DealScope sensitivity controls'!F7,IF('DealScope sensitivity controls'!F7="","",11>'DealScope sensitivity controls'!F7))="",FALSE,IF(ISERROR(11>'DealScope sensitivity controls'!F7),11>'DealScope sensitivity controls'!F7,IF('DealScope sensitivity controls'!F7="","",11>'DealScope sensitivity controls'!F7))),IF('Model inputs'!B43="","",'Model inputs'!B43),0)))+IF(IF(IF(IF(ISERROR('Model inputs'!B29=1),'Model inputs'!B29=1,IF('Model inputs'!B29="","",'Model inputs'!B29=1))="",FALSE,IF(ISERROR('Model inputs'!B29=1),'Model inputs'!B29=1,IF('Model inputs'!B29="","",'Model inputs'!B29=1))),'Model inputs'!B43*MIN(MAX((12-'DealScope sensitivity controls'!F7)/'Model inputs'!B21,0),1),IF(IF(IF(ISERROR(12>'DealScope sensitivity controls'!F7),12>'DealScope sensitivity controls'!F7,IF('DealScope sensitivity controls'!F7="","",12>'DealScope sensitivity controls'!F7))="",FALSE,IF(ISERROR(12>'DealScope sensitivity controls'!F7),12>'DealScope sensitivity controls'!F7,IF('DealScope sensitivity controls'!F7="","",12>'DealScope sensitivity controls'!F7))),IF('Model inputs'!B43="","",'Model inputs'!B43),0))="",0,IF(IF(IF(ISERROR('Model inputs'!B29=1),'Model inputs'!B29=1,IF('Model inputs'!B29="","",'Model inputs'!B29=1))="",FALSE,IF(ISERROR('Model inputs'!B29=1),'Model inputs'!B29=1,IF('Model inputs'!B29="","",'Model inputs'!B29=1))),'Model inputs'!B43*MIN(MAX((12-'DealScope sensitivity controls'!F7)/'Model inputs'!B21,0),1),IF(IF(IF(ISERROR(12>'DealScope sensitivity controls'!F7),12>'DealScope sensitivity controls'!F7,IF('DealScope sensitivity controls'!F7="","",12>'DealScope sensitivity controls'!F7))="",FALSE,IF(ISERROR(12>'DealScope sensitivity controls'!F7),12>'DealScope sensitivity controls'!F7,IF('DealScope sensitivity controls'!F7="","",12>'DealScope sensitivity controls'!F7))),IF('Model inputs'!B43="","",'Model inputs'!B43),0))) -> 97.5 | I10: ='DealScope sensitivity compariso'!H10*'DealScope sensitivity compariso'!C10 -> 292500 | J10: ='DealScope sensitivity compariso'!I10*(1-'Model inputs'!B38)-'DealScope sensitivity compariso'!H10*('DealScope sensitivity compariso'!B10*'DealScope sensitivity compariso'!D10+'Model inputs'!B42*'Model inputs'!B41)-SUM('Model inputs'!B76,'Model inputs'!B77) -> 240614.88
A11: Audits 4/month | B11: =IF(IF(IF(ISERROR('DealScope sensitivity controls'!H8=1),'DealScope sensitivity controls'!H8=1,IF('DealScope sensitivity controls'!H8="","",'DealScope sensitivity controls'!H8=1))="",FALSE,IF(ISERROR('DealScope sensitivity controls'!H8=1),'DealScope sensitivity controls'!H8=1,IF('DealScope sensitivity controls'!H8="","",'DealScope sensitivity controls'!H8=1))),'Model inputs'!B6/12*'DealScope sensitivity controls'!G8,IF('DealScope sensitivity controls'!B8="","",'DealScope sensitivity controls'!B8)) -> 4 | C11: =IF(EXACT("Annual deal-team","Annual deal-team"),('Model inputs'!B45/12+MAX('DealScope sensitivity compariso'!B11-'Model inputs'!B24/12,0)*'Model inputs'!B32)*(1-'DealScope sensitivity controls'!C8),('Model inputs'!B45/12+'Model inputs'!B9*'DealScope sensitivity compariso'!B11)*(1-'DealScope sensitivity controls'!C8)) -> 4000 | D11: ='Model inputs'!B15*'DealScope sensitivity controls'!E8*'DealScope sensitivity controls'!D8*'Model inputs'!B17+'Model inputs'!B30+'Model inputs'!B39+'Model inputs'!B19 -> 94.65 | E11: =IFERROR('DealScope sensitivity compariso'!C11/'DealScope sensitivity compariso'!B11,"") -> 1000 | F11: =IFERROR(('DealScope sensitivity compariso'!E11-'DealScope sensitivity compariso'!D11)/'DealScope sensitivity compariso'!E11,"") -> 0.90535 | G11: =IFERROR(('DealScope sensitivity compariso'!C11*(1-'Model inputs'!B38)-'DealScope sensitivity compariso'!B11*'DealScope sensitivity compariso'!D11-'Model inputs'!B42*'Model inputs'!B41)/'DealScope sensitivity compariso'!C11,"") -> 0.86785 | H11: ='Model inputs'!B102+IF(IF(IF(IF(ISERROR('Model inputs'!B29=1),'Model inputs'!B29=1,IF('Model inputs'!B29="","",'Model inputs'!B29=1))="",FALSE,IF(ISERROR('Model inputs'!B29=1),'Model inputs'!B29=1,IF('Model inputs'!B29="","",'Model inputs'!B29=1))),'Model inputs'!B43*MIN(MAX((11-'DealScope sensitivity controls'!F8)/'Model inputs'!B21,0),1),IF(IF(IF(ISERROR(11>'DealScope sensitivity controls'!F8),11>'DealScope sensitivity controls'!F8,IF('DealScope sensitivity controls'!F8="","",11>'DealScope sensitivity controls'!F8))="",FALSE,IF(ISERROR(11>'DealScope sensitivity controls'!F8),11>'DealScope sensitivity controls'!F8,IF('DealScope sensitivity controls'!F8="","",11>'DealScope sensitivity controls'!F8))),IF('Model inputs'!B43="","",'Model inputs'!B43),0))="",0,IF(IF(IF(ISERROR('Model inputs'!B29=1),'Model inputs'!B29=1,IF('Model inputs'!B29="","",'Model inputs'!B29=1))="",FALSE,IF(ISERROR('Model inputs'!B29=1),'Model inputs'!B29=1,IF('Model inputs'!B29="","",'Model inputs'!B29=1))),'Model inputs'!B43*MIN(MAX((11-'DealScope sensitivity controls'!F8)/'Model inputs'!B21,0),1),IF(IF(IF(ISERROR(11>'DealScope sensitivity controls'!F8),11>'DealScope sensitivity controls'!F8,IF('DealScope sensitivity controls'!F8="","",11>'DealScope sensitivity controls'!F8))="",FALSE,IF(ISERROR(11>'DealScope sensitivity controls'!F8),11>'DealScope sensitivity controls'!F8,IF('DealScope sensitivity controls'!F8="","",11>'DealScope sensitivity controls'!F8))),IF('Model inputs'!B43="","",'Model inputs'!B43),0)))+IF(IF(IF(IF(ISERROR('Model inputs'!B29=1),'Model inputs'!B29=1,IF('Model inputs'!B29="","",'Model inputs'!B29=1))="",FALSE,IF(ISERROR('Model inputs'!B29=1),'Model inputs'!B29=1,IF('Model inputs'!B29="","",'Model inputs'!B29=1))),'Model inputs'!B43*MIN(MAX((12-'DealScope sensitivity controls'!F8)/'Model inputs'!B21,0),1),IF(IF(IF(ISERROR(12>'DealScope sensitivity controls'!F8),12>'DealScope sensitivity controls'!F8,IF('DealScope sensitivity controls'!F8="","",12>'DealScope sensitivity controls'!F8))="",FALSE,IF(ISERROR(12>'DealScope sensitivity controls'!F8),12>'DealScope sensitivity controls'!F8,IF('DealScope sensitivity controls'!F8="","",12>'DealScope sensitivity controls'!F8))),IF('Model inputs'!B43="","",'Model inputs'!B43),0))="",0,IF(IF(IF(ISERROR('Model inputs'!B29=1),'Model inputs'!B29=1,IF('Model inputs'!B29="","",'Model inputs'!B29=1))="",FALSE,IF(ISERROR('Model inputs'!B29=1),'Model inputs'!B29=1,IF('Model inputs'!B29="","",'Model inputs'!B29=1))),'Model inputs'!B43*MIN(MAX((12-'DealScope sensitivity controls'!F8)/'Model inputs'!B21,0),1),IF(IF(IF(ISERROR(12>'DealScope sensitivity controls'!F8),12>'DealScope sensitivity controls'!F8,IF('DealScope sensitivity controls'!F8="","",12>'DealScope sensitivity controls'!F8))="",FALSE,IF(ISERROR(12>'DealScope sensitivity controls'!F8),12>'DealScope sensitivity controls'!F8,IF('DealScope sensitivity controls'!F8="","",12>'DealScope sensitivity controls'!F8))),IF('Model inputs'!B43="","",'Model inputs'!B43),0))) -> 97.5 | I11: ='DealScope sensitivity compariso'!H11*'DealScope sensitivity compariso'!C11 -> 390000 | J11: ='DealScope sensitivity compariso'!I11*(1-'Model inputs'!B38)-'DealScope sensitivity compariso'!H11*('DealScope sensitivity compariso'!B11*'DealScope sensitivity compariso'!D11+'Model inputs'!B42*'Model inputs'!B41)-SUM('Model inputs'!B76,'Model inputs'!B77) -> 325961.5
A12: Baseline | B12: =IF(IF(IF(ISERROR('DealScope sensitivity controls'!H5=1),'DealScope sensitivity controls'!H5=1,IF('DealScope sensitivity controls'!H5="","",'DealScope sensitivity controls'!H5=1))="",FALSE,IF(ISERROR('DealScope sensitivity controls'!H5=1),'DealScope sensitivity controls'!H5=1,IF('DealScope sensitivity controls'!H5="","",'DealScope sensitivity controls'!H5=1))),'Model inputs'!B6/12*'DealScope sensitivity controls'!G5,IF('DealScope sensitivity controls'!B5="","",'DealScope sensitivity controls'!B5)) -> 4 | C12: =IF(EXACT("Annual deal-team","Annual deal-team"),('Model inputs'!B45/12+MAX('DealScope sensitivity compariso'!B12-'Model inputs'!B24/12,0)*'Model inputs'!B32)*(1-'DealScope sensitivity controls'!C5),('Model inputs'!B45/12+'Model inputs'!B9*'DealScope sensitivity compariso'!B12)*(1-'DealScope sensitivity controls'!C5)) -> 4000 | D12: ='Model inputs'!B15*'DealScope sensitivity controls'!E5*'DealScope sensitivity controls'!D5*'Model inputs'!B17+'Model inputs'!B30+'Model inputs'!B39+'Model inputs'!B19 -> 94.65 | E12: =IFERROR('DealScope sensitivity compariso'!C12/'DealScope sensitivity compariso'!B12,"") -> 1000 | F12: =IFERROR(('DealScope sensitivity compariso'!E12-'DealScope sensitivity compariso'!D12)/'DealScope sensitivity compariso'!E12,"") -> 0.90535 | G12: =IFERROR(('DealScope sensitivity compariso'!C12*(1-'Model inputs'!B38)-'DealScope sensitivity compariso'!B12*'DealScope sensitivity compariso'!D12-'Model inputs'!B42*'Model inputs'!B41)/'DealScope sensitivity compariso'!C12,"") -> 0.86785 | H12: ='Model inputs'!B107+IF(IF(IF(IF(ISERROR('Model inputs'!B29=1),'Model inputs'!B29=1,IF('Model inputs'!B29="","",'Model inputs'!B29=1))="",FALSE,IF(ISERROR('Model inputs'!B29=1),'Model inputs'!B29=1,IF('Model inputs'!B29="","",'Model inputs'!B29=1))),'Model inputs'!B43*MIN(MAX((11-'DealScope sensitivity controls'!F5)/'Model inputs'!B21,0),1),IF(IF(IF(ISERROR(11>'DealScope sensitivity controls'!F5),11>'DealScope sensitivity controls'!F5,IF('DealScope sensitivity controls'!F5="","",11>'DealScope sensitivity controls'!F5))="",FALSE,IF(ISERROR(11>'DealScope sensitivity controls'!F5),11>'DealScope sensitivity controls'!F5,IF('DealScope sensitivity controls'!F5="","",11>'DealScope sensitivity controls'!F5))),IF('Model inputs'!B43="","",'Model inputs'!B43),0))="",0,IF(IF(IF(ISERROR('Model inputs'!B29=1),'Model inputs'!B29=1,IF('Model inputs'!B29="","",'Model inputs'!B29=1))="",FALSE,IF(ISERROR('Model inputs'!B29=1),'Model inputs'!B29=1,IF('Model inputs'!B29="","",'Model inputs'!B29=1))),'Model inputs'!B43*MIN(MAX((11-'DealScope sensitivity controls'!F5)/'Model inputs'!B21,0),1),IF(IF(IF(ISERROR(11>'DealScope sensitivity controls'!F5),11>'DealScope sensitivity controls'!F5,IF('DealScope sensitivity controls'!F5="","",11>'DealScope sensitivity controls'!F5))="",FALSE,IF(ISERROR(11>'DealScope sensitivity controls'!F5),11>'DealScope sensitivity controls'!F5,IF('DealScope sensitivity controls'!F5="","",11>'DealScope sensitivity controls'!F5))),IF('Model inputs'!B43="","",'Model inputs'!B43),0)))+IF(IF(IF(IF(ISERROR('Model inputs'!B29=1),'Model inputs'!B29=1,IF('Model inputs'!B29="","",'Model inputs'!B29=1))="",FALSE,IF(ISERROR('Model inputs'!B29=1),'Model inputs'!B29=1,IF('Model inputs'!B29="","",'Model inputs'!B29=1))),'Model inputs'!B43*MIN(MAX((12-'DealScope sensitivity controls'!F5)/'Model inputs'!B21,0),1),IF(IF(IF(ISERROR(12>'DealScope sensitivity controls'!F5),12>'DealScope sensitivity controls'!F5,IF('DealScope sensitivity controls'!F5="","",12>'DealScope sensitivity controls'!F5))="",FALSE,IF(ISERROR(12>'DealScope sensitivity controls'!F5),12>'DealScope sensitivity controls'!F5,IF('DealScope sensitivity controls'!F5="","",12>'DealScope sensitivity controls'!F5))),IF('Model inputs'!B43="","",'Model inputs'!B43),0))="",0,IF(IF(IF(ISERROR('Model inputs'!B29=1),'Model inputs'!B29=1,IF('Model inputs'!B29="","",'Model inputs'!B29=1))="",FALSE,IF(ISERROR('Model inputs'!B29=1),'Model inputs'!B29=1,IF('Model inputs'!B29="","",'Model inputs'!B29=1))),'Model inputs'!B43*MIN(MAX((12-'DealScope sensitivity controls'!F5)/'Model inputs'!B21,0),1),IF(IF(IF(ISERROR(12>'DealScope sensitivity controls'!F5),12>'DealScope sensitivity controls'!F5,IF('DealScope sensitivity controls'!F5="","",12>'DealScope sensitivity controls'!F5))="",FALSE,IF(ISERROR(12>'DealScope sensitivity controls'!F5),12>'DealScope sensitivity controls'!F5,IF('DealScope sensitivity controls'!F5="","",12>'DealScope sensitivity controls'!F5))),IF('Model inputs'!B43="","",'Model inputs'!B43),0))) -> 97.5 | I12: ='DealScope sensitivity compariso'!H12*'DealScope sensitivity compariso'!C12 -> 390000 | J12: ='DealScope sensitivity compariso'!I12*(1-'Model inputs'!B38)-'DealScope sensitivity compariso'!H12*('DealScope sensitivity compariso'!B12*'DealScope sensitivity compariso'!D12+'Model inputs'!B42*'Model inputs'!B41)-SUM('Model inputs'!B76,'Model inputs'!B77) -> 325961.5
A13: Credit rate $0.05 | B13: =IF(IF(IF(ISERROR('DealScope sensitivity controls'!H15=1),'DealScope sensitivity controls'!H15=1,IF('DealScope sensitivity controls'!H15="","",'DealScope sensitivity controls'!H15=1))="",FALSE,IF(ISERROR('DealScope sensitivity controls'!H15=1),'DealScope sensitivity controls'!H15=1,IF('DealScope sensitivity controls'!H15="","",'DealScope sensitivity controls'!H15=1))),'Model inputs'!B6/12*'DealScope sensitivity controls'!G15,IF('DealScope sensitivity controls'!B15="","",'DealScope sensitivity controls'!B15)) -> 4 | C13: =IF(EXACT("Annual deal-team","Annual deal-team"),('Model inputs'!B45/12+MAX('DealScope sensitivity compariso'!B13-'Model inputs'!B24/12,0)*'Model inputs'!B32)*(1-'DealScope sensitivity controls'!C15),('Model inputs'!B45/12+'Model inputs'!B9*'DealScope sensitivity compariso'!B13)*(1-'DealScope sensitivity controls'!C15)) -> 4000 | D13: ='Model inputs'!B15*'DealScope sensitivity controls'!E15*'DealScope sensitivity controls'!D15*'Model inputs'!B17+'Model inputs'!B30+'Model inputs'!B39+'Model inputs'!B19 -> 93.35 | E13: =IFERROR('DealScope sensitivity compariso'!C13/'DealScope sensitivity compariso'!B13,"") -> 1000 | F13: =IFERROR(('DealScope sensitivity compariso'!E13-'DealScope sensitivity compariso'!D13)/'DealScope sensitivity compariso'!E13,"") -> 0.90665 | G13: =IFERROR(('DealScope sensitivity compariso'!C13*(1-'Model inputs'!B38)-'DealScope sensitivity compariso'!B13*'DealScope sensitivity compariso'!D13-'Model inputs'!B42*'Model inputs'!B41)/'DealScope sensitivity compariso'!C13,"") -> 0.86915 | H13: ='Model inputs'!B112+IF(IF(IF(IF(ISERROR('Model inputs'!B29=1),'Model inputs'!B29=1,IF('Model inputs'!B29="","",'Model inputs'!B29=1))="",FALSE,IF(ISERROR('Model inputs'!B29=1),'Model inputs'!B29=1,IF('Model inputs'!B29="","",'Model inputs'!B29=1))),'Model inputs'!B43*MIN(MAX((11-'DealScope sensitivity controls'!F15)/'Model inputs'!B21,0),1),IF(IF(IF(ISERROR(11>'DealScope sensitivity controls'!F15),11>'DealScope sensitivity controls'!F15,IF('DealScope sensitivity controls'!F15="","",11>'DealScope sensitivity controls'!F15))="",FALSE,IF(ISERROR(11>'DealScope sensitivity controls'!F15),11>'DealScope sensitivity controls'!F15,IF('DealScope sensitivity controls'!F15="","",11>'DealScope sensitivity controls'!F15))),IF('Model inputs'!B43="","",'Model inputs'!B43),0))="",0,IF(IF(IF(ISERROR('Model inputs'!B29=1),'Model inputs'!B29=1,IF('Model inputs'!B29="","",'Model inputs'!B29=1))="",FALSE,IF(ISERROR('Model inputs'!B29=1),'Model inputs'!B29=1,IF('Model inputs'!B29="","",'Model inputs'!B29=1))),'Model inputs'!B43*MIN(MAX((11-'DealScope sensitivity controls'!F15)/'Model inputs'!B21,0),1),IF(IF(IF(ISERROR(11>'DealScope sensitivity controls'!F15),11>'DealScope sensitivity controls'!F15,IF('DealScope sensitivity controls'!F15="","",11>'DealScope sensitivity controls'!F15))="",FALSE,IF(ISERROR(11>'DealScope sensitivity controls'!F15),11>'DealScope sensitivity controls'!F15,IF('DealScope sensitivity controls'!F15="","",11>'DealScope sensitivity controls'!F15))),IF('Model inputs'!B43="","",'Model inputs'!B43),0)))+IF(IF(IF(IF(ISERROR('Model inputs'!B29=1),'Model inputs'!B29=1,IF('Model inputs'!B29="","",'Model inputs'!B29=1))="",FALSE,IF(ISERROR('Model inputs'!B29=1),'Model inputs'!B29=1,IF('Model inputs'!B29="","",'Model inputs'!B29=1))),'Model inputs'!B43*MIN(MAX((12-'DealScope sensitivity controls'!F15)/'Model inputs'!B21,0),1),IF(IF(IF(ISERROR(12>'DealScope sensitivity controls'!F15),12>'DealScope sensitivity controls'!F15,IF('DealScope sensitivity controls'!F15="","",12>'DealScope sensitivity controls'!F15))="",FALSE,IF(ISERROR(12>'DealScope sensitivity controls'!F15),12>'DealScope sensitivity controls'!F15,IF('DealScope sensitivity controls'!F15="","",12>'DealScope sensitivity controls'!F15))),IF('Model inputs'!B43="","",'Model inputs'!B43),0))="",0,IF(IF(IF(ISERROR('Model inputs'!B29=1),'Model inputs'!B29=1,IF('Model inputs'!B29="","",'Model inputs'!B29=1))="",FALSE,IF(ISERROR('Model inputs'!B29=1),'Model inputs'!B29=1,IF('Model inputs'!B29="","",'Model inputs'!B29=1))),'Model inputs'!B43*MIN(MAX((12-'DealScope sensitivity controls'!F15)/'Model inputs'!B21,0),1),IF(IF(IF(ISERROR(12>'DealScope sensitivity controls'!F15),12>'DealScope sensitivity controls'!F15,IF('DealScope sensitivity controls'!F15="","",12>'DealScope sensitivity controls'!F15))="",FALSE,IF(ISERROR(12>'DealScope sensitivity controls'!F15),12>'DealScope sensitivity controls'!F15,IF('DealScope sensitivity controls'!F15="","",12>'DealScope sensitivity controls'!F15))),IF('Model inputs'!B43="","",'Model inputs'!B43),0))) -> 97.5 | I13: ='DealScope sensitivity compariso'!H13*'DealScope sensitivity compariso'!C13 -> 390000 | J13: ='DealScope sensitivity compariso'!I13*(1-'Model inputs'!B38)-'DealScope sensitivity compariso'!H13*('DealScope sensitivity compariso'!B13*'DealScope sensitivity compariso'!D13+'Model inputs'!B42*'Model inputs'!B41)-SUM('Model inputs'!B76,'Model inputs'!B77) -> 326468.5
A14: Credit rate $0.10 | B14: =IF(IF(IF(ISERROR('DealScope sensitivity controls'!H16=1),'DealScope sensitivity controls'!H16=1,IF('DealScope sensitivity controls'!H16="","",'DealScope sensitivity controls'!H16=1))="",FALSE,IF(ISERROR('DealScope sensitivity controls'!H16=1),'DealScope sensitivity controls'!H16=1,IF('DealScope sensitivity controls'!H16="","",'DealScope sensitivity controls'!H16=1))),'Model inputs'!B6/12*'DealScope sensitivity controls'!G16,IF('DealScope sensitivity controls'!B16="","",'DealScope sensitivity controls'!B16)) -> 4 | C14: =IF(EXACT("Annual deal-team","Annual deal-team"),('Model inputs'!B45/12+MAX('DealScope sensitivity compariso'!B14-'Model inputs'!B24/12,0)*'Model inputs'!B32)*(1-'DealScope sensitivity controls'!C16),('Model inputs'!B45/12+'Model inputs'!B9*'DealScope sensitivity compariso'!B14)*(1-'DealScope sensitivity controls'!C16)) -> 4000 | D14: ='Model inputs'!B15*'DealScope sensitivity controls'!E16*'DealScope sensitivity controls'!D16*'Model inputs'!B17+'Model inputs'!B30+'Model inputs'!B39+'Model inputs'!B19 -> 94.65 | E14: =IFERROR('DealScope sensitivity compariso'!C14/'DealScope sensitivity compariso'!B14,"") -> 1000 | F14: =IFERROR(('DealScope sensitivity compariso'!E14-'DealScope sensitivity compariso'!D14)/'DealScope sensitivity compariso'!E14,"") -> 0.90535 | G14: =IFERROR(('DealScope sensitivity compariso'!C14*(1-'Model inputs'!B38)-'DealScope sensitivity compariso'!B14*'DealScope sensitivity compariso'!D14-'Model inputs'!B42*'Model inputs'!B41)/'DealScope sensitivity compariso'!C14,"") -> 0.86785 | H14: ='Model inputs'!B117+IF(IF(IF(IF(ISERROR('Model inputs'!B29=1),'Model inputs'!B29=1,IF('Model inputs'!B29="","",'Model inputs'!B29=1))="",FALSE,IF(ISERROR('Model inputs'!B29=1),'Model inputs'!B29=1,IF('Model inputs'!B29="","",'Model inputs'!B29=1))),'Model inputs'!B43*MIN(MAX((11-'DealScope sensitivity controls'!F16)/'Model inputs'!B21,0),1),IF(IF(IF(ISERROR(11>'DealScope sensitivity controls'!F16),11>'DealScope sensitivity controls'!F16,IF('DealScope sensitivity controls'!F16="","",11>'DealScope sensitivity controls'!F16))="",FALSE,IF(ISERROR(11>'DealScope sensitivity controls'!F16),11>'DealScope sensitivity controls'!F16,IF('DealScope sensitivity controls'!F16="","",11>'DealScope sensitivity controls'!F16))),IF('Model inputs'!B43="","",'Model inputs'!B43),0))="",0,IF(IF(IF(ISERROR('Model inputs'!B29=1),'Model inputs'!B29=1,IF('Model inputs'!B29="","",'Model inputs'!B29=1))="",FALSE,IF(ISERROR('Model inputs'!B29=1),'Model inputs'!B29=1,IF('Model inputs'!B29="","",'Model inputs'!B29=1))),'Model inputs'!B43*MIN(MAX((11-'DealScope sensitivity controls'!F16)/'Model inputs'!B21,0),1),IF(IF(IF(ISERROR(11>'DealScope sensitivity controls'!F16),11>'DealScope sensitivity controls'!F16,IF('DealScope sensitivity controls'!F16="","",11>'DealScope sensitivity controls'!F16))="",FALSE,IF(ISERROR(11>'DealScope sensitivity controls'!F16),11>'DealScope sensitivity controls'!F16,IF('DealScope sensitivity controls'!F16="","",11>'DealScope sensitivity controls'!F16))),IF('Model inputs'!B43="","",'Model inputs'!B43),0)))+IF(IF(IF(IF(ISERROR('Model inputs'!B29=1),'Model inputs'!B29=1,IF('Model inputs'!B29="","",'Model inputs'!B29=1))="",FALSE,IF(ISERROR('Model inputs'!B29=1),'Model inputs'!B29=1,IF('Model inputs'!B29="","",'Model inputs'!B29=1))),'Model inputs'!B43*MIN(MAX((12-'DealScope sensitivity controls'!F16)/'Model inputs'!B21,0),1),IF(IF(IF(ISERROR(12>'DealScope sensitivity controls'!F16),12>'DealScope sensitivity controls'!F16,IF('DealScope sensitivity controls'!F16="","",12>'DealScope sensitivity controls'!F16))="",FALSE,IF(ISERROR(12>'DealScope sensitivity controls'!F16),12>'DealScope sensitivity controls'!F16,IF('DealScope sensitivity controls'!F16="","",12>'DealScope sensitivity controls'!F16))),IF('Model inputs'!B43="","",'Model inputs'!B43),0))="",0,IF(IF(IF(ISERROR('Model inputs'!B29=1),'Model inputs'!B29=1,IF('Model inputs'!B29="","",'Model inputs'!B29=1))="",FALSE,IF(ISERROR('Model inputs'!B29=1),'Model inputs'!B29=1,IF('Model inputs'!B29="","",'Model inputs'!B29=1))),'Model inputs'!B43*MIN(MAX((12-'DealScope sensitivity controls'!F16)/'Model inputs'!B21,0),1),IF(IF(IF(ISERROR(12>'DealScope sensitivity controls'!F16),12>'DealScope sensitivity controls'!F16,IF('DealScope sensitivity controls'!F16="","",12>'DealScope sensitivity controls'!F16))="",FALSE,IF(ISERROR(12>'DealScope sensitivity controls'!F16),12>'DealScope sensitivity controls'!F16,IF('DealScope sensitivity controls'!F16="","",12>'DealScope sensitivity controls'!F16))),IF('Model inputs'!B43="","",'Model inputs'!B43),0))) -> 97.5 | I14: ='DealScope sensitivity compariso'!H14*'DealScope sensitivity compariso'!C14 -> 390000 | J14: ='DealScope sensitivity compariso'!I14*(1-'Model inputs'!B38)-'DealScope sensitivity compariso'!H14*('DealScope sensitivity compariso'!B14*'DealScope sensitivity compariso'!D14+'Model inputs'!B42*'Model inputs'!B41)-SUM('Model inputs'!B76,'Model inputs'!B77) -> 325961.5
