Workbook

Sheet DealScope editable drivers
A1: DealScope editable drivers
A2: DealScope — Assumptions · Main Scenario
A4: Variable / dimension | B4: Value
A5: Target paying customers | B5: =5 -> 5
A6: Audits per customer per month | B6: =3 -> 3
A7: Sales delay months | B7: =0 -> 0
A8: Linear customer ramp switch | B8: =0 -> 0
A9: Selected pricing model | B9: ="Per audit — base" -> Per audit — base
A10: Price discount | B10: =0 -> 0
A11: Data and model cost multiplier | B11: =1 -> 1
A12: Crustdata credits per audit | B12: =26 -> 26
A13: Crustdata credit cap | B13: =40 -> 40
A14: Crustdata dollars per credit | B14: =0.1 -> 0.1
A15: Flash inference per audit | B15: =0.05 -> 0.05
A16: Escalation cost multiple | B16: =5 -> 5
A17: Escalation share | B17: =0 -> 0
A18: QA hours per audit | B18: =1.5 -> 1.5
A19: QA dollars per hour | B19: =60 -> 60
A20: Support hours per customer per month | B20: =0.5 -> 0.5
A21: Support dollars per hour | B21: =60 -> 60
A22: Delivery tooling per audit | B22: =2 -> 2
A23: Processing rate | B23: =0.03 -> 0.03
A24: Hosting monthly | B24: =150 -> 150
A25: Software monthly | B25: =100 -> 100
A26: Data minimum monthly | B26: =0 -> 0
A27: Compliance monthly | B27: =500 -> 500
A28: Compliance start month | B28: =6 -> 6
A29: Founder salary monthly | B29: =0 -> 0
A30: Sales marketing monthly | B30: =500 -> 500
A31: Cash supplied switch | B31: =0 -> 0
A32: Available opening cash | B32: =""
A33: Actual credit allocation | B33: =200 -> 200
A34: Annual included audits | B34: =24 -> 24
A35: Annual overage price | B35: =1000 -> 1000
A36: Annual fee | B36: =24000 -> 24000
A37: Hybrid workspace fee | B37: =6000 -> 6000
A38: Hybrid audit price | B38: =1000 -> 1000
A39: Annual utilization | B39: =1 -> 1
A40: Forecast start date | B40: =DATE(2026,10,1) -> 46296
A41: Forecast months | B41: =12 -> 12
...

Sheet DealScope pricing inputs
A1: DealScope pricing inputs
A2: DealScope — Assumptions · Main Scenario
A4: Variable / dimension | B4: Audit list price | C4: Upfront subscription fee | D4: Included annual audits | E4: Overage audit price
A5: Per audit — low | B5: =750 -> 750 | C5: =0 -> 0 | D5: =0 -> 0 | E5: =0 -> 0
A6: Per audit — base | B6: =1500 -> 1500 | C6: =0 -> 0 | D6: =0 -> 0 | E6: =0 -> 0
A7: Per audit — high | B7: =3000 -> 3000 | C7: =0 -> 0 | D7: =0 -> 0 | E7: =0 -> 0
A8: Annual deal-team | B8: =0 -> 0 | C8: =IF('DealScope editable drivers'!B36="","",'DealScope editable drivers'!B36) -> 24000 | D8: =IF('DealScope editable drivers'!B34="","",'DealScope editable drivers'!B34) -> 24 | E8: =IF('DealScope editable drivers'!B35="","",'DealScope editable drivers'!B35) -> 1000
A9: Hybrid | B9: =IF('DealScope editable drivers'!B38="","",'DealScope editable drivers'!B38) -> 1000 | C9: =IF('DealScope editable drivers'!B37="","",'DealScope editable drivers'!B37) -> 6000 | D9: =0 -> 0 | E9: =0 -> 0

Sheet DealScope delivery unit costs
A1: DealScope delivery unit costs
A2: DealScope — Assumptions · Main Scenario
A4: Variable / dimension | B4: Value
A5: Crustdata cost per audit | B5: ='DealScope editable drivers'!B12*'DealScope editable drivers'!B14*'DealScope editable drivers'!B11 -> 2.6
A6: LLM cost per audit | B6: ='DealScope editable drivers'!B15*(1+'DealScope editable drivers'!B17*('DealScope editable drivers'!B16-1))*'DealScope editable drivers'!B11 -> 0.05
A7: QA cost per audit | B7: ='DealScope editable drivers'!B18*'DealScope editable drivers'!B19 -> 90
A8: Delivery cost per audit | B8: ='DealScope delivery unit costs'!B5+'DealScope delivery unit costs'!B6+'DealScope delivery unit costs'!B7+'DealScope editable drivers'!B22 -> 94.65
A9: Credits within cap switch | B9: =IF(IF(IF(ISERROR('DealScope editable drivers'!B12<='DealScope editable drivers'!B13),'DealScope editable drivers'!B12<='DealScope editable drivers'!B13,IF(OR('DealScope editable drivers'!B12="",'DealScope editable drivers'!B13=""),"",'DealScope editable drivers'!B12<='DealScope editable drivers'!B13))="",FALSE,IF(ISERROR('DealScope editable drivers'!B12<='DealScope editable drivers'!B13),'DealScope editable drivers'!B12<='DealScope editable drivers'!B13,IF(OR('DealScope editable drivers'!B12="",'DealScope editable drivers'!B13=""),"",'DealScope editable drivers'!B12<='DealScope editable drivers'!B13))),1,0) -> 1
A10: Audits covered by allocation | B10: =FLOOR('DealScope editable drivers'!B33/'DealScope editable drivers'!B12,1) -> 7
