Workbook

Sheet DealScope scenario comparison
A1: DealScope scenario comparison
A2: DealScope — Business summary · Growth
A4: Variable / dimension | B4: Value | C4: Value > Conservative
A5: Forecast earned revenue | B5: =SUM('Model inputs'!B305,'Model inputs'!B306) -> 390000 | C5: =SUM('Model inputs'!B307,'Model inputs'!B308) -> 30000
A6: Forecast cash collections | B6: =SUM('Model inputs'!B309,'Model inputs'!B310) -> 555000 | C6: =SUM('Model inputs'!B311,'Model inputs'!B312) -> 30000
A7: Forecast audits | B7: =SUM('Model inputs'!B313,'Model inputs'!B314) -> 390 | C7: =SUM('Model inputs'!B315,'Model inputs'!B316) -> 40
A8: Forecast gross margin | B8: =IFERROR('Model inputs'!B16/'DealScope scenario comparison'!B5,"") -> 0.90535 | C8: =IFERROR('Model inputs'!B17/'DealScope scenario comparison'!C5,"") -> 0.87203333
A9: Forecast contribution margin | B9: =IFERROR('Model inputs'!B14/'DealScope scenario comparison'!B5,"") -> 0.86785 | C9: =IFERROR('Model inputs'!B15/'DealScope scenario comparison'!C5,"") -> 0.82203333
A10: Forecast net cash burn | B10: =SUM('Model inputs'!B317,'Model inputs'!B318) -> -486011.5 | C10: =SUM('Model inputs'!B319,'Model inputs'!B320) -> -12161
A11: Peak modeled funding need | B11: =MAX(IF(IF(AND('Model inputs'!B20<=DATE(2026,1,1),DATE(2026,1,1)<=EDATE('Model inputs'!B20,'Model inputs'!B18-1*1))="",FALSE,AND('Model inputs'!B20<=DATE(2026,1,1),DATE(2026,1,1)<=EDATE('Model inputs'!B20,'Model inputs'!B18-1*1))),'Model inputs'!C12,""),IF(IF(AND('Model inputs'!B20<=DATE(2026,2,1),DATE(2026,2,1)<=EDATE('Model inputs'!B20,'Model inputs'!B18-1*1))="",FALSE,AND('Model inputs'!B20<=DATE(2026,2,1),DATE(2026,2,1)<=EDATE('Model inputs'!B20,'Model inputs'!B18-1*1))),'Model inputs'!D12,""),IF(IF(AND('Model inputs'!B20<=DATE(2026,3,1),DATE(2026,3,1)<=EDATE('Model inputs'!B20,'Model inputs'!B18-1*1))="",FALSE,AND('Model inputs'!B20<=DATE(2026,3,1),DATE(2026,3,1)<=EDATE('Model inputs'!B20,'Model inputs'!B18-1*1))),'Model inputs'!E12,""),IF(IF(AND('Model inputs'!B20<=DATE(2026,4,1),DATE(2026,4,1)<=EDATE('Model inputs'!B20,'Model inputs'!B18-1*1))="",FALSE,AND('Model inputs'!B20<=DATE(2026,4,1),DATE(2026,4,1)<=EDATE('Model inputs'!B20,'Model inputs'!B18-1*1))),'Model inputs'!F12,""),IF(IF(AND('Model inputs'!B20<=DATE(2026,5,1),DATE(2026,5,1)<=EDATE('Model inputs'!B20,'Model inputs'!B18-1*1))="",FALSE,AND('Model inputs'!B20<=DATE(2026,5,1),DATE(2026,5,1)<=EDATE('Model inputs'!B20,'Model inputs'!B18-1*1))),'Model inputs'!G12,""),IF(IF(AND('Model inputs'!B20<=DATE(2026,6,1),DATE(2026,6,1)<=EDATE('Model inputs'!B20,'Model inputs'!B18-1*1))="",FALSE,AND('Model inputs'!B20<=DATE(2026,6,1),DATE(2026,6,1)<=EDATE('Model inputs'!B20,'Model inputs'!B18-1*1))),'Model inputs'!H12,""),IF(IF(AND('Model inputs'!B20<=DATE(2026,7,1),DATE(2026,7,1)<=EDATE('Model inputs'!B20,'Model inputs'!B18-1*1))="",FALSE,AND('Model inputs'!B20<=DATE(2026,7,1),DATE(2026,7,1)<=EDATE('Model inputs'!B20,'Model inputs'!B18-1*1))),'Model inputs'!I12,""),IF(IF(AND('Model inputs'!B20<=DATE(2026,8,1),DATE(2026,8,1)<=EDATE('Model inputs'!B20,'Model inputs'!B18-1*1))="",FALSE,AND('Model inputs'!B20<=DATE(2026,8,1),DATE(2026,8,1)<=EDATE('Model inputs'!B20,'Model inputs'!B18-1*1))),'Model inputs'!J12,""),IF(IF(AND('Model inputs'!B20<=DATE(2026,9,1),DATE(2026,9,1)<=EDATE('Model inputs'!B20,'Model inputs'!B18-1*1))="",FALSE,AND('Model inputs'!B20<=DATE(2026,9,1),DATE(2026,9,1)<=EDATE('Model inputs'!B20,'Model inputs'!B18-1*1))),'Model inputs'!K12,""),IF(IF(AND('Model inputs'!B20<=DATE(2026,10,1),DATE(2026,10,1)<=EDATE('Model inputs'!B20,'Model inputs'!B18-1*1))="",FALSE,AND('Model inputs'!B20<=DATE(2026,10,1),DATE(2026,10,1)<=EDATE('Model inputs'!B20,'Model inputs'!B18-1*1))),'Model inputs'!L12,""),IF(IF(AND('Model inputs'!B20<=DATE(2026,11,1),DATE(2026,11,1)<=EDATE('Model inputs'!B20,'Model inputs'!B18-1*1))="",FALSE,AND('Model inputs'!B20<=DATE(2026,11,1),DATE(2026,11,1)<=EDATE('Model inputs'!B20,'Model inputs'!B18-1*1))),'Model inputs'!M12,""),IF(IF(AND('Model inputs'!B20<=DATE(2026,12,1),DATE(2026,12,1)<=EDATE('Model inputs'!B20,'Model inputs'!B18-1*1))="",FALSE,AND('Model inputs'!B20<=DATE(2026,12,1),DATE(2026,12,1)<=EDATE('Model inputs'!B20,'Model inputs'!B18-1*1))),'Model inputs'!N12,""),IF(IF(AND('Model inputs'!B20<=DATE(2027,1,1),DATE(2027,1,1)<=EDATE('Model inputs'!B20,'Model inputs'!B18-1*1))="",FALSE,AND('Model inputs'!B20<=DATE(2027,1,1),DATE(2027,1,1)<=EDATE('Model inputs'!B20,'Model inputs'!B18-1*1))),'Model inputs'!O12,""),IF(IF(AND('Model inputs'!B20<=DATE(2027,2,1),DATE(2027,2,1)<=EDATE('Model inputs'!B20,'Model inputs'!B18-1*1))="",FALSE,AND('Model inputs'!B20<=DATE(2027,2,1),DATE(2027,2,1)<=EDATE('Model inputs'!B20,'Model inputs'!B18-1*1))),'Model inputs'!P12,""),IF(IF(AND('Model inputs'!B20<=DATE(2027,3,1),DATE(2027,3,1)<=EDATE('Model inputs'!B20,'Model inputs'!B18-1*1))="",FALSE,AND('Model inputs'!B20<=DATE(2027,3,1),DATE(2027,3,1)<=EDATE('Model inputs'!B20,'Model inputs'!B18-1*1))),'Model inputs'!Q12,""),IF(IF(AND('Model inputs'!B20<=DATE(2027,4,1),DATE(2027,4,1)<=EDATE('Model inputs'!B20,'Model inputs'!B18-1*1))="",FALSE,AND('Model inputs'!B20<=DATE(2027,4,1),DATE(2027,4,1)<=EDATE('Model inputs'!B20,'Model inputs'!B18-1*1))),'Model inputs'!R12,""),IF(IF(AND('Model inputs'!B20<=DATE(2027,5,1),DATE(2027,5,1)<=EDATE('Model inputs'!B20,'Model inputs'!B18-1*1))="",FALSE,AND('Model inputs'!B20<=DATE(2027,5,1),DATE(2027,5,1)<=EDATE('Model inputs'!B20,'Model inputs'!B18-1*1))),'Model inputs'!S12,""),IF(IF(AND('Model inputs'!B20<=DATE(2027,6,1),DATE(2027,6,1)<=EDATE('Model inputs'!B20,'Model inputs'!B18-1*1))="",FALSE,AND('Model inputs'!B20<=DATE(2027,6,1),DATE(2027,6,1)<=EDATE('Model inputs'!B20,'Model inputs'!B18-1*1))),'Model inputs'!T12,""),IF(IF(AND('Model inputs'!B20<=DATE(2027,7,1),DATE(2027,7,1)<=EDATE('Model inputs'!B20,'Model inputs'!B18-1*1))="",FALSE,AND('Model inputs'!B20<=DATE(2027,7,1),DATE(2027,7,1)<=EDATE('Model inputs'!B20,'Model inputs'!B18-1*1))),'Model inputs'!U12,""),IF(IF(AND('Model inputs'!B20<=DATE(2027,8,1),DATE(2027,8,1)<=EDATE('Model inputs'!B20,'Model inputs'!B18-1*1))="",FALSE,AND('Model inputs'!B20<=DATE(2027,8,1),DATE(2027,8,1)<=EDATE('Model inputs'!B20,'Model inputs'!B18-1*1))),'Model inputs'!V12,""),IF(IF(AND('Model inputs'!B20<=DATE(2027,9,1),DATE(2027,9,1)<=EDATE('Model inputs'!B20,'Model inputs'!B18-1*1))="",FALSE,AND('Model inputs'!B20<=DATE(2027,9,1),DATE(2027,9,1)<=EDATE('Model inputs'!B20,'Model inputs'!B18-1*1))),'Model inputs'!W12,""),IF(IF(AND('Model inputs'!B20<=DATE(2027,10,1),DATE(2027,10,1)<=EDATE('Model inputs'!B20,'Model inputs'!B18-1*1))="",FALSE,AND('Model inputs'!B20<=DATE(2027,10,1),DATE(2027,10,1)<=EDATE('Model inputs'!B20,'Model inputs'!B18-1*1))),'Model inputs'!X12,""),IF(IF(AND('Model inputs'!B20<=DATE(2027,11,1),DATE(2027,11,1)<=EDATE('Model inputs'!B20,'Model inputs'!B18-1*1))="",FALSE,AND('Model inputs'!B20<=DATE(2027,11,1),DATE(2027,11,1)<=EDATE('Model inputs'!B20,'Model inputs'!B18-1*1))),'Model inputs'!Y12,""),IF(IF(AND('Model inputs'!B20<=DATE(2027,12,1),DATE(2027,12,1)<=EDATE('Model inputs'!B20,'Model inputs'!B18-1*1))="",FALSE,AND('Model inputs'!B20<=DATE(2027,12,1),DATE(2027,12,1)<=EDATE('Model inputs'!B20,'Model inputs'!B18-1*1))),'Model inputs'!Z12,"")) -> 0 | C11: =MAX(IF(IF(AND('Model inputs'!B21<=DATE(2026,1,1),DATE(2026,1,1)<=EDATE('Model inputs'!B21,'Model inputs'!B19-1*1))="",FALSE,AND('Model inputs'!B21<=DATE(2026,1,1),DATE(2026,1,1)<=EDATE('Model inputs'!B21,'Model inputs'!B19-1*1))),'Model inputs'!C13,""),IF(IF(AND('Model inputs'!B21<=DATE(2026,2,1),DATE(2026,2,1)<=EDATE('Model inputs'!B21,'Model inputs'!B19-1*1))="",FALSE,AND('Model inputs'!B21<=DATE(2026,2,1),DATE(2026,2,1)<=EDATE('Model inputs'!B21,'Model inputs'!B19-1*1))),'Model inputs'!D13,""),IF(IF(AND('Model inputs'!B21<=DATE(2026,3,1),DATE(2026,3,1)<=EDATE('Model inputs'!B21,'Model inputs'!B19-1*1))="",FALSE,AND('Model inputs'!B21<=DATE(2026,3,1),DATE(2026,3,1)<=EDATE('Model inputs'!B21,'Model inputs'!B19-1*1))),'Model inputs'!E13,""),IF(IF(AND('Model inputs'!B21<=DATE(2026,4,1),DATE(2026,4,1)<=EDATE('Model inputs'!B21,'Model inputs'!B19-1*1))="",FALSE,AND('Model inputs'!B21<=DATE(2026,4,1),DATE(2026,4,1)<=EDATE('Model inputs'!B21,'Model inputs'!B19-1*1))),'Model inputs'!F13,""),IF(IF(AND('Model inputs'!B21<=DATE(2026,5,1),DATE(2026,5,1)<=EDATE('Model inputs'!B21,'Model inputs'!B19-1*1))="",FALSE,AND('Model inputs'!B21<=DATE(2026,5,1),DATE(2026,5,1)<=EDATE('Model inputs'!B21,'Model inputs'!B19-1*1))),'Model inputs'!G13,""),IF(IF(AND('Model inputs'!B21<=DATE(2026,6,1),DATE(2026,6,1)<=EDATE('Model inputs'!B21,'Model inputs'!B19-1*1))="",FALSE,AND('Model inputs'!B21<=DATE(2026,6,1),DATE(2026,6,1)<=EDATE('Model inputs'!B21,'Model inputs'!B19-1*1))),'Model inputs'!H13,""),IF(IF(AND('Model inputs'!B21<=DATE(2026,7,1),DATE(2026,7,1)<=EDATE('Model inputs'!B21,'Model inputs'!B19-1*1))="",FALSE,AND('Model inputs'!B21<=DATE(2026,7,1),DATE(2026,7,1)<=EDATE('Model inputs'!B21,'Model inputs'!B19-1*1))),'Model inputs'!I13,""),IF(IF(AND('Model inputs'!B21<=DATE(2026,8,1),DATE(2026,8,1)<=EDATE('Model inputs'!B21,'Model inputs'!B19-1*1))="",FALSE,AND('Model inputs'!B21<=DATE(2026,8,1),DATE(2026,8,1)<=EDATE('Model inputs'!B21,'Model inputs'!B19-1*1))),'Model inputs'!J13,""),IF(IF(AND('Model inputs'!B21<=DATE(2026,9,1),DATE(2026,9,1)<=EDATE('Model inputs'!B21,'Model inputs'!B19-1*1))="",FALSE,AND('Model inputs'!B21<=DATE(2026,9,1),DATE(2026,9,1)<=EDATE('Model inputs'!B21,'Model inputs'!B19-1*1))),'Model inputs'!K13,""),IF(IF(AND('Model inputs'!B21<=DATE(2026,10,1),DATE(2026,10,1)<=EDATE('Model inputs'!B21,'Model inputs'!B19-1*1))="",FALSE,AND('Model inputs'!B21<=DATE(2026,10,1),DATE(2026,10,1)<=EDATE('Model inputs'!B21,'Model inputs'!B19-1*1))),'Model inputs'!L13,""),IF(IF(AND('Model inputs'!B21<=DATE(2026,11,1),DATE(2026,11,1)<=EDATE('Model inputs'!B21,'Model inputs'!B19-1*1))="",FALSE,AND('Model inputs'!B21<=DATE(2026,11,1),DATE(2026,11,1)<=EDATE('Model inputs'!B21,'Model inputs'!B19-1*1))),'Model inputs'!M13,""),IF(IF(AND('Model inputs'!B21<=DATE(2026,12,1),DATE(2026,12,1)<=EDATE('Model inputs'!B21,'Model inputs'!B19-1*1))="",FALSE,AND('Model inputs'!B21<=DATE(2026,12,1),DATE(2026,12,1)<=EDATE('Model inputs'!B21,'Model inputs'!B19-1*1))),'Model inputs'!N13,""),IF(IF(AND('Model inputs'!B21<=DATE(2027,1,1),DATE(2027,1,1)<=EDATE('Model inputs'!B21,'Model inputs'!B19-1*1))="",FALSE,AND('Model inputs'!B21<=DATE(2027,1,1),DATE(2027,1,1)<=EDATE('Model inputs'!B21,'Model inputs'!B19-1*1))),'Model inputs'!O13,""),IF(IF(AND('Model inputs'!B21<=DATE(2027,2,1),DATE(2027,2,1)<=EDATE('Model inputs'!B21,'Model inputs'!B19-1*1))="",FALSE,AND('Model inputs'!B21<=DATE(2027,2,1),DATE(2027,2,1)<=EDATE('Model inputs'!B21,'Model inputs'!B19-1*1))),'Model inputs'!P13,""),IF(IF(AND('Model inputs'!B21<=DATE(2027,3,1),DATE(2027,3,1)<=EDATE('Model inputs'!B21,'Model inputs'!B19-1*1))="",FALSE,AND('Model inputs'!B21<=DATE(2027,3,1),DATE(2027,3,1)<=EDATE('Model inputs'!B21,'Model inputs'!B19-1*1))),'Model inputs'!Q13,""),IF(IF(AND('Model inputs'!B21<=DATE(2027,4,1),DATE(2027,4,1)<=EDATE('Model inputs'!B21,'Model inputs'!B19-1*1))="",FALSE,AND('Model inputs'!B21<=DATE(2027,4,1),DATE(2027,4,1)<=EDATE('Model inputs'!B21,'Model inputs'!B19-1*1))),'Model inputs'!R13,""),IF(IF(AND('Model inputs'!B21<=DATE(2027,5,1),DATE(2027,5,1)<=EDATE('Model inputs'!B21,'Model inputs'!B19-1*1))="",FALSE,AND('Model inputs'!B21<=DATE(2027,5,1),DATE(2027,5,1)<=EDATE('Model inputs'!B21,'Model inputs'!B19-1*1))),'Model inputs'!S13,""),IF(IF(AND('Model inputs'!B21<=DATE(2027,6,1),DATE(2027,6,1)<=EDATE('Model inputs'!B21,'Model inputs'!B19-1*1))="",FALSE,AND('Model inputs'!B21<=DATE(2027,6,1),DATE(2027,6,1)<=EDATE('Model inputs'!B21,'Model inputs'!B19-1*1))),'Model inputs'!T13,""),IF(IF(AND('Model inputs'!B21<=DATE(2027,7,1),DATE(2027,7,1)<=EDATE('Model inputs'!B21,'Model inputs'!B19-1*1))="",FALSE,AND('Model inputs'!B21<=DATE(2027,7,1),DATE(2027,7,1)<=EDATE('Model inputs'!B21,'Model inputs'!B19-1*1))),'Model inputs'!U13,""),IF(IF(AND('Model inputs'!B21<=DATE(2027,8,1),DATE(2027,8,1)<=EDATE('Model inputs'!B21,'Model inputs'!B19-1*1))="",FALSE,AND('Model inputs'!B21<=DATE(2027,8,1),DATE(2027,8,1)<=EDATE('Model inputs'!B21,'Model inputs'!B19-1*1))),'Model inputs'!V13,""),IF(IF(AND('Model inputs'!B21<=DATE(2027,9,1),DATE(2027,9,1)<=EDATE('Model inputs'!B21,'Model inputs'!B19-1*1))="",FALSE,AND('Model inputs'!B21<=DATE(2027,9,1),DATE(2027,9,1)<=EDATE('Model inputs'!B21,'Model inputs'!B19-1*1))),'Model inputs'!W13,""),IF(IF(AND('Model inputs'!B21<=DATE(2027,10,1),DATE(2027,10,1)<=EDATE('Model inputs'!B21,'Model inputs'!B19-1*1))="",FALSE,AND('Model inputs'!B21<=DATE(2027,10,1),DATE(2027,10,1)<=EDATE('Model inputs'!B21,'Model inputs'!B19-1*1))),'Model inputs'!X13,""),IF(IF(AND('Model inputs'!B21<=DATE(2027,11,1),DATE(2027,11,1)<=EDATE('Model inputs'!B21,'Model inputs'!B19-1*1))="",FALSE,AND('Model inputs'!B21<=DATE(2027,11,1),DATE(2027,11,1)<=EDATE('Model inputs'!B21,'Model inputs'!B19-1*1))),'Model inputs'!Y13,""),IF(IF(AND('Model inputs'!B21<=DATE(2027,12,1),DATE(2027,12,1)<=EDATE('Model inputs'!B21,'Model inputs'!B19-1*1))="",FALSE,AND('Model inputs'!B21<=DATE(2027,12,1),DATE(2027,12,1)<=EDATE('Model inputs'!B21,'Model inputs'!B19-1*1))),'Model inputs'!Z13,"")) -> 1500
A12: Conditional runway months | B12: =IF(IF(IF(IFERROR(IF(ISERROR('Model inputs'!B10=1),'Model inputs'!B10=1,IF('Model inputs'!B10="","",'Model inputs'!B10=1))=FALSE,FALSE),FALSE,IF(IFERROR(IF(ISERROR('Model inputs'!B8>0),'Model inputs'!B8>0,IF('Model inputs'!B8="","",'Model inputs'!B8>0))=FALSE,FALSE),FALSE,IF(OR(IF(ISERROR('Model inputs'!B10=1),'Model inputs'!B10=1,IF('Model inputs'!B10="","",'Model inputs'!B10=1))="",IF(ISERROR('Model inputs'!B8>0),'Model inputs'!B8>0,IF('Model inputs'!B8="","",'Model inputs'!B8>0))=""),"",AND(IF(ISERROR('Model inputs'!B10=1),'Model inputs'!B10=1,IF('Model inputs'!B10="","",'Model inputs'!B10=1)),IF(ISERROR('Model inputs'!B8>0),'Model inputs'!B8>0,IF('Model inputs'!B8="","",'Model inputs'!B8>0))))))="",FALSE,IF(IFERROR(IF(ISERROR('Model inputs'!B10=1),'Model inputs'!B10=1,IF('Model inputs'!B10="","",'Model inputs'!B10=1))=FALSE,FALSE),FALSE,IF(IFERROR(IF(ISERROR('Model inputs'!B8>0),'Model inputs'!B8>0,IF('Model inputs'!B8="","",'Model inputs'!B8>0))=FALSE,FALSE),FALSE,IF(OR(IF(ISERROR('Model inputs'!B10=1),'Model inputs'!B10=1,IF('Model inputs'!B10="","",'Model inputs'!B10=1))="",IF(ISERROR('Model inputs'!B8>0),'Model inputs'!B8>0,IF('Model inputs'!B8="","",'Model inputs'!B8>0))=""),"",AND(IF(ISERROR('Model inputs'!B10=1),'Model inputs'!B10=1,IF('Model inputs'!B10="","",'Model inputs'!B10=1)),IF(ISERROR('Model inputs'!B8>0),'Model inputs'!B8>0,IF('Model inputs'!B8="","",'Model inputs'!B8>0))))))),IF('Model inputs'!B6="",0,'Model inputs'!B6)/'Model inputs'!B8,"") | C12: =IF(IF(IF(IFERROR(IF(ISERROR('Model inputs'!B11=1),'Model inputs'!B11=1,IF('Model inputs'!B11="","",'Model inputs'!B11=1))=FALSE,FALSE),FALSE,IF(IFERROR(IF(ISERROR('Model inputs'!B9>0),'Model inputs'!B9>0,IF('Model inputs'!B9="","",'Model inputs'!B9>0))=FALSE,FALSE),FALSE,IF(OR(IF(ISERROR('Model inputs'!B11=1),'Model inputs'!B11=1,IF('Model inputs'!B11="","",'Model inputs'!B11=1))="",IF(ISERROR('Model inputs'!B9>0),'Model inputs'!B9>0,IF('Model inputs'!B9="","",'Model inputs'!B9>0))=""),"",AND(IF(ISERROR('Model inputs'!B11=1),'Model inputs'!B11=1,IF('Model inputs'!B11="","",'Model inputs'!B11=1)),IF(ISERROR('Model inputs'!B9>0),'Model inputs'!B9>0,IF('Model inputs'!B9="","",'Model inputs'!B9>0))))))="",FALSE,IF(IFERROR(IF(ISERROR('Model inputs'!B11=1),'Model inputs'!B11=1,IF('Model inputs'!B11="","",'Model inputs'!B11=1))=FALSE,FALSE),FALSE,IF(IFERROR(IF(ISERROR('Model inputs'!B9>0),'Model inputs'!B9>0,IF('Model inputs'!B9="","",'Model inputs'!B9>0))=FALSE,FALSE),FALSE,IF(OR(IF(ISERROR('Model inputs'!B11=1),'Model inputs'!B11=1,IF('Model inputs'!B11="","",'Model inputs'!B11=1))="",IF(ISERROR('Model inputs'!B9>0),'Model inputs'!B9>0,IF('Model inputs'!B9="","",'Model inputs'!B9>0))=""),"",AND(IF(ISERROR('Model inputs'!B11=1),'Model inputs'!B11=1,IF('Model inputs'!B11="","",'Model inputs'!B11=1)),IF(ISERROR('Model inputs'!B9>0),'Model inputs'!B9>0,IF('Model inputs'!B9="","",'Model inputs'!B9>0))))))),IF('Model inputs'!B7="",0,'Model inputs'!B7)/'Model inputs'!B9,"")

Sheet Model inputs
A1: Model inputs
A2: Integration values are aggregated snapshots; raw source records are not included.
A4: Variables
A5: Variable / segment | B5: Value | C5: 2026-01 | D5: 2026-02 | E5: 2026-03 | F5: 2026-04 | G5: 2026-05 | H5: 2026-06 | I5: 2026-07 | J5: 2026-08 | K5: 2026-09 | L5: 2026-10 | M5: 2026-11 | N5: 2026-12 | O5: 2027-01 | P5: 2027-02 | Q5: 2027-03 | R5: 2027-04 | S5: 2027-05 | T5: 2027-06 | U5: 2027-07 | V5: 2027-08 | W5: 2027-09 | X5: 2027-10 | Y5: 2027-11 | Z5: 2027-12 | AA5: Value
A6: Available opening cash · Growth | B6: =""
A7: Available opening cash · Conservative | B7: =""
A8: Average monthly net cash burn · Growth | B8: ='DealScope scenario comparison'!B10/'Model inputs'!B18 -> -40500.958
A9: Average monthly net cash burn · Conservative | B9: ='DealScope scenario comparison'!C10/'Model inputs'!B19 -> -1013.4167
A10: Cash supplied switch · Growth | B10: =0 -> 0
A11: Cash supplied switch · Conservative | B11: =0 -> 0
A12: Cumulative funding gap · Growth | C12: 0 | D12: 0 | E12: 0 | F12: 0 | G12: 0 | H12: 0 | I12: 0 | J12: 0 | K12: 0 | L12: =MAX(IF(IF(IF(IF(ISERROR('Model inputs'!L84=1),'Model inputs'!L84=1,IF('Model inputs'!L84="","",'Model inputs'!L84=1))="",FALSE,IF(ISERROR('Model inputs'!L84=1),'Model inputs'!L84=1,IF('Model inputs'!L84="","",'Model inputs'!L84=1))),0,IF('Model inputs'!K54="","",'Model inputs'!K54))="",0,IF(IF(IF(ISERROR('Model inputs'!L84=1),'Model inputs'!L84=1,IF('Model inputs'!L84="","",'Model inputs'!L84=1))="",FALSE,IF(ISERROR('Model inputs'!L84=1),'Model inputs'!L84=1,IF('Model inputs'!L84="","",'Model inputs'!L84=1))),0,IF('Model inputs'!K54="","",'Model inputs'!K54)))+'Model inputs'!L28,0) -> 0 | M12: =MAX(IF(IF(IF(IF(ISERROR('Model inputs'!M84=1),'Model inputs'!M84=1,IF('Model inputs'!M84="","",'Model inputs'!M84=1))="",FALSE,IF(ISERROR('Model inputs'!M84=1),'Model inputs'!M84=1,IF('Model inputs'!M84="","",'Model inputs'!M84=1))),0,IF('Model inputs'!L54="","",'Model inputs'!L54))="",0,IF(IF(IF(ISERROR('Model inputs'!M84=1),'Model inputs'!M84=1,IF('Model inputs'!M84="","",'Model inputs'!M84=1))="",FALSE,IF(ISERROR('Model inputs'!M84=1),'Model inputs'!M84=1,IF('Model inputs'!M84="","",'Model inputs'!M84=1))),0,IF('Model inputs'!L54="","",'Model inputs'!L54)))+'Model inputs'!M28,0) -> 0 | N12: =MAX(IF(IF(IF(IF(ISERROR('Model inputs'!N84=1),'Model inputs'!N84=1,IF('Model inputs'!N84="","",'Model inputs'!N84=1))="",FALSE,IF(ISERROR('Model inputs'!N84=1),'Model inputs'!N84=1,IF('Model inputs'!N84="","",'Model inputs'!N84=1))),0,IF('Model inputs'!M54="","",'Model inputs'!M54))="",0,IF(IF(IF(ISERROR('Model inputs'!N84=1),'Model inputs'!N84=1,IF('Model inputs'!N84="","",'Model inputs'!N84=1))="",FALSE,IF(ISERROR('Model inputs'!N84=1),'Model inputs'!N84=1,IF('Model inputs'!N84="","",'Model inputs'!N84=1))),0,IF('Model inputs'!M54="","",'Model inputs'!M54)))+'Model inputs'!N28,0) -> 0 | O12: =MAX(IF(IF(IF(IF(ISERROR('Model inputs'!O84=1),'Model inputs'!O84=1,IF('Model inputs'!O84="","",'Model inputs'!O84=1))="",FALSE,IF(ISERROR('Model inputs'!O84=1),'Model inputs'!O84=1,IF('Model inputs'!O84="","",'Model inputs'!O84=1))),0,IF('Model inputs'!N54="","",'Model inputs'!N54))="",0,IF(IF(IF(ISERROR('Model inputs'!O84=1),'Model inputs'!O84=1,IF('Model inputs'!O84="","",'Model inputs'!O84=1))="",FALSE,IF(ISERROR('Model inputs'!O84=1),'Model inputs'!O84=1,IF('Model inputs'!O84="","",'Model inputs'!O84=1))),0,IF('Model inputs'!N54="","",'Model inputs'!N54)))+'Model inputs'!O28,0) -> 0 | P12: =MAX(IF(IF(IF(IF(ISERROR('Model inputs'!P84=1),'Model inputs'!P84=1,IF('Model inputs'!P84="","",'Model inputs'!P84=1))="",FALSE,IF(ISERROR('Model inputs'!P84=1),'Model inputs'!P84=1,IF('Model inputs'!P84="","",'Model inputs'!P84=1))),0,IF('Model inputs'!O54="","",'Model inputs'!O54))="",0,IF(IF(IF(ISERROR('Model inputs'!P84=1),'Model inputs'!P84=1,IF('Model inputs'!P84="","",'Model inputs'!P84=1))="",FALSE,IF(ISERROR('Model inputs'!P84=1),'Model inputs'!P84=1,IF('Model inputs'!P84="","",'Model inputs'!P84=1))),0,IF('Model inputs'!O54="","",'Model inputs'!O54)))+'Model inputs'!P28,0) -> 0 | Q12: =MAX(IF(IF(IF(IF(ISERROR('Model inputs'!Q84=1),'Model inputs'!Q84=1,IF('Model inputs'!Q84="","",'Model inputs'!Q84=1))="",FALSE,IF(ISERROR('Model inputs'!Q84=1),'Model inputs'!Q84=1,IF('Model inputs'!Q84="","",'Model inputs'!Q84=1))),0,IF('Model inputs'!P54="","",'Model inputs'!P54))="",0,IF(IF(IF(ISERROR('Model inputs'!Q84=1),'Model inputs'!Q84=1,IF('Model inputs'!Q84="","",'Model inputs'!Q84=1))="",FALSE,IF(ISERROR('Model inputs'!Q84=1),'Model inputs'!Q84=1,IF('Model inputs'!Q84="","",'Model inputs'!Q84=1))),0,IF('Model inputs'!P54="","",'Model inputs'!P54)))+'Model inputs'!Q28,0) -> 0 | R12: =MAX(IF(IF(IF(IF(ISERROR('Model inputs'!R84=1),'Model inputs'!R84=1,IF('Model inputs'!R84="","",'Model inputs'!R84=1))="",FALSE,IF(ISERROR('Model inputs'!R84=1),'Model inputs'!R84=1,IF('Model inputs'!R84="","",'Model inputs'!R84=1))),0,IF('Model inputs'!Q54="","",'Model inputs'!Q54))="",0,IF(IF(IF(ISERROR('Model inputs'!R84=1),'Model inputs'!R84=1,IF('Model inputs'!R84="","",'Model inputs'!R84=1))="",FALSE,IF(ISERROR('Model inputs'!R84=1),'Model inputs'!R84=1,IF('Model inputs'!R84="","",'Model inputs'!R84=1))),0,IF('Model inputs'!Q54="","",'Model inputs'!Q54)))+'Model inputs'!R28,0) -> 0 | S12: =MAX(IF(IF(IF(IF(ISERROR('Model inputs'!S84=1),'Model inputs'!S84=1,IF('Model inputs'!S84="","",'Model inputs'!S84=1))="",FALSE,IF(ISERROR('Model inputs'!S84=1),'Model inputs'!S84=1,IF('Model inputs'!S84="","",'Model inputs'!S84=1))),0,IF('Model inputs'!R54="","",'Model inputs'!R54))="",0,IF(IF(IF(ISERROR('Model inputs'!S84=1),'Model inputs'!S84=1,IF('Model inputs'!S84="","",'Model inputs'!S84=1))="",FALSE,IF(ISERROR('Model inputs'!S84=1),'Model inputs'!S84=1,IF('Model inputs'!S84="","",'Model inputs'!S84=1))),0,IF('Model inputs'!R54="","",'Model inputs'!R54)))+'Model inputs'!S28,0) -> 0 | ... Z12: =MAX(IF(IF(IF(IF(ISERROR('Model inputs'!Z84=1),'Model inputs'!Z84=1,IF('Model inputs'!Z84="","",'Model inputs'!Z84=1))="",FALSE,IF(ISERROR('Model inputs'!Z84=1),'Model inputs'!Z84=1,IF('Model inputs'!Z84="","",'Model inputs'!Z84=1))),0,IF('Model inputs'!Y54="","",'Model inputs'!Y54))="",0,IF(IF(IF(ISERROR('Model inputs'!Z84=1),'Model inputs'!Z84=1,IF('Model inputs'!Z84="","",'Model inputs'!Z84=1))="",FALSE,IF(ISERROR('Model inputs'!Z84=1),'Model inputs'!Z84=1,IF('Model inputs'!Z84="","",'Model inputs'!Z84=1))),0,IF('Model inputs'!Y54="","",'Model inputs'!Y54)))+'Model inputs'!Z28,0) -> 0
A13: Cumulative funding gap · Conservative | C13: 0 | D13: 0 | E13: 0 | F13: 0 | G13: 0 | H13: 0 | I13: 0 | J13: 0 | K13: 0 | L13: =MAX(IF(IF(IF(IF(ISERROR('Model inputs'!L85=1),'Model inputs'!L85=1,IF('Model inputs'!L85="","",'Model inputs'!L85=1))="",FALSE,IF(ISERROR('Model inputs'!L85=1),'Model inputs'!L85=1,IF('Model inputs'!L85="","",'Model inputs'!L85=1))),0,IF('Model inputs'!K55="","",'Model inputs'!K55))="",0,IF(IF(IF(ISERROR('Model inputs'!L85=1),'Model inputs'!L85=1,IF('Model inputs'!L85="","",'Model inputs'!L85=1))="",FALSE,IF(ISERROR('Model inputs'!L85=1),'Model inputs'!L85=1,IF('Model inputs'!L85="","",'Model inputs'!L85=1))),0,IF('Model inputs'!K55="","",'Model inputs'!K55)))+'Model inputs'!L29,0) -> 750 | M13: =MAX(IF(IF(IF(IF(ISERROR('Model inputs'!M85=1),'Model inputs'!M85=1,IF('Model inputs'!M85="","",'Model inputs'!M85=1))="",FALSE,IF(ISERROR('Model inputs'!M85=1),'Model inputs'!M85=1,IF('Model inputs'!M85="","",'Model inputs'!M85=1))),0,IF('Model inputs'!L55="","",'Model inputs'!L55))="",0,IF(IF(IF(ISERROR('Model inputs'!M85=1),'Model inputs'!M85=1,IF('Model inputs'!M85="","",'Model inputs'!M85=1))="",FALSE,IF(ISERROR('Model inputs'!M85=1),'Model inputs'!M85=1,IF('Model inputs'!M85="","",'Model inputs'!M85=1))),0,IF('Model inputs'!L55="","",'Model inputs'!L55)))+'Model inputs'!M29,0) -> 1500 | N13: =MAX(IF(IF(IF(IF(ISERROR('Model inputs'!N85=1),'Model inputs'!N85=1,IF('Model inputs'!N85="","",'Model inputs'!N85=1))="",FALSE,IF(ISERROR('Model inputs'!N85=1),'Model inputs'!N85=1,IF('Model inputs'!N85="","",'Model inputs'!N85=1))),0,IF('Model inputs'!M55="","",'Model inputs'!M55))="",0,IF(IF(IF(ISERROR('Model inputs'!N85=1),'Model inputs'!N85=1,IF('Model inputs'!N85="","",'Model inputs'!N85=1))="",FALSE,IF(ISERROR('Model inputs'!N85=1),'Model inputs'!N85=1,IF('Model inputs'!N85="","",'Model inputs'!N85=1))),0,IF('Model inputs'!M55="","",'Model inputs'!M55)))+'Model inputs'!N29,0) -> 0 | O13: =MAX(IF(IF(IF(IF(ISERROR('Model inputs'!O85=1),'Model inputs'!O85=1,IF('Model inputs'!O85="","",'Model inputs'!O85=1))="",FALSE,IF(ISERROR('Model inputs'!O85=1),'Model inputs'!O85=1,IF('Model inputs'!O85="","",'Model inputs'!O85=1))),0,IF('Model inputs'!N55="","",'Model inputs'!N55))="",0,IF(IF(IF(ISERROR('Model inputs'!O85=1),'Model inputs'!O85=1,IF('Model inputs'!O85="","",'Model inputs'!O85=1))="",FALSE,IF(ISERROR('Model inputs'!O85=1),'Model inputs'!O85=1,IF('Model inputs'!O85="","",'Model inputs'!O85=1))),0,IF('Model inputs'!N55="","",'Model inputs'!N55)))+'Model inputs'!O29,0) -> 0 | P13: =MAX(IF(IF(IF(IF(ISERROR('Model inputs'!P85=1),'Model inputs'!P85=1,IF('Model inputs'!P85="","",'Model inputs'!P85=1))="",FALSE,IF(ISERROR('Model inputs'!P85=1),'Model inputs'!P85=1,IF('Model inputs'!P85="","",'Model inputs'!P85=1))),0,IF('Model inputs'!O55="","",'Model inputs'!O55))="",0,IF(IF(IF(ISERROR('Model inputs'!P85=1),'Model inputs'!P85=1,IF('Model inputs'!P85="","",'Model inputs'!P85=1))="",FALSE,IF(ISERROR('Model inputs'!P85=1),'Model inputs'!P85=1,IF('Model inputs'!P85="","",'Model inputs'!P85=1))),0,IF('Model inputs'!O55="","",'Model inputs'!O55)))+'Model inputs'!P29,0) -> 0 | Q13: =MAX(IF(IF(IF(IF(ISERROR('Model inputs'!Q85=1),'Model inputs'!Q85=1,IF('Model inputs'!Q85="","",'Model inputs'!Q85=1))="",FALSE,IF(ISERROR('Model inputs'!Q85=1),'Model inputs'!Q85=1,IF('Model inputs'!Q85="","",'Model inputs'!Q85=1))),0,IF('Model inputs'!P55="","",'Model inputs'!P55))="",0,IF(IF(IF(ISERROR('Model inputs'!Q85=1),'Model inputs'!Q85=1,IF('Model inputs'!Q85="","",'Model inputs'!Q85=1))="",FALSE,IF(ISERROR('Model inputs'!Q85=1),'Model inputs'!Q85=1,IF('Model inputs'!Q85="","",'Model inputs'!Q85=1))),0,IF('Model inputs'!P55="","",'Model inputs'!P55)))+'Model inputs'!Q29,0) -> 0 | R13: =MAX(IF(IF(IF(IF(ISERROR('Model inputs'!R85=1),'Model inputs'!R85=1,IF('Model inputs'!R85="","",'Model inputs'!R85=1))="",FALSE,IF(ISERROR('Model inputs'!R85=1),'Model inputs'!R85=1,IF('Model inputs'!R85="","",'Model inputs'!R85=1))),0,IF('Model inputs'!Q55="","",'Model inputs'!Q55))="",0,IF(IF(IF(ISERROR('Model inputs'!R85=1),'Model inputs'!R85=1,IF('Model inputs'!R85="","",'Model inputs'!R85=1))="",FALSE,IF(ISERROR('Model inputs'!R85=1),'Model inputs'!R85=1,IF('Model inputs'!R85="","",'Model inputs'!R85=1))),0,IF('Model inputs'!Q55="","",'Model inputs'!Q55)))+'Model inputs'!R29,0) -> 0 | S13: =MAX(IF(IF(IF(IF(ISERROR('Model inputs'!S85=1),'Model inputs'!S85=1,IF('Model inputs'!S85="","",'Model inputs'!S85=1))="",FALSE,IF(ISERROR('Model inputs'!S85=1),'Model inputs'!S85=1,IF('Model inputs'!S85="","",'Model inputs'!S85=1))),0,IF('Model inputs'!R55="","",'Model inputs'!R55))="",0,IF(IF(IF(ISERROR('Model inputs'!S85=1),'Model inputs'!S85=1,IF('Model inputs'!S85="","",'Model inputs'!S85=1))="",FALSE,IF(ISERROR('Model inputs'!S85=1),'Model inputs'!S85=1,IF('Model inputs'!S85="","",'Model inputs'!S85=1))),0,IF('Model inputs'!R55="","",'Model inputs'!R55)))+'Model inputs'!S29,0) -> 0 | ... Z13: =MAX(IF(IF(IF(IF(ISERROR('Model inputs'!Z85=1),'Model inputs'!Z85=1,IF('Model inputs'!Z85="","",'Model inputs'!Z85=1))="",FALSE,IF(ISERROR('Model inputs'!Z85=1),'Model inputs'!Z85=1,IF('Model inputs'!Z85="","",'Model inputs'!Z85=1))),0,IF('Model inputs'!Y55="","",'Model inputs'!Y55))="",0,IF(IF(IF(ISERROR('Model inputs'!Z85=1),'Model inputs'!Z85=1,IF('Model inputs'!Z85="","",'Model inputs'!Z85=1))="",FALSE,IF(ISERROR('Model inputs'!Z85=1),'Model inputs'!Z85=1,IF('Model inputs'!Z85="","",'Model inputs'!Z85=1))),0,IF('Model inputs'!Y55="","",'Model inputs'!Y55)))+'Model inputs'!Z29,0) -> 0
A14: Forecast contribution profit · Growth | B14: =SUM('Model inputs'!B321,'Model inputs'!B322) -> 338461.5
A15: Forecast contribution profit · Conservative | B15: =SUM('Model inputs'!B323,'Model inputs'!B324) -> 24661
A16: Forecast gross profit · Growth | B16: ='DealScope scenario comparison'!B5-'Model inputs'!B68 -> 353086.5
A17: Forecast gross profit · Conservative | B17: ='DealScope scenario comparison'!C5-'Model inputs'!B69 -> 26161
A18: Forecast months · Growth | B18: =12 -> 12
A19: Forecast months · Conservative | B19: =12 -> 12
A20: Forecast start date · Growth | B20: =DATE(2026,10,1) -> 46296
A21: Forecast start date · Conservative | B21: =DATE(2026,10,1) -> 46296
A22: Plan Audits delivered · Growth | C22: 0 | D22: 0 | E22: 0 | F22: 0 | G22: 0 | H22: 0 | I22: 0 | J22: 0 | K22: 0 | L22: =IF(SUM(IF(IF('Model inputs'!B325="",0,1)="",0,IF('Model inputs'!B325="",0,1)),IF(IF('Model inputs'!B326="",0,1)="",0,IF('Model inputs'!B326="",0,1)),IF(IF('Model inputs'!B327="",0,1)="",0,IF('Model inputs'!B327="",0,1)),IF(IF('Model inputs'!B328="",0,1)="",0,IF('Model inputs'!B328="",0,1)),IF(IF('Model inputs'!B329="",0,1)="",0,IF('Model inputs'!B329="",0,1)))=0,"",SUM('Model inputs'!B325,'Model inputs'!B326,'Model inputs'!B327,'Model inputs'!B328,'Model inputs'!B329)) -> 5 | M22: =IF(SUM(IF(IF('Model inputs'!B330="",0,1)="",0,IF('Model inputs'!B330="",0,1)),IF(IF('Model inputs'!B331="",0,1)="",0,IF('Model inputs'!B331="",0,1)),IF(IF('Model inputs'!B332="",0,1)="",0,IF('Model inputs'!B332="",0,1)),IF(IF('Model inputs'!B333="",0,1)="",0,IF('Model inputs'!B333="",0,1)),IF(IF('Model inputs'!B334="",0,1)="",0,IF('Model inputs'!B334="",0,1)))=0,"",SUM('Model inputs'!B330,'Model inputs'!B331,'Model inputs'!B332,'Model inputs'!B333,'Model inputs'!B334)) -> 10 | N22: =IF(SUM(IF(IF('Model inputs'!B335="",0,1)="",0,IF('Model inputs'!B335="",0,1)),IF(IF('Model inputs'!B336="",0,1)="",0,IF('Model inputs'!B336="",0,1)),IF(IF('Model inputs'!B337="",0,1)="",0,IF('Model inputs'!B337="",0,1)),IF(IF('Model inputs'!B338="",0,1)="",0,IF('Model inputs'!B338="",0,1)),IF(IF('Model inputs'!B339="",0,1)="",0,IF('Model inputs'!B339="",0,1)))=0,"",SUM('Model inputs'!B335,'Model inputs'!B336,'Model inputs'!B337,'Model inputs'!B338,'Model inputs'!B339)) -> 15 | O22: =IF(SUM(IF(IF('Model inputs'!B340="",0,1)="",0,IF('Model inputs'!B340="",0,1)),IF(IF('Model inputs'!B341="",0,1)="",0,IF('Model inputs'!B341="",0,1)),IF(IF('Model inputs'!B342="",0,1)="",0,IF('Model inputs'!B342="",0,1)),IF(IF('Model inputs'!B343="",0,1)="",0,IF('Model inputs'!B343="",0,1)),IF(IF('Model inputs'!B344="",0,1)="",0,IF('Model inputs'!B344="",0,1)))=0,"",SUM('Model inputs'!B340,'Model inputs'!B341,'Model inputs'!B342,'Model inputs'!B343,'Model inputs'!B344)) -> 20 | P22: =IF(SUM(IF(IF('Model inputs'!B345="",0,1)="",0,IF('Model inputs'!B345="",0,1)),IF(IF('Model inputs'!B346="",0,1)="",0,IF('Model inputs'!B346="",0,1)),IF(IF('Model inputs'!B347="",0,1)="",0,IF('Model inputs'!B347="",0,1)),IF(IF('Model inputs'!B348="",0,1)="",0,IF('Model inputs'!B348="",0,1)),IF(IF('Model inputs'!B349="",0,1)="",0,IF('Model inputs'!B349="",0,1)))=0,"",SUM('Model inputs'!B345,'Model inputs'!B346,'Model inputs'!B347,'Model inputs'!B348,'Model inputs'!B349)) -> 25 | Q22: =IF(SUM(IF(IF('Model inputs'!B350="",0,1)="",0,IF('Model inputs'!B350="",0,1)),IF(IF('Model inputs'!B351="",0,1)="",0,IF('Model inputs'!B351="",0,1)),IF(IF('Model inputs'!B352="",0,1)="",0,IF('Model inputs'!B352="",0,1)),IF(IF('Model inputs'!B353="",0,1)="",0,IF('Model inputs'!B353="",0,1)),IF(IF('Model inputs'!B354="",0,1)="",0,IF('Model inputs'!B354="",0,1)))=0,"",SUM('Model inputs'!B350,'Model inputs'!B351,'Model inputs'!B352,'Model inputs'!B353,'Model inputs'!B354)) -> 30 | R22: =IF(SUM(IF(IF('Model inputs'!B355="",0,1)="",0,IF('Model inputs'!B355="",0,1)),IF(IF('Model inputs'!B356="",0,1)="",0,IF('Model inputs'!B356="",0,1)),IF(IF('Model inputs'!B357="",0,1)="",0,IF('Model inputs'!B357="",0,1)),IF(IF('Model inputs'!B358="",0,1)="",0,IF('Model inputs'!B358="",0,1)),IF(IF('Model inputs'!B359="",0,1)="",0,IF('Model inputs'!B359="",0,1)))=0,"",SUM('Model inputs'!B355,'Model inputs'!B356,'Model inputs'!B357,'Model inputs'!B358,'Model inputs'!B359)) -> 35 | S22: =IF(SUM(IF(IF('Model inputs'!B360="",0,1)="",0,IF('Model inputs'!B360="",0,1)),IF(IF('Model inputs'!B361="",0,1)="",0,IF('Model inputs'!B361="",0,1)),IF(IF('Model inputs'!B362="",0,1)="",0,IF('Model inputs'!B362="",0,1)),IF(IF('Model inputs'!B363="",0,1)="",0,IF('Model inputs'!B363="",0,1)),IF(IF('Model inputs'!B364="",0,1)="",0,IF('Model inputs'!B364="",0,1)))=0,"",SUM('Model inputs'!B360,'Model inputs'!B361,'Model inputs'!B362,'Model inputs'!B363,'Model inputs'!B364)) -> 40 | T22: =IF(SUM(IF(IF('Model inputs'!B365="",0,1)="",0,IF('Model inputs'!B365="",0,1)),IF(IF('Model inputs'!B366="",0,1)="",0,IF('Model inputs'!B366="",0,1)),IF(IF('Model inputs'!B367="",0,1)="",0,IF('Model inputs'!B367="",0,1)),IF(IF('Model inputs'!B368="",0,1)="",0,IF('Model inputs'!B368="",0,1)),IF(IF('Model inputs'!B369="",0,1)="",0,IF('Model inputs'!B369="",0,1)))=0,"",SUM('Model inputs'!B365,'Model inputs'!B366,'Model inputs'!B367,'Model inputs'!B368,'Model inputs'!B369)) -> 45 | U22: =IF(SUM(IF(IF('Model inputs'!B370="",0,1)="",0,IF('Model inputs'!B370="",0,1)),IF(IF('Model inputs'!B371="",0,1)="",0,IF('Model inputs'!B371="",0,1)),IF(IF('Model inputs'!B372="",0,1)="",0,IF('Model inputs'!B372="",0,1)),IF(IF('Model inputs'!B373="",0,1)="",0,IF('Model inputs'!B373="",0,1)),IF(IF('Model inputs'!B374="",0,1)="",0,IF('Model inputs'!B374="",0,1)))=0,"",SUM('Model inputs'!B370,'Model inputs'!B371,'Model inputs'!B372,'Model inputs'!B373,'Model inputs'!B374)) -> 50 | V22: =IF(SUM(IF(IF('Model inputs'!B375="",0,1)="",0,IF('Model inputs'!B375="",0,1)),IF(IF('Model inputs'!B376="",0,1)="",0,IF('Model inputs'!B376="",0,1)),IF(IF('Model inputs'!B377="",0,1)="",0,IF('Model inputs'!B377="",0,1)),IF(IF('Model inputs'!B378="",0,1)="",0,IF('Model inputs'!B378="",0,1)),IF(IF('Model inputs'!B379="",0,1)="",0,IF('Model inputs'!B379="",0,1)))=0,"",SUM('Model inputs'!B375,'Model inputs'!B376,'Model inputs'!B377,'Model inputs'!B378,'Model inputs'!B379)) -> 55 | W22: =IF(SUM(IF(IF('Model inputs'!B380="",0,1)="",0,IF('Model inputs'!B380="",0,1)),IF(IF('Model inputs'!B381="",0,1)="",0,IF('Model inputs'!B381="",0,1)),IF(IF('Model inputs'!B382="",0,1)="",0,IF('Model inputs'!B382="",0,1)),IF(IF('Model inputs'!B383="",0,1)="",0,IF('Model inputs'!B383="",0,1)),IF(IF('Model inputs'!B384="",0,1)="",0,IF('Model inputs'!B384="",0,1)))=0,"",SUM('Model inputs'!B380,'Model inputs'!B381,'Model inputs'!B382,'Model inputs'!B383,'Model inputs'!B384)) -> 60 | X22: =IF(SUM(IF(IF('Model inputs'!B385="",0,1)="",0,IF('Model inputs'!B385="",0,1)),IF(IF('Model inputs'!B386="",0,1)="",0,IF('Model inputs'!B386="",0,1)),IF(IF('Model inputs'!B387="",0,1)="",0,IF('Model inputs'!B387="",0,1)),IF(IF('Model inputs'!B388="",0,1)="",0,IF('Model inputs'!B388="",0,1)),IF(IF('Model inputs'!B389="",0,1)="",0,IF('Model inputs'!B389="",0,1)))=0,"",SUM('Model inputs'!B385,'Model inputs'!B386,'Model inputs'!B387,'Model inputs'!B388,'Model inputs'!B389)) -> 60 | Y22: =IF(SUM(IF(IF('Model inputs'!B390="",0,1)="",0,IF('Model inputs'!B390="",0,1)),IF(IF('Model inputs'!B391="",0,1)="",0,IF('Model inputs'!B391="",0,1)),IF(IF('Model inputs'!B392="",0,1)="",0,IF('Model inputs'!B392="",0,1)),IF(IF('Model inputs'!B393="",0,1)="",0,IF('Model inputs'!B393="",0,1)),IF(IF('Model inputs'!B394="",0,1)="",0,IF('Model inputs'!B394="",0,1)))=0,"",SUM('Model inputs'!B390,'Model inputs'!B391,'Model inputs'!B392,'Model inputs'!B393,'Model inputs'!B394)) -> 60 | Z22: =IF(SUM(IF(IF('Model inputs'!B395="",0,1)="",0,IF('Model inputs'!B395="",0,1)),IF(IF('Model inputs'!B396="",0,1)="",0,IF('Model inputs'!B396="",0,1)),IF(IF('Model inputs'!B397="",0,1)="",0,IF('Model inputs'!B397="",0,1)),IF(IF('Model inputs'!B398="",0,1)="",0,IF('Model inputs'!B398="",0,1)),IF(IF('Model inputs'!B399="",0,1)="",0,IF('Model inputs'!B399="",0,1)))=0,"",SUM('Model inputs'!B395,'Model inputs'!B396,'Model inputs'!B397,'Model inputs'!B398,'Model inputs'!B399)) -> 60
A23: Plan Audits delivered · Conservative | C23: 0 | D23: 0 | E23: 0 | F23: 0 | G23: 0 | H23: 0 | I23: 0 | J23: 0 | K23: 0 | L23: =IF(SUM(IF(IF('Model inputs'!B400="",0,1)="",0,IF('Model inputs'!B400="",0,1)),IF(IF('Model inputs'!B401="",0,1)="",0,IF('Model inputs'!B401="",0,1)),IF(IF('Model inputs'!B402="",0,1)="",0,IF('Model inputs'!B402="",0,1)),IF(IF('Model inputs'!B403="",0,1)="",0,IF('Model inputs'!B403="",0,1)),IF(IF('Model inputs'!B404="",0,1)="",0,IF('Model inputs'!B404="",0,1)))=0,"",SUM('Model inputs'!B400,'Model inputs'!B401,'Model inputs'!B402,'Model inputs'!B403,'Model inputs'!B404)) -> 0 | M23: =IF(SUM(IF(IF('Model inputs'!B405="",0,1)="",0,IF('Model inputs'!B405="",0,1)),IF(IF('Model inputs'!B406="",0,1)="",0,IF('Model inputs'!B406="",0,1)),IF(IF('Model inputs'!B407="",0,1)="",0,IF('Model inputs'!B407="",0,1)),IF(IF('Model inputs'!B408="",0,1)="",0,IF('Model inputs'!B408="",0,1)),IF(IF('Model inputs'!B409="",0,1)="",0,IF('Model inputs'!B409="",0,1)))=0,"",SUM('Model inputs'!B405,'Model inputs'!B406,'Model inputs'!B407,'Model inputs'!B408,'Model inputs'!B409)) -> 0 | N23: =IF(SUM(IF(IF('Model inputs'!B410="",0,1)="",0,IF('Model inputs'!B410="",0,1)),IF(IF('Model inputs'!B411="",0,1)="",0,IF('Model inputs'!B411="",0,1)),IF(IF('Model inputs'!B412="",0,1)="",0,IF('Model inputs'!B412="",0,1)),IF(IF('Model inputs'!B413="",0,1)="",0,IF('Model inputs'!B413="",0,1)),IF(IF('Model inputs'!B414="",0,1)="",0,IF('Model inputs'!B414="",0,1)))=0,"",SUM('Model inputs'!B410,'Model inputs'!B411,'Model inputs'!B412,'Model inputs'!B413,'Model inputs'!B414)) -> 4 | O23: =IF(SUM(IF(IF('Model inputs'!B415="",0,1)="",0,IF('Model inputs'!B415="",0,1)),IF(IF('Model inputs'!B416="",0,1)="",0,IF('Model inputs'!B416="",0,1)),IF(IF('Model inputs'!B417="",0,1)="",0,IF('Model inputs'!B417="",0,1)),IF(IF('Model inputs'!B418="",0,1)="",0,IF('Model inputs'!B418="",0,1)),IF(IF('Model inputs'!B419="",0,1)="",0,IF('Model inputs'!B419="",0,1)))=0,"",SUM('Model inputs'!B415,'Model inputs'!B416,'Model inputs'!B417,'Model inputs'!B418,'Model inputs'!B419)) -> 4 | P23: =IF(SUM(IF(IF('Model inputs'!B420="",0,1)="",0,IF('Model inputs'!B420="",0,1)),IF(IF('Model inputs'!B421="",0,1)="",0,IF('Model inputs'!B421="",0,1)),IF(IF('Model inputs'!B422="",0,1)="",0,IF('Model inputs'!B422="",0,1)),IF(IF('Model inputs'!B423="",0,1)="",0,IF('Model inputs'!B423="",0,1)),IF(IF('Model inputs'!B424="",0,1)="",0,IF('Model inputs'!B424="",0,1)))=0,"",SUM('Model inputs'!B420,'Model inputs'!B421,'Model inputs'!B422,'Model inputs'!B423,'Model inputs'!B424)) -> 4 | Q23: =IF(SUM(IF(IF('Model inputs'!B425="",0,1)="",0,IF('Model inputs'!B425="",0,1)),IF(IF('Model inputs'!B426="",0,1)="",0,IF('Model inputs'!B426="",0,1)),IF(IF('Model inputs'!B427="",0,1)="",0,IF('Model inputs'!B427="",0,1)),IF(IF('Model inputs'!B428="",0,1)="",0,IF('Model inputs'!B428="",0,1)),IF(IF('Model inputs'!B429="",0,1)="",0,IF('Model inputs'!B429="",0,1)))=0,"",SUM('Model inputs'!B425,'Model inputs'!B426,'Model inputs'!B427,'Model inputs'!B428,'Model inputs'!B429)) -> 4 | R23: =IF(SUM(IF(IF('Model inputs'!B430="",0,1)="",0,IF('Model inputs'!B430="",0,1)),IF(IF('Model inputs'!B431="",0,1)="",0,IF('Model inputs'!B431="",0,1)),IF(IF('Model inputs'!B432="",0,1)="",0,IF('Model inputs'!B432="",0,1)),IF(IF('Model inputs'!B433="",0,1)="",0,IF('Model inputs'!B433="",0,1)),IF(IF('Model inputs'!B434="",0,1)="",0,IF('Model inputs'!B434="",0,1)))=0,"",SUM('Model inputs'!B430,'Model inputs'!B431,'Model inputs'!B432,'Model inputs'!B433,'Model inputs'!B434)) -> 4 | S23: =IF(SUM(IF(IF('Model inputs'!B435="",0,1)="",0,IF('Model inputs'!B435="",0,1)),IF(IF('Model inputs'!B436="",0,1)="",0,IF('Model inputs'!B436="",0,1)),IF(IF('Model inputs'!B437="",0,1)="",0,IF('Model inputs'!B437="",0,1)),IF(IF('Model inputs'!B438="",0,1)="",0,IF('Model inputs'!B438="",0,1)),IF(IF('Model inputs'!B439="",0,1)="",0,IF('Model inputs'!B439="",0,1)))=0,"",SUM('Model inputs'!B435,'Model inputs'!B436,'Model inputs'!B437,'Model inputs'!B438,'Model inputs'!B439)) -> 4 | T23: =IF(SUM(IF(IF('Model inputs'!B440="",0,1)="",0,IF('Model inputs'!B440="",0,1)),IF(IF('Model inputs'!B441="",0,1)="",0,IF('Model inputs'!B441="",0,1)),IF(IF('Model inputs'!B442="",0,1)="",0,IF('Model inputs'!B442="",0,1)),IF(IF('Model inputs'!B443="",0,1)="",0,IF('Model inputs'!B443="",0,1)),IF(IF('Model inputs'!B444="",0,1)="",0,IF('Model inputs'!B444="",0,1)))=0,"",SUM('Model inputs'!B440,'Model inputs'!B441,'Model inputs'!B442,'Model inputs'!B443,'Model inputs'!B444)) -> 4 | U23: =IF(SUM(IF(IF('Model inputs'!B445="",0,1)="",0,IF('Model inputs'!B445="",0,1)),IF(IF('Model inputs'!B446="",0,1)="",0,IF('Model inputs'!B446="",0,1)),IF(IF('Model inputs'!B447="",0,1)="",0,IF('Model inputs'!B447="",0,1)),IF(IF('Model inputs'!B448="",0,1)="",0,IF('Model inputs'!B448="",0,1)),IF(IF('Model inputs'!B449="",0,1)="",0,IF('Model inputs'!B449="",0,1)))=0,"",SUM('Model inputs'!B445,'Model inputs'!B446,'Model inputs'!B447,'Model inputs'!B448,'Model inputs'!B449)) -> 4 | V23: =IF(SUM(IF(IF('Model inputs'!B450="",0,1)="",0,IF('Model inputs'!B450="",0,1)),IF(IF('Model inputs'!B451="",0,1)="",0,IF('Model inputs'!B451="",0,1)),IF(IF('Model inputs'!B452="",0,1)="",0,IF('Model inputs'!B452="",0,1)),IF(IF('Model inputs'!B453="",0,1)="",0,IF('Model inputs'!B453="",0,1)),IF(IF('Model inputs'!B454="",0,1)="",0,IF('Model inputs'!B454="",0,1)))=0,"",SUM('Model inputs'!B450,'Model inputs'!B451,'Model inputs'!B452,'Model inputs'!B453,'Model inputs'!B454)) -> 4 | W23: =IF(SUM(IF(IF('Model inputs'!B455="",0,1)="",0,IF('Model inputs'!B455="",0,1)),IF(IF('Model inputs'!B456="",0,1)="",0,IF('Model inputs'!B456="",0,1)),IF(IF('Model inputs'!B457="",0,1)="",0,IF('Model inputs'!B457="",0,1)),IF(IF('Model inputs'!B458="",0,1)="",0,IF('Model inputs'!B458="",0,1)),IF(IF('Model inputs'!B459="",0,1)="",0,IF('Model inputs'!B459="",0,1)))=0,"",SUM('Model inputs'!B455,'Model inputs'!B456,'Model inputs'!B457,'Model inputs'!B458,'Model inputs'!B459)) -> 4 | X23: =IF(SUM(IF(IF('Model inputs'!B460="",0,1)="",0,IF('Model inputs'!B460="",0,1)),IF(IF('Model inputs'!B461="",0,1)="",0,IF('Model inputs'!B461="",0,1)),IF(IF('Model inputs'!B462="",0,1)="",0,IF('Model inputs'!B462="",0,1)),IF(IF('Model inputs'!B463="",0,1)="",0,IF('Model inputs'!B463="",0,1)),IF(IF('Model inputs'!B464="",0,1)="",0,IF('Model inputs'!B464="",0,1)))=0,"",SUM('Model inputs'!B460,'Model inputs'!B461,'Model inputs'!B462,'Model inputs'!B463,'Model inputs'!B464)) -> 4 | Y23: =IF(SUM(IF(IF('Model inputs'!B465="",0,1)="",0,IF('Model inputs'!B465="",0,1)),IF(IF('Model inputs'!B466="",0,1)="",0,IF('Model inputs'!B466="",0,1)),IF(IF('Model inputs'!B467="",0,1)="",0,IF('Model inputs'!B467="",0,1)),IF(IF('Model inputs'!B468="",0,1)="",0,IF('Model inputs'!B468="",0,1)),IF(IF('Model inputs'!B469="",0,1)="",0,IF('Model inputs'!B469="",0,1)))=0,"",SUM('Model inputs'!B465,'Model inputs'!B466,'Model inputs'!B467,'Model inputs'!B468,'Model inputs'!B469)) -> 4 | Z23: =IF(SUM(IF(IF('Model inputs'!B470="",0,1)="",0,IF('Model inputs'!B470="",0,1)),IF(IF('Model inputs'!B471="",0,1)="",0,IF('Model inputs'!B471="",0,1)),IF(IF('Model inputs'!B472="",0,1)="",0,IF('Model inputs'!B472="",0,1)),IF(IF('Model inputs'!B473="",0,1)="",0,IF('Model inputs'!B473="",0,1)),IF(IF('Model inputs'!B474="",0,1)="",0,IF('Model inputs'!B474="",0,1)))=0,"",SUM('Model inputs'!B470,'Model inputs'!B471,'Model inputs'!B472,'Model inputs'!B473,'Model inputs'!B474)) -> 4
A24: Plan Cash collections · Growth | C24: 0 | D24: 0 | E24: 0 | F24: 0 | G24: 0 | H24: 0 | I24: 0 | J24: 0 | K24: 0 | L24: =IF(SUM(IF(IF('Model inputs'!B475="",0,1)="",0,IF('Model inputs'!B475="",0,1)),IF(IF('Model inputs'!B476="",0,1)="",0,IF('Model inputs'!B476="",0,1)),IF(IF('Model inputs'!B477="",0,1)="",0,IF('Model inputs'!B477="",0,1)),IF(IF('Model inputs'!B478="",0,1)="",0,IF('Model inputs'!B478="",0,1)),IF(IF('Model inputs'!B479="",0,1)="",0,IF('Model inputs'!B479="",0,1)))=0,"",SUM('Model inputs'!B475,'Model inputs'!B476,'Model inputs'!B477,'Model inputs'!B478,'Model inputs'!B479)) -> 32500 | M24: =IF(SUM(IF(IF('Model inputs'!B480="",0,1)="",0,IF('Model inputs'!B480="",0,1)),IF(IF('Model inputs'!B481="",0,1)="",0,IF('Model inputs'!B481="",0,1)),IF(IF('Model inputs'!B482="",0,1)="",0,IF('Model inputs'!B482="",0,1)),IF(IF('Model inputs'!B483="",0,1)="",0,IF('Model inputs'!B483="",0,1)),IF(IF('Model inputs'!B484="",0,1)="",0,IF('Model inputs'!B484="",0,1)))=0,"",SUM('Model inputs'!B480,'Model inputs'!B481,'Model inputs'!B482,'Model inputs'!B483,'Model inputs'!B484)) -> 35000 | N24: =IF(SUM(IF(IF('Model inputs'!B485="",0,1)="",0,IF('Model inputs'!B485="",0,1)),IF(IF('Model inputs'!B486="",0,1)="",0,IF('Model inputs'!B486="",0,1)),IF(IF('Model inputs'!B487="",0,1)="",0,IF('Model inputs'!B487="",0,1)),IF(IF('Model inputs'!B488="",0,1)="",0,IF('Model inputs'!B488="",0,1)),IF(IF('Model inputs'!B489="",0,1)="",0,IF('Model inputs'!B489="",0,1)))=0,"",SUM('Model inputs'!B485,'Model inputs'!B486,'Model inputs'!B487,'Model inputs'!B488,'Model inputs'!B489)) -> 37500 | O24: =IF(SUM(IF(IF('Model inputs'!B490="",0,1)="",0,IF('Model inputs'!B490="",0,1)),IF(IF('Model inputs'!B491="",0,1)="",0,IF('Model inputs'!B491="",0,1)),IF(IF('Model inputs'!B492="",0,1)="",0,IF('Model inputs'!B492="",0,1)),IF(IF('Model inputs'!B493="",0,1)="",0,IF('Model inputs'!B493="",0,1)),IF(IF('Model inputs'!B494="",0,1)="",0,IF('Model inputs'!B494="",0,1)))=0,"",SUM('Model inputs'!B490,'Model inputs'!B491,'Model inputs'!B492,'Model inputs'!B493,'Model inputs'!B494)) -> 40000 | P24: =IF(SUM(IF(IF('Model inputs'!B495="",0,1)="",0,IF('Model inputs'!B495="",0,1)),IF(IF('Model inputs'!B496="",0,1)="",0,IF('Model inputs'!B496="",0,1)),IF(IF('Model inputs'!B497="",0,1)="",0,IF('Model inputs'!B497="",0,1)),IF(IF('Model inputs'!B498="",0,1)="",0,IF('Model inputs'!B498="",0,1)),IF(IF('Model inputs'!B499="",0,1)="",0,IF('Model inputs'!B499="",0,1)))=0,"",SUM('Model inputs'!B495,'Model inputs'!B496,'Model inputs'!B497,'Model inputs'!B498,'Model inputs'!B499)) -> 42500 | Q24: =IF(SUM(IF(IF('Model inputs'!B500="",0,1)="",0,IF('Model inputs'!B500="",0,1)),IF(IF('Model inputs'!B501="",0,1)="",0,IF('Model inputs'!B501="",0,1)),IF(IF('Model inputs'!B502="",0,1)="",0,IF('Model inputs'!B502="",0,1)),IF(IF('Model inputs'!B503="",0,1)="",0,IF('Model inputs'!B503="",0,1)),IF(IF('Model inputs'!B504="",0,1)="",0,IF('Model inputs'!B504="",0,1)))=0,"",SUM('Model inputs'!B500,'Model inputs'!B501,'Model inputs'!B502,'Model inputs'!B503,'Model inputs'!B504)) -> 45000 | R24: =IF(SUM(IF(IF('Model inputs'!B505="",0,1)="",0,IF('Model inputs'!B505="",0,1)),IF(IF('Model inputs'!B506="",0,1)="",0,IF('Model inputs'!B506="",0,1)),IF(IF('Model inputs'!B507="",0,1)="",0,IF('Model inputs'!B507="",0,1)),IF(IF('Model inputs'!B508="",0,1)="",0,IF('Model inputs'!B508="",0,1)),IF(IF('Model inputs'!B509="",0,1)="",0,IF('Model inputs'!B509="",0,1)))=0,"",SUM('Model inputs'!B505,'Model inputs'!B506,'Model inputs'!B507,'Model inputs'!B508,'Model inputs'!B509)) -> 47500 | S24: =IF(SUM(IF(IF('Model inputs'!B510="",0,1)="",0,IF('Model inputs'!B510="",0,1)),IF(IF('Model inputs'!B511="",0,1)="",0,IF('Model inputs'!B511="",0,1)),IF(IF('Model inputs'!B512="",0,1)="",0,IF('Model inputs'!B512="",0,1)),IF(IF('Model inputs'!B513="",0,1)="",0,IF('Model inputs'!B513="",0,1)),IF(IF('Model inputs'!B514="",0,1)="",0,IF('Model inputs'!B514="",0,1)))=0,"",SUM('Model inputs'!B510,'Model inputs'!B511,'Model inputs'!B512,'Model inputs'!B513,'Model inputs'!B514)) -> 50000 | T24: =IF(SUM(IF(IF('Model inputs'!B515="",0,1)="",0,IF('Model inputs'!B515="",0,1)),IF(IF('Model inputs'!B516="",0,1)="",0,IF('Model inputs'!B516="",0,1)),IF(IF('Model inputs'!B517="",0,1)="",0,IF('Model inputs'!B517="",0,1)),IF(IF('Model inputs'!B518="",0,1)="",0,IF('Model inputs'!B518="",0,1)),IF(IF('Model inputs'!B519="",0,1)="",0,IF('Model inputs'!B519="",0,1)))=0,"",SUM('Model inputs'!B515,'Model inputs'!B516,'Model inputs'!B517,'Model inputs'!B518,'Model inputs'!B519)) -> 52500 | U24: =IF(SUM(IF(IF('Model inputs'!B520="",0,1)="",0,IF('Model inputs'!B520="",0,1)),IF(IF('Model inputs'!B521="",0,1)="",0,IF('Model inputs'!B521="",0,1)),IF(IF('Model inputs'!B522="",0,1)="",0,IF('Model inputs'!B522="",0,1)),IF(IF('Model inputs'!B523="",0,1)="",0,IF('Model inputs'!B523="",0,1)),IF(IF('Model inputs'!B524="",0,1)="",0,IF('Model inputs'!B524="",0,1)))=0,"",SUM('Model inputs'!B520,'Model inputs'!B521,'Model inputs'!B522,'Model inputs'!B523,'Model inputs'!B524)) -> 55000 | V24: =IF(SUM(IF(IF('Model inputs'!B525="",0,1)="",0,IF('Model inputs'!B525="",0,1)),IF(IF('Model inputs'!B526="",0,1)="",0,IF('Model inputs'!B526="",0,1)),IF(IF('Model inputs'!B527="",0,1)="",0,IF('Model inputs'!B527="",0,1)),IF(IF('Model inputs'!B528="",0,1)="",0,IF('Model inputs'!B528="",0,1)),IF(IF('Model inputs'!B529="",0,1)="",0,IF('Model inputs'!B529="",0,1)))=0,"",SUM('Model inputs'!B525,'Model inputs'!B526,'Model inputs'!B527,'Model inputs'!B528,'Model inputs'!B529)) -> 57500 | W24: =IF(SUM(IF(IF('Model inputs'!B530="",0,1)="",0,IF('Model inputs'!B530="",0,1)),IF(IF('Model inputs'!B531="",0,1)="",0,IF('Model inputs'!B531="",0,1)),IF(IF('Model inputs'!B532="",0,1)="",0,IF('Model inputs'!B532="",0,1)),IF(IF('Model inputs'!B533="",0,1)="",0,IF('Model inputs'!B533="",0,1)),IF(IF('Model inputs'!B534="",0,1)="",0,IF('Model inputs'!B534="",0,1)))=0,"",SUM('Model inputs'!B530,'Model inputs'!B531,'Model inputs'!B532,'Model inputs'!B533,'Model inputs'!B534)) -> 60000 | X24: =IF(SUM(IF(IF('Model inputs'!B535="",0,1)="",0,IF('Model inputs'!B535="",0,1)),IF(IF('Model inputs'!B536="",0,1)="",0,IF('Model inputs'!B536="",0,1)),IF(IF('Model inputs'!B537="",0,1)="",0,IF('Model inputs'!B537="",0,1)),IF(IF('Model inputs'!B538="",0,1)="",0,IF('Model inputs'!B538="",0,1)),IF(IF('Model inputs'!B539="",0,1)="",0,IF('Model inputs'!B539="",0,1)))=0,"",SUM('Model inputs'!B535,'Model inputs'!B536,'Model inputs'!B537,'Model inputs'!B538,'Model inputs'!B539)) -> 30000 | Y24: =IF(SUM(IF(IF('Model inputs'!B540="",0,1)="",0,IF('Model inputs'!B540="",0,1)),IF(IF('Model inputs'!B541="",0,1)="",0,IF('Model inputs'!B541="",0,1)),IF(IF('Model inputs'!B542="",0,1)="",0,IF('Model inputs'!B542="",0,1)),IF(IF('Model inputs'!B543="",0,1)="",0,IF('Model inputs'!B543="",0,1)),IF(IF('Model inputs'!B544="",0,1)="",0,IF('Model inputs'!B544="",0,1)))=0,"",SUM('Model inputs'!B540,'Model inputs'!B541,'Model inputs'!B542,'Model inputs'!B543,'Model inputs'!B544)) -> 30000 | Z24: =IF(SUM(IF(IF('Model inputs'!B545="",0,1)="",0,IF('Model inputs'!B545="",0,1)),IF(IF('Model inputs'!B546="",0,1)="",0,IF('Model inputs'!B546="",0,1)),IF(IF('Model inputs'!B547="",0,1)="",0,IF('Model inputs'!B547="",0,1)),IF(IF('Model inputs'!B548="",0,1)="",0,IF('Model inputs'!B548="",0,1)),IF(IF('Model inputs'!B549="",0,1)="",0,IF('Model inputs'!B549="",0,1)))=0,"",SUM('Model inputs'!B545,'Model inputs'!B546,'Model inputs'!B547,'Model inputs'!B548,'Model inputs'!B549)) -> 30000
A25: Plan Cash collections · Conservative | C25: 0 | D25: 0 | E25: 0 | F25: 0 | G25: 0 | H25: 0 | I25: 0 | J25: 0 | K25: 0 | L25: =IF(SUM(IF(IF('Model inputs'!B550="",0,1)="",0,IF('Model inputs'!B550="",0,1)),IF(IF('Model inputs'!B551="",0,1)="",0,IF('Model inputs'!B551="",0,1)),IF(IF('Model inputs'!B552="",0,1)="",0,IF('Model inputs'!B552="",0,1)),IF(IF('Model inputs'!B553="",0,1)="",0,IF('Model inputs'!B553="",0,1)),IF(IF('Model inputs'!B554="",0,1)="",0,IF('Model inputs'!B554="",0,1)))=0,"",SUM('Model inputs'!B550,'Model inputs'!B551,'Model inputs'!B552,'Model inputs'!B553,'Model inputs'!B554)) -> 0 | M25: =IF(SUM(IF(IF('Model inputs'!B555="",0,1)="",0,IF('Model inputs'!B555="",0,1)),IF(IF('Model inputs'!B556="",0,1)="",0,IF('Model inputs'!B556="",0,1)),IF(IF('Model inputs'!B557="",0,1)="",0,IF('Model inputs'!B557="",0,1)),IF(IF('Model inputs'!B558="",0,1)="",0,IF('Model inputs'!B558="",0,1)),IF(IF('Model inputs'!B559="",0,1)="",0,IF('Model inputs'!B559="",0,1)))=0,"",SUM('Model inputs'!B555,'Model inputs'!B556,'Model inputs'!B557,'Model inputs'!B558,'Model inputs'!B559)) -> 0 | N25: =IF(SUM(IF(IF('Model inputs'!B560="",0,1)="",0,IF('Model inputs'!B560="",0,1)),IF(IF('Model inputs'!B561="",0,1)="",0,IF('Model inputs'!B561="",0,1)),IF(IF('Model inputs'!B562="",0,1)="",0,IF('Model inputs'!B562="",0,1)),IF(IF('Model inputs'!B563="",0,1)="",0,IF('Model inputs'!B563="",0,1)),IF(IF('Model inputs'!B564="",0,1)="",0,IF('Model inputs'!B564="",0,1)))=0,"",SUM('Model inputs'!B560,'Model inputs'!B561,'Model inputs'!B562,'Model inputs'!B563,'Model inputs'!B564)) -> 3000 | O25: =IF(SUM(IF(IF('Model inputs'!B565="",0,1)="",0,IF('Model inputs'!B565="",0,1)),IF(IF('Model inputs'!B566="",0,1)="",0,IF('Model inputs'!B566="",0,1)),IF(IF('Model inputs'!B567="",0,1)="",0,IF('Model inputs'!B567="",0,1)),IF(IF('Model inputs'!B568="",0,1)="",0,IF('Model inputs'!B568="",0,1)),IF(IF('Model inputs'!B569="",0,1)="",0,IF('Model inputs'!B569="",0,1)))=0,"",SUM('Model inputs'!B565,'Model inputs'!B566,'Model inputs'!B567,'Model inputs'!B568,'Model inputs'!B569)) -> 3000 | P25: =IF(SUM(IF(IF('Model inputs'!B570="",0,1)="",0,IF('Model inputs'!B570="",0,1)),IF(IF('Model inputs'!B571="",0,1)="",0,IF('Model inputs'!B571="",0,1)),IF(IF('Model inputs'!B572="",0,1)="",0,IF('Model inputs'!B572="",0,1)),IF(IF('Model inputs'!B573="",0,1)="",0,IF('Model inputs'!B573="",0,1)),IF(IF('Model inputs'!B574="",0,1)="",0,IF('Model inputs'!B574="",0,1)))=0,"",SUM('Model inputs'!B570,'Model inputs'!B571,'Model inputs'!B572,'Model inputs'!B573,'Model inputs'!B574)) -> 3000 | Q25: =IF(SUM(IF(IF('Model inputs'!B575="",0,1)="",0,IF('Model inputs'!B575="",0,1)),IF(IF('Model inputs'!B576="",0,1)="",0,IF('Model inputs'!B576="",0,1)),IF(IF('Model inputs'!B577="",0,1)="",0,IF('Model inputs'!B577="",0,1)),IF(IF('Model inputs'!B578="",0,1)="",0,IF('Model inputs'!B578="",0,1)),IF(IF('Model inputs'!B579="",0,1)="",0,IF('Model inputs'!B579="",0,1)))=0,"",SUM('Model inputs'!B575,'Model inputs'!B576,'Model inputs'!B577,'Model inputs'!B578,'Model inputs'!B579)) -> 3000 | R25: =IF(SUM(IF(IF('Model inputs'!B580="",0,1)="",0,IF('Model inputs'!B580="",0,1)),IF(IF('Model inputs'!B581="",0,1)="",0,IF('Model inputs'!B581="",0,1)),IF(IF('Model inputs'!B582="",0,1)="",0,IF('Model inputs'!B582="",0,1)),IF(IF('Model inputs'!B583="",0,1)="",0,IF('Model inputs'!B583="",0,1)),IF(IF('Model inputs'!B584="",0,1)="",0,IF('Model inputs'!B584="",0,1)))=0,"",SUM('Model inputs'!B580,'Model inputs'!B581,'Model inputs'!B582,'Model inputs'!B583,'Model inputs'!B584)) -> 3000 | S25: =IF(SUM(IF(IF('Model inputs'!B585="",0,1)="",0,IF('Model inputs'!B585="",0,1)),IF(IF('Model inputs'!B586="",0,1)="",0,IF('Model inputs'!B586="",0,1)),IF(IF('Model inputs'!B587="",0,1)="",0,IF('Model inputs'!B587="",0,1)),IF(IF('Model inputs'!B588="",0,1)="",0,IF('Model inputs'!B588="",0,1)),IF(IF('Model inputs'!B589="",0,1)="",0,IF('Model inputs'!B589="",0,1)))=0,"",SUM('Model inputs'!B585,'Model inputs'!B586,'Model inputs'!B587,'Model inputs'!B588,'Model inputs'!B589)) -> 3000 | T25: =IF(SUM(IF(IF('Model inputs'!B590="",0,1)="",0,IF('Model inputs'!B590="",0,1)),IF(IF('Model inputs'!B591="",0,1)="",0,IF('Model inputs'!B591="",0,1)),IF(IF('Model inputs'!B592="",0,1)="",0,IF('Model inputs'!B592="",0,1)),IF(IF('Model inputs'!B593="",0,1)="",0,IF('Model inputs'!B593="",0,1)),IF(IF('Model inputs'!B594="",0,1)="",0,IF('Model inputs'!B594="",0,1)))=0,"",SUM('Model inputs'!B590,'Model inputs'!B591,'Model inputs'!B592,'Model inputs'!B593,'Model inputs'!B594)) -> 3000 | U25: =IF(SUM(IF(IF('Model inputs'!B595="",0,1)="",0,IF('Model inputs'!B595="",0,1)),IF(IF('Model inputs'!B596="",0,1)="",0,IF('Model inputs'!B596="",0,1)),IF(IF('Model inputs'!B597="",0,1)="",0,IF('Model inputs'!B597="",0,1)),IF(IF('Model inputs'!B598="",0,1)="",0,IF('Model inputs'!B598="",0,1)),IF(IF('Model inputs'!B599="",0,1)="",0,IF('Model inputs'!B599="",0,1)))=0,"",SUM('Model inputs'!B595,'Model inputs'!B596,'Model inputs'!B597,'Model inputs'!B598,'Model inputs'!B599)) -> 3000 | V25: =IF(SUM(IF(IF('Model inputs'!B600="",0,1)="",0,IF('Model inputs'!B600="",0,1)),IF(IF('Model inputs'!B601="",0,1)="",0,IF('Model inputs'!B601="",0,1)),IF(IF('Model inputs'!B602="",0,1)="",0,IF('Model inputs'!B602="",0,1)),IF(IF('Model inputs'!B603="",0,1)="",0,IF('Model inputs'!B603="",0,1)),IF(IF('Model inputs'!B604="",0,1)="",0,IF('Model inputs'!B604="",0,1)))=0,"",SUM('Model inputs'!B600,'Model inputs'!B601,'Model inputs'!B602,'Model inputs'!B603,'Model inputs'!B604)) -> 3000 | W25: =IF(SUM(IF(IF('Model inputs'!B605="",0,1)="",0,IF('Model inputs'!B605="",0,1)),IF(IF('Model inputs'!B606="",0,1)="",0,IF('Model inputs'!B606="",0,1)),IF(IF('Model inputs'!B607="",0,1)="",0,IF('Model inputs'!B607="",0,1)),IF(IF('Model inputs'!B608="",0,1)="",0,IF('Model inputs'!B608="",0,1)),IF(IF('Model inputs'!B609="",0,1)="",0,IF('Model inputs'!B609="",0,1)))=0,"",SUM('Model inputs'!B605,'Model inputs'!B606,'Model inputs'!B607,'Model inputs'!B608,'Model inputs'!B609)) -> 3000 | X25: =IF(SUM(IF(IF('Model inputs'!B610="",0,1)="",0,IF('Model inputs'!B610="",0,1)),IF(IF('Model inputs'!B611="",0,1)="",0,IF('Model inputs'!B611="",0,1)),IF(IF('Model inputs'!B612="",0,1)="",0,IF('Model inputs'!B612="",0,1)),IF(IF('Model inputs'!B613="",0,1)="",0,IF('Model inputs'!B613="",0,1)),IF(IF('Model inputs'!B614="",0,1)="",0,IF('Model inputs'!B614="",0,1)))=0,"",SUM('Model inputs'!B610,'Model inputs'!B611,'Model inputs'!B612,'Model inputs'!B613,'Model inputs'!B614)) -> 3000 | Y25: =IF(SUM(IF(IF('Model inputs'!B615="",0,1)="",0,IF('Model inputs'!B615="",0,1)),IF(IF('Model inputs'!B616="",0,1)="",0,IF('Model inputs'!B616="",0,1)),IF(IF('Model inputs'!B617="",0,1)="",0,IF('Model inputs'!B617="",0,1)),IF(IF('Model inputs'!B618="",0,1)="",0,IF('Model inputs'!B618="",0,1)),IF(IF('Model inputs'!B619="",0,1)="",0,IF('Model inputs'!B619="",0,1)))=0,"",SUM('Model inputs'!B615,'Model inputs'!B616,'Model inputs'!B617,'Model inputs'!B618,'Model inputs'!B619)) -> 3000 | Z25: =IF(SUM(IF(IF('Model inputs'!B620="",0,1)="",0,IF('Model inputs'!B620="",0,1)),IF(IF('Model inputs'!B621="",0,1)="",0,IF('Model inputs'!B621="",0,1)),IF(IF('Model inputs'!B622="",0,1)="",0,IF('Model inputs'!B622="",0,1)),IF(IF('Model inputs'!B623="",0,1)="",0,IF('Model inputs'!B623="",0,1)),IF(IF('Model inputs'!B624="",0,1)="",0,IF('Model inputs'!B624="",0,1)))=0,"",SUM('Model inputs'!B620,'Model inputs'!B621,'Model inputs'!B622,'Model inputs'!B623,'Model inputs'!B624)) -> 3000
