Workbook

Sheet DealScope 12-month financial pr
A1: DealScope 12-month financial projection
A2: DealScope — Financial projection · Growth
A4: Variable / dimension | B4: 2026-10 | C4: 2026-11 | D4: 2026-12 | E4: 2027-01 | F4: 2027-02 | G4: 2027-03 | H4: 2027-04 | I4: 2027-05 | J4: 2027-06 | K4: 2027-07 | L4: 2027-08 | M4: 2027-09
A5: Paying customer equivalents | B5: =IF(IF(IF(ISERROR('Model inputs'!O80=1),'Model inputs'!O80=1,IF('Model inputs'!O80="","",'Model inputs'!O80=1))="",FALSE,IF(ISERROR('Model inputs'!O80=1),'Model inputs'!O80=1,IF('Model inputs'!O80="","",'Model inputs'!O80=1))),'Model inputs'!O114*MIN(MAX(('Model inputs'!C105-'Model inputs'!O109)/'Model inputs'!O63,0),1),IF(IF(IF(ISERROR('Model inputs'!C105>'Model inputs'!O109),'Model inputs'!C105>'Model inputs'!O109,IF(OR('Model inputs'!C105="",'Model inputs'!O109=""),"",'Model inputs'!C105>'Model inputs'!O109))="",FALSE,IF(ISERROR('Model inputs'!C105>'Model inputs'!O109),'Model inputs'!C105>'Model inputs'!O109,IF(OR('Model inputs'!C105="",'Model inputs'!O109=""),"",'Model inputs'!C105>'Model inputs'!O109))),IF('Model inputs'!O114="","",'Model inputs'!O114),0)) -> 1.25 | C5: =IF(IF(IF(ISERROR('Model inputs'!O80=1),'Model inputs'!O80=1,IF('Model inputs'!O80="","",'Model inputs'!O80=1))="",FALSE,IF(ISERROR('Model inputs'!O80=1),'Model inputs'!O80=1,IF('Model inputs'!O80="","",'Model inputs'!O80=1))),'Model inputs'!O114*MIN(MAX(('Model inputs'!D105-'Model inputs'!O109)/'Model inputs'!O63,0),1),IF(IF(IF(ISERROR('Model inputs'!D105>'Model inputs'!O109),'Model inputs'!D105>'Model inputs'!O109,IF(OR('Model inputs'!D105="",'Model inputs'!O109=""),"",'Model inputs'!D105>'Model inputs'!O109))="",FALSE,IF(ISERROR('Model inputs'!D105>'Model inputs'!O109),'Model inputs'!D105>'Model inputs'!O109,IF(OR('Model inputs'!D105="",'Model inputs'!O109=""),"",'Model inputs'!D105>'Model inputs'!O109))),IF('Model inputs'!O114="","",'Model inputs'!O114),0)) -> 2.5 | D5: =IF(IF(IF(ISERROR('Model inputs'!O80=1),'Model inputs'!O80=1,IF('Model inputs'!O80="","",'Model inputs'!O80=1))="",FALSE,IF(ISERROR('Model inputs'!O80=1),'Model inputs'!O80=1,IF('Model inputs'!O80="","",'Model inputs'!O80=1))),'Model inputs'!O114*MIN(MAX(('Model inputs'!E105-'Model inputs'!O109)/'Model inputs'!O63,0),1),IF(IF(IF(ISERROR('Model inputs'!E105>'Model inputs'!O109),'Model inputs'!E105>'Model inputs'!O109,IF(OR('Model inputs'!E105="",'Model inputs'!O109=""),"",'Model inputs'!E105>'Model inputs'!O109))="",FALSE,IF(ISERROR('Model inputs'!E105>'Model inputs'!O109),'Model inputs'!E105>'Model inputs'!O109,IF(OR('Model inputs'!E105="",'Model inputs'!O109=""),"",'Model inputs'!E105>'Model inputs'!O109))),IF('Model inputs'!O114="","",'Model inputs'!O114),0)) -> 3.75 | E5: =IF(IF(IF(ISERROR('Model inputs'!O80=1),'Model inputs'!O80=1,IF('Model inputs'!O80="","",'Model inputs'!O80=1))="",FALSE,IF(ISERROR('Model inputs'!O80=1),'Model inputs'!O80=1,IF('Model inputs'!O80="","",'Model inputs'!O80=1))),'Model inputs'!O114*MIN(MAX(('Model inputs'!F105-'Model inputs'!O109)/'Model inputs'!O63,0),1),IF(IF(IF(ISERROR('Model inputs'!F105>'Model inputs'!O109),'Model inputs'!F105>'Model inputs'!O109,IF(OR('Model inputs'!F105="",'Model inputs'!O109=""),"",'Model inputs'!F105>'Model inputs'!O109))="",FALSE,IF(ISERROR('Model inputs'!F105>'Model inputs'!O109),'Model inputs'!F105>'Model inputs'!O109,IF(OR('Model inputs'!F105="",'Model inputs'!O109=""),"",'Model inputs'!F105>'Model inputs'!O109))),IF('Model inputs'!O114="","",'Model inputs'!O114),0)) -> 5 | F5: =IF(IF(IF(ISERROR('Model inputs'!O80=1),'Model inputs'!O80=1,IF('Model inputs'!O80="","",'Model inputs'!O80=1))="",FALSE,IF(ISERROR('Model inputs'!O80=1),'Model inputs'!O80=1,IF('Model inputs'!O80="","",'Model inputs'!O80=1))),'Model inputs'!O114*MIN(MAX(('Model inputs'!G105-'Model inputs'!O109)/'Model inputs'!O63,0),1),IF(IF(IF(ISERROR('Model inputs'!G105>'Model inputs'!O109),'Model inputs'!G105>'Model inputs'!O109,IF(OR('Model inputs'!G105="",'Model inputs'!O109=""),"",'Model inputs'!G105>'Model inputs'!O109))="",FALSE,IF(ISERROR('Model inputs'!G105>'Model inputs'!O109),'Model inputs'!G105>'Model inputs'!O109,IF(OR('Model inputs'!G105="",'Model inputs'!O109=""),"",'Model inputs'!G105>'Model inputs'!O109))),IF('Model inputs'!O114="","",'Model inputs'!O114),0)) -> 6.25 | G5: =IF(IF(IF(ISERROR('Model inputs'!O80=1),'Model inputs'!O80=1,IF('Model inputs'!O80="","",'Model inputs'!O80=1))="",FALSE,IF(ISERROR('Model inputs'!O80=1),'Model inputs'!O80=1,IF('Model inputs'!O80="","",'Model inputs'!O80=1))),'Model inputs'!O114*MIN(MAX(('Model inputs'!H105-'Model inputs'!O109)/'Model inputs'!O63,0),1),IF(IF(IF(ISERROR('Model inputs'!H105>'Model inputs'!O109),'Model inputs'!H105>'Model inputs'!O109,IF(OR('Model inputs'!H105="",'Model inputs'!O109=""),"",'Model inputs'!H105>'Model inputs'!O109))="",FALSE,IF(ISERROR('Model inputs'!H105>'Model inputs'!O109),'Model inputs'!H105>'Model inputs'!O109,IF(OR('Model inputs'!H105="",'Model inputs'!O109=""),"",'Model inputs'!H105>'Model inputs'!O109))),IF('Model inputs'!O114="","",'Model inputs'!O114),0)) -> 7.5 | H5: =IF(IF(IF(ISERROR('Model inputs'!O80=1),'Model inputs'!O80=1,IF('Model inputs'!O80="","",'Model inputs'!O80=1))="",FALSE,IF(ISERROR('Model inputs'!O80=1),'Model inputs'!O80=1,IF('Model inputs'!O80="","",'Model inputs'!O80=1))),'Model inputs'!O114*MIN(MAX(('Model inputs'!I105-'Model inputs'!O109)/'Model inputs'!O63,0),1),IF(IF(IF(ISERROR('Model inputs'!I105>'Model inputs'!O109),'Model inputs'!I105>'Model inputs'!O109,IF(OR('Model inputs'!I105="",'Model inputs'!O109=""),"",'Model inputs'!I105>'Model inputs'!O109))="",FALSE,IF(ISERROR('Model inputs'!I105>'Model inputs'!O109),'Model inputs'!I105>'Model inputs'!O109,IF(OR('Model inputs'!I105="",'Model inputs'!O109=""),"",'Model inputs'!I105>'Model inputs'!O109))),IF('Model inputs'!O114="","",'Model inputs'!O114),0)) -> 8.75 | I5: =IF(IF(IF(ISERROR('Model inputs'!O80=1),'Model inputs'!O80=1,IF('Model inputs'!O80="","",'Model inputs'!O80=1))="",FALSE,IF(ISERROR('Model inputs'!O80=1),'Model inputs'!O80=1,IF('Model inputs'!O80="","",'Model inputs'!O80=1))),'Model inputs'!O114*MIN(MAX(('Model inputs'!J105-'Model inputs'!O109)/'Model inputs'!O63,0),1),IF(IF(IF(ISERROR('Model inputs'!J105>'Model inputs'!O109),'Model inputs'!J105>'Model inputs'!O109,IF(OR('Model inputs'!J105="",'Model inputs'!O109=""),"",'Model inputs'!J105>'Model inputs'!O109))="",FALSE,IF(ISERROR('Model inputs'!J105>'Model inputs'!O109),'Model inputs'!J105>'Model inputs'!O109,IF(OR('Model inputs'!J105="",'Model inputs'!O109=""),"",'Model inputs'!J105>'Model inputs'!O109))),IF('Model inputs'!O114="","",'Model inputs'!O114),0)) -> 10 | J5: =IF(IF(IF(ISERROR('Model inputs'!O80=1),'Model inputs'!O80=1,IF('Model inputs'!O80="","",'Model inputs'!O80=1))="",FALSE,IF(ISERROR('Model inputs'!O80=1),'Model inputs'!O80=1,IF('Model inputs'!O80="","",'Model inputs'!O80=1))),'Model inputs'!O114*MIN(MAX(('Model inputs'!K105-'Model inputs'!O109)/'Model inputs'!O63,0),1),IF(IF(IF(ISERROR('Model inputs'!K105>'Model inputs'!O109),'Model inputs'!K105>'Model inputs'!O109,IF(OR('Model inputs'!K105="",'Model inputs'!O109=""),"",'Model inputs'!K105>'Model inputs'!O109))="",FALSE,IF(ISERROR('Model inputs'!K105>'Model inputs'!O109),'Model inputs'!K105>'Model inputs'!O109,IF(OR('Model inputs'!K105="",'Model inputs'!O109=""),"",'Model inputs'!K105>'Model inputs'!O109))),IF('Model inputs'!O114="","",'Model inputs'!O114),0)) -> 11.25 | K5: =IF(IF(IF(ISERROR('Model inputs'!O80=1),'Model inputs'!O80=1,IF('Model inputs'!O80="","",'Model inputs'!O80=1))="",FALSE,IF(ISERROR('Model inputs'!O80=1),'Model inputs'!O80=1,IF('Model inputs'!O80="","",'Model inputs'!O80=1))),'Model inputs'!O114*MIN(MAX(('Model inputs'!L105-'Model inputs'!O109)/'Model inputs'!O63,0),1),IF(IF(IF(ISERROR('Model inputs'!L105>'Model inputs'!O109),'Model inputs'!L105>'Model inputs'!O109,IF(OR('Model inputs'!L105="",'Model inputs'!O109=""),"",'Model inputs'!L105>'Model inputs'!O109))="",FALSE,IF(ISERROR('Model inputs'!L105>'Model inputs'!O109),'Model inputs'!L105>'Model inputs'!O109,IF(OR('Model inputs'!L105="",'Model inputs'!O109=""),"",'Model inputs'!L105>'Model inputs'!O109))),IF('Model inputs'!O114="","",'Model inputs'!O114),0)) -> 12.5 | L5: =IF(IF(IF(ISERROR('Model inputs'!O80=1),'Model inputs'!O80=1,IF('Model inputs'!O80="","",'Model inputs'!O80=1))="",FALSE,IF(ISERROR('Model inputs'!O80=1),'Model inputs'!O80=1,IF('Model inputs'!O80="","",'Model inputs'!O80=1))),'Model inputs'!O114*MIN(MAX(('Model inputs'!M105-'Model inputs'!O109)/'Model inputs'!O63,0),1),IF(IF(IF(ISERROR('Model inputs'!M105>'Model inputs'!O109),'Model inputs'!M105>'Model inputs'!O109,IF(OR('Model inputs'!M105="",'Model inputs'!O109=""),"",'Model inputs'!M105>'Model inputs'!O109))="",FALSE,IF(ISERROR('Model inputs'!M105>'Model inputs'!O109),'Model inputs'!M105>'Model inputs'!O109,IF(OR('Model inputs'!M105="",'Model inputs'!O109=""),"",'Model inputs'!M105>'Model inputs'!O109))),IF('Model inputs'!O114="","",'Model inputs'!O114),0)) -> 13.75 | M5: =IF(IF(IF(ISERROR('Model inputs'!O80=1),'Model inputs'!O80=1,IF('Model inputs'!O80="","",'Model inputs'!O80=1))="",FALSE,IF(ISERROR('Model inputs'!O80=1),'Model inputs'!O80=1,IF('Model inputs'!O80="","",'Model inputs'!O80=1))),'Model inputs'!O114*MIN(MAX(('Model inputs'!N105-'Model inputs'!O109)/'Model inputs'!O63,0),1),IF(IF(IF(ISERROR('Model inputs'!N105>'Model inputs'!O109),'Model inputs'!N105>'Model inputs'!O109,IF(OR('Model inputs'!N105="",'Model inputs'!O109=""),"",'Model inputs'!N105>'Model inputs'!O109))="",FALSE,IF(ISERROR('Model inputs'!N105>'Model inputs'!O109),'Model inputs'!N105>'Model inputs'!O109,IF(OR('Model inputs'!N105="",'Model inputs'!O109=""),"",'Model inputs'!N105>'Model inputs'!O109))),IF('Model inputs'!O114="","",'Model inputs'!O114),0)) -> 15
A6: Plan Audits delivered | B6: =IF(SUM(IF(IF('Model inputs'!B274="",0,1)="",0,IF('Model inputs'!B274="",0,1)),IF(IF('Model inputs'!B275="",0,1)="",0,IF('Model inputs'!B275="",0,1)),IF(IF('Model inputs'!B276="",0,1)="",0,IF('Model inputs'!B276="",0,1)),IF(IF('Model inputs'!B277="",0,1)="",0,IF('Model inputs'!B277="",0,1)),IF(IF('Model inputs'!B278="",0,1)="",0,IF('Model inputs'!B278="",0,1)))=0,"",SUM('Model inputs'!B274,'Model inputs'!B275,'Model inputs'!B276,'Model inputs'!B277,'Model inputs'!B278)) -> 5 | C6: =IF(SUM(IF(IF('Model inputs'!B279="",0,1)="",0,IF('Model inputs'!B279="",0,1)),IF(IF('Model inputs'!B280="",0,1)="",0,IF('Model inputs'!B280="",0,1)),IF(IF('Model inputs'!B281="",0,1)="",0,IF('Model inputs'!B281="",0,1)),IF(IF('Model inputs'!B282="",0,1)="",0,IF('Model inputs'!B282="",0,1)),IF(IF('Model inputs'!B283="",0,1)="",0,IF('Model inputs'!B283="",0,1)))=0,"",SUM('Model inputs'!B279,'Model inputs'!B280,'Model inputs'!B281,'Model inputs'!B282,'Model inputs'!B283)) -> 10 | D6: =IF(SUM(IF(IF('Model inputs'!B284="",0,1)="",0,IF('Model inputs'!B284="",0,1)),IF(IF('Model inputs'!B285="",0,1)="",0,IF('Model inputs'!B285="",0,1)),IF(IF('Model inputs'!B286="",0,1)="",0,IF('Model inputs'!B286="",0,1)),IF(IF('Model inputs'!B287="",0,1)="",0,IF('Model inputs'!B287="",0,1)),IF(IF('Model inputs'!B288="",0,1)="",0,IF('Model inputs'!B288="",0,1)))=0,"",SUM('Model inputs'!B284,'Model inputs'!B285,'Model inputs'!B286,'Model inputs'!B287,'Model inputs'!B288)) -> 15 | E6: =IF(SUM(IF(IF('Model inputs'!B289="",0,1)="",0,IF('Model inputs'!B289="",0,1)),IF(IF('Model inputs'!B290="",0,1)="",0,IF('Model inputs'!B290="",0,1)),IF(IF('Model inputs'!B291="",0,1)="",0,IF('Model inputs'!B291="",0,1)),IF(IF('Model inputs'!B292="",0,1)="",0,IF('Model inputs'!B292="",0,1)),IF(IF('Model inputs'!B293="",0,1)="",0,IF('Model inputs'!B293="",0,1)))=0,"",SUM('Model inputs'!B289,'Model inputs'!B290,'Model inputs'!B291,'Model inputs'!B292,'Model inputs'!B293)) -> 20 | F6: =IF(SUM(IF(IF('Model inputs'!B294="",0,1)="",0,IF('Model inputs'!B294="",0,1)),IF(IF('Model inputs'!B295="",0,1)="",0,IF('Model inputs'!B295="",0,1)),IF(IF('Model inputs'!B296="",0,1)="",0,IF('Model inputs'!B296="",0,1)),IF(IF('Model inputs'!B297="",0,1)="",0,IF('Model inputs'!B297="",0,1)),IF(IF('Model inputs'!B298="",0,1)="",0,IF('Model inputs'!B298="",0,1)))=0,"",SUM('Model inputs'!B294,'Model inputs'!B295,'Model inputs'!B296,'Model inputs'!B297,'Model inputs'!B298)) -> 25 | G6: =IF(SUM(IF(IF('Model inputs'!B299="",0,1)="",0,IF('Model inputs'!B299="",0,1)),IF(IF('Model inputs'!B300="",0,1)="",0,IF('Model inputs'!B300="",0,1)),IF(IF('Model inputs'!B301="",0,1)="",0,IF('Model inputs'!B301="",0,1)),IF(IF('Model inputs'!B302="",0,1)="",0,IF('Model inputs'!B302="",0,1)),IF(IF('Model inputs'!B303="",0,1)="",0,IF('Model inputs'!B303="",0,1)))=0,"",SUM('Model inputs'!B299,'Model inputs'!B300,'Model inputs'!B301,'Model inputs'!B302,'Model inputs'!B303)) -> 30 | H6: =IF(SUM(IF(IF('Model inputs'!B304="",0,1)="",0,IF('Model inputs'!B304="",0,1)),IF(IF('Model inputs'!B305="",0,1)="",0,IF('Model inputs'!B305="",0,1)),IF(IF('Model inputs'!B306="",0,1)="",0,IF('Model inputs'!B306="",0,1)),IF(IF('Model inputs'!B307="",0,1)="",0,IF('Model inputs'!B307="",0,1)),IF(IF('Model inputs'!B308="",0,1)="",0,IF('Model inputs'!B308="",0,1)))=0,"",SUM('Model inputs'!B304,'Model inputs'!B305,'Model inputs'!B306,'Model inputs'!B307,'Model inputs'!B308)) -> 35 | I6: =IF(SUM(IF(IF('Model inputs'!B309="",0,1)="",0,IF('Model inputs'!B309="",0,1)),IF(IF('Model inputs'!B310="",0,1)="",0,IF('Model inputs'!B310="",0,1)),IF(IF('Model inputs'!B311="",0,1)="",0,IF('Model inputs'!B311="",0,1)),IF(IF('Model inputs'!B312="",0,1)="",0,IF('Model inputs'!B312="",0,1)),IF(IF('Model inputs'!B313="",0,1)="",0,IF('Model inputs'!B313="",0,1)))=0,"",SUM('Model inputs'!B309,'Model inputs'!B310,'Model inputs'!B311,'Model inputs'!B312,'Model inputs'!B313)) -> 40 | J6: =IF(SUM(IF(IF('Model inputs'!B314="",0,1)="",0,IF('Model inputs'!B314="",0,1)),IF(IF('Model inputs'!B315="",0,1)="",0,IF('Model inputs'!B315="",0,1)),IF(IF('Model inputs'!B316="",0,1)="",0,IF('Model inputs'!B316="",0,1)),IF(IF('Model inputs'!B317="",0,1)="",0,IF('Model inputs'!B317="",0,1)),IF(IF('Model inputs'!B318="",0,1)="",0,IF('Model inputs'!B318="",0,1)))=0,"",SUM('Model inputs'!B314,'Model inputs'!B315,'Model inputs'!B316,'Model inputs'!B317,'Model inputs'!B318)) -> 45 | K6: =IF(SUM(IF(IF('Model inputs'!B319="",0,1)="",0,IF('Model inputs'!B319="",0,1)),IF(IF('Model inputs'!B320="",0,1)="",0,IF('Model inputs'!B320="",0,1)),IF(IF('Model inputs'!B321="",0,1)="",0,IF('Model inputs'!B321="",0,1)),IF(IF('Model inputs'!B322="",0,1)="",0,IF('Model inputs'!B322="",0,1)),IF(IF('Model inputs'!B323="",0,1)="",0,IF('Model inputs'!B323="",0,1)))=0,"",SUM('Model inputs'!B319,'Model inputs'!B320,'Model inputs'!B321,'Model inputs'!B322,'Model inputs'!B323)) -> 50 | L6: =IF(SUM(IF(IF('Model inputs'!B324="",0,1)="",0,IF('Model inputs'!B324="",0,1)),IF(IF('Model inputs'!B325="",0,1)="",0,IF('Model inputs'!B325="",0,1)),IF(IF('Model inputs'!B326="",0,1)="",0,IF('Model inputs'!B326="",0,1)),IF(IF('Model inputs'!B327="",0,1)="",0,IF('Model inputs'!B327="",0,1)),IF(IF('Model inputs'!B328="",0,1)="",0,IF('Model inputs'!B328="",0,1)))=0,"",SUM('Model inputs'!B324,'Model inputs'!B325,'Model inputs'!B326,'Model inputs'!B327,'Model inputs'!B328)) -> 55 | M6: =IF(SUM(IF(IF('Model inputs'!B329="",0,1)="",0,IF('Model inputs'!B329="",0,1)),IF(IF('Model inputs'!B330="",0,1)="",0,IF('Model inputs'!B330="",0,1)),IF(IF('Model inputs'!B331="",0,1)="",0,IF('Model inputs'!B331="",0,1)),IF(IF('Model inputs'!B332="",0,1)="",0,IF('Model inputs'!B332="",0,1)),IF(IF('Model inputs'!B333="",0,1)="",0,IF('Model inputs'!B333="",0,1)))=0,"",SUM('Model inputs'!B329,'Model inputs'!B330,'Model inputs'!B331,'Model inputs'!B332,'Model inputs'!B333)) -> 60
A7: Plan Earned revenue | B7: =IF(SUM(IF(IF('Model inputs'!B334="",0,1)="",0,IF('Model inputs'!B334="",0,1)),IF(IF('Model inputs'!B335="",0,1)="",0,IF('Model inputs'!B335="",0,1)),IF(IF('Model inputs'!B336="",0,1)="",0,IF('Model inputs'!B336="",0,1)),IF(IF('Model inputs'!B337="",0,1)="",0,IF('Model inputs'!B337="",0,1)),IF(IF('Model inputs'!B338="",0,1)="",0,IF('Model inputs'!B338="",0,1)))=0,"",SUM('Model inputs'!B334,'Model inputs'!B335,'Model inputs'!B336,'Model inputs'!B337,'Model inputs'!B338)) -> 5000 | C7: =IF(SUM(IF(IF('Model inputs'!B339="",0,1)="",0,IF('Model inputs'!B339="",0,1)),IF(IF('Model inputs'!B340="",0,1)="",0,IF('Model inputs'!B340="",0,1)),IF(IF('Model inputs'!B341="",0,1)="",0,IF('Model inputs'!B341="",0,1)),IF(IF('Model inputs'!B342="",0,1)="",0,IF('Model inputs'!B342="",0,1)),IF(IF('Model inputs'!B343="",0,1)="",0,IF('Model inputs'!B343="",0,1)))=0,"",SUM('Model inputs'!B339,'Model inputs'!B340,'Model inputs'!B341,'Model inputs'!B342,'Model inputs'!B343)) -> 10000 | D7: =IF(SUM(IF(IF('Model inputs'!B344="",0,1)="",0,IF('Model inputs'!B344="",0,1)),IF(IF('Model inputs'!B345="",0,1)="",0,IF('Model inputs'!B345="",0,1)),IF(IF('Model inputs'!B346="",0,1)="",0,IF('Model inputs'!B346="",0,1)),IF(IF('Model inputs'!B347="",0,1)="",0,IF('Model inputs'!B347="",0,1)),IF(IF('Model inputs'!B348="",0,1)="",0,IF('Model inputs'!B348="",0,1)))=0,"",SUM('Model inputs'!B344,'Model inputs'!B345,'Model inputs'!B346,'Model inputs'!B347,'Model inputs'!B348)) -> 15000 | E7: =IF(SUM(IF(IF('Model inputs'!B349="",0,1)="",0,IF('Model inputs'!B349="",0,1)),IF(IF('Model inputs'!B350="",0,1)="",0,IF('Model inputs'!B350="",0,1)),IF(IF('Model inputs'!B351="",0,1)="",0,IF('Model inputs'!B351="",0,1)),IF(IF('Model inputs'!B352="",0,1)="",0,IF('Model inputs'!B352="",0,1)),IF(IF('Model inputs'!B353="",0,1)="",0,IF('Model inputs'!B353="",0,1)))=0,"",SUM('Model inputs'!B349,'Model inputs'!B350,'Model inputs'!B351,'Model inputs'!B352,'Model inputs'!B353)) -> 20000 | F7: =IF(SUM(IF(IF('Model inputs'!B354="",0,1)="",0,IF('Model inputs'!B354="",0,1)),IF(IF('Model inputs'!B355="",0,1)="",0,IF('Model inputs'!B355="",0,1)),IF(IF('Model inputs'!B356="",0,1)="",0,IF('Model inputs'!B356="",0,1)),IF(IF('Model inputs'!B357="",0,1)="",0,IF('Model inputs'!B357="",0,1)),IF(IF('Model inputs'!B358="",0,1)="",0,IF('Model inputs'!B358="",0,1)))=0,"",SUM('Model inputs'!B354,'Model inputs'!B355,'Model inputs'!B356,'Model inputs'!B357,'Model inputs'!B358)) -> 25000 | G7: =IF(SUM(IF(IF('Model inputs'!B359="",0,1)="",0,IF('Model inputs'!B359="",0,1)),IF(IF('Model inputs'!B360="",0,1)="",0,IF('Model inputs'!B360="",0,1)),IF(IF('Model inputs'!B361="",0,1)="",0,IF('Model inputs'!B361="",0,1)),IF(IF('Model inputs'!B362="",0,1)="",0,IF('Model inputs'!B362="",0,1)),IF(IF('Model inputs'!B363="",0,1)="",0,IF('Model inputs'!B363="",0,1)))=0,"",SUM('Model inputs'!B359,'Model inputs'!B360,'Model inputs'!B361,'Model inputs'!B362,'Model inputs'!B363)) -> 30000 | H7: =IF(SUM(IF(IF('Model inputs'!B364="",0,1)="",0,IF('Model inputs'!B364="",0,1)),IF(IF('Model inputs'!B365="",0,1)="",0,IF('Model inputs'!B365="",0,1)),IF(IF('Model inputs'!B366="",0,1)="",0,IF('Model inputs'!B366="",0,1)),IF(IF('Model inputs'!B367="",0,1)="",0,IF('Model inputs'!B367="",0,1)),IF(IF('Model inputs'!B368="",0,1)="",0,IF('Model inputs'!B368="",0,1)))=0,"",SUM('Model inputs'!B364,'Model inputs'!B365,'Model inputs'!B366,'Model inputs'!B367,'Model inputs'!B368)) -> 35000 | I7: =IF(SUM(IF(IF('Model inputs'!B369="",0,1)="",0,IF('Model inputs'!B369="",0,1)),IF(IF('Model inputs'!B370="",0,1)="",0,IF('Model inputs'!B370="",0,1)),IF(IF('Model inputs'!B371="",0,1)="",0,IF('Model inputs'!B371="",0,1)),IF(IF('Model inputs'!B372="",0,1)="",0,IF('Model inputs'!B372="",0,1)),IF(IF('Model inputs'!B373="",0,1)="",0,IF('Model inputs'!B373="",0,1)))=0,"",SUM('Model inputs'!B369,'Model inputs'!B370,'Model inputs'!B371,'Model inputs'!B372,'Model inputs'!B373)) -> 40000 | J7: =IF(SUM(IF(IF('Model inputs'!B374="",0,1)="",0,IF('Model inputs'!B374="",0,1)),IF(IF('Model inputs'!B375="",0,1)="",0,IF('Model inputs'!B375="",0,1)),IF(IF('Model inputs'!B376="",0,1)="",0,IF('Model inputs'!B376="",0,1)),IF(IF('Model inputs'!B377="",0,1)="",0,IF('Model inputs'!B377="",0,1)),IF(IF('Model inputs'!B378="",0,1)="",0,IF('Model inputs'!B378="",0,1)))=0,"",SUM('Model inputs'!B374,'Model inputs'!B375,'Model inputs'!B376,'Model inputs'!B377,'Model inputs'!B378)) -> 45000 | K7: =IF(SUM(IF(IF('Model inputs'!B379="",0,1)="",0,IF('Model inputs'!B379="",0,1)),IF(IF('Model inputs'!B380="",0,1)="",0,IF('Model inputs'!B380="",0,1)),IF(IF('Model inputs'!B381="",0,1)="",0,IF('Model inputs'!B381="",0,1)),IF(IF('Model inputs'!B382="",0,1)="",0,IF('Model inputs'!B382="",0,1)),IF(IF('Model inputs'!B383="",0,1)="",0,IF('Model inputs'!B383="",0,1)))=0,"",SUM('Model inputs'!B379,'Model inputs'!B380,'Model inputs'!B381,'Model inputs'!B382,'Model inputs'!B383)) -> 50000 | L7: =IF(SUM(IF(IF('Model inputs'!B384="",0,1)="",0,IF('Model inputs'!B384="",0,1)),IF(IF('Model inputs'!B385="",0,1)="",0,IF('Model inputs'!B385="",0,1)),IF(IF('Model inputs'!B386="",0,1)="",0,IF('Model inputs'!B386="",0,1)),IF(IF('Model inputs'!B387="",0,1)="",0,IF('Model inputs'!B387="",0,1)),IF(IF('Model inputs'!B388="",0,1)="",0,IF('Model inputs'!B388="",0,1)))=0,"",SUM('Model inputs'!B384,'Model inputs'!B385,'Model inputs'!B386,'Model inputs'!B387,'Model inputs'!B388)) -> 55000 | M7: =IF(SUM(IF(IF('Model inputs'!B389="",0,1)="",0,IF('Model inputs'!B389="",0,1)),IF(IF('Model inputs'!B390="",0,1)="",0,IF('Model inputs'!B390="",0,1)),IF(IF('Model inputs'!B391="",0,1)="",0,IF('Model inputs'!B391="",0,1)),IF(IF('Model inputs'!B392="",0,1)="",0,IF('Model inputs'!B392="",0,1)),IF(IF('Model inputs'!B393="",0,1)="",0,IF('Model inputs'!B393="",0,1)))=0,"",SUM('Model inputs'!B389,'Model inputs'!B390,'Model inputs'!B391,'Model inputs'!B392,'Model inputs'!B393)) -> 60000
A8: Plan Delivery COGS | B8: =IF(SUM(IF(IF('Model inputs'!B394="",0,1)="",0,IF('Model inputs'!B394="",0,1)),IF(IF('Model inputs'!B395="",0,1)="",0,IF('Model inputs'!B395="",0,1)),IF(IF('Model inputs'!B396="",0,1)="",0,IF('Model inputs'!B396="",0,1)),IF(IF('Model inputs'!B397="",0,1)="",0,IF('Model inputs'!B397="",0,1)),IF(IF('Model inputs'!B398="",0,1)="",0,IF('Model inputs'!B398="",0,1)))=0,"",SUM('Model inputs'!B394,'Model inputs'!B395,'Model inputs'!B396,'Model inputs'!B397,'Model inputs'!B398)) -> 473.25 | C8: =IF(SUM(IF(IF('Model inputs'!B399="",0,1)="",0,IF('Model inputs'!B399="",0,1)),IF(IF('Model inputs'!B400="",0,1)="",0,IF('Model inputs'!B400="",0,1)),IF(IF('Model inputs'!B401="",0,1)="",0,IF('Model inputs'!B401="",0,1)),IF(IF('Model inputs'!B402="",0,1)="",0,IF('Model inputs'!B402="",0,1)),IF(IF('Model inputs'!B403="",0,1)="",0,IF('Model inputs'!B403="",0,1)))=0,"",SUM('Model inputs'!B399,'Model inputs'!B400,'Model inputs'!B401,'Model inputs'!B402,'Model inputs'!B403)) -> 946.5 | D8: =IF(SUM(IF(IF('Model inputs'!B404="",0,1)="",0,IF('Model inputs'!B404="",0,1)),IF(IF('Model inputs'!B405="",0,1)="",0,IF('Model inputs'!B405="",0,1)),IF(IF('Model inputs'!B406="",0,1)="",0,IF('Model inputs'!B406="",0,1)),IF(IF('Model inputs'!B407="",0,1)="",0,IF('Model inputs'!B407="",0,1)),IF(IF('Model inputs'!B408="",0,1)="",0,IF('Model inputs'!B408="",0,1)))=0,"",SUM('Model inputs'!B404,'Model inputs'!B405,'Model inputs'!B406,'Model inputs'!B407,'Model inputs'!B408)) -> 1419.75 | E8: =IF(SUM(IF(IF('Model inputs'!B409="",0,1)="",0,IF('Model inputs'!B409="",0,1)),IF(IF('Model inputs'!B410="",0,1)="",0,IF('Model inputs'!B410="",0,1)),IF(IF('Model inputs'!B411="",0,1)="",0,IF('Model inputs'!B411="",0,1)),IF(IF('Model inputs'!B412="",0,1)="",0,IF('Model inputs'!B412="",0,1)),IF(IF('Model inputs'!B413="",0,1)="",0,IF('Model inputs'!B413="",0,1)))=0,"",SUM('Model inputs'!B409,'Model inputs'!B410,'Model inputs'!B411,'Model inputs'!B412,'Model inputs'!B413)) -> 1893 | F8: =IF(SUM(IF(IF('Model inputs'!B414="",0,1)="",0,IF('Model inputs'!B414="",0,1)),IF(IF('Model inputs'!B415="",0,1)="",0,IF('Model inputs'!B415="",0,1)),IF(IF('Model inputs'!B416="",0,1)="",0,IF('Model inputs'!B416="",0,1)),IF(IF('Model inputs'!B417="",0,1)="",0,IF('Model inputs'!B417="",0,1)),IF(IF('Model inputs'!B418="",0,1)="",0,IF('Model inputs'!B418="",0,1)))=0,"",SUM('Model inputs'!B414,'Model inputs'!B415,'Model inputs'!B416,'Model inputs'!B417,'Model inputs'!B418)) -> 2366.25 | G8: =IF(SUM(IF(IF('Model inputs'!B419="",0,1)="",0,IF('Model inputs'!B419="",0,1)),IF(IF('Model inputs'!B420="",0,1)="",0,IF('Model inputs'!B420="",0,1)),IF(IF('Model inputs'!B421="",0,1)="",0,IF('Model inputs'!B421="",0,1)),IF(IF('Model inputs'!B422="",0,1)="",0,IF('Model inputs'!B422="",0,1)),IF(IF('Model inputs'!B423="",0,1)="",0,IF('Model inputs'!B423="",0,1)))=0,"",SUM('Model inputs'!B419,'Model inputs'!B420,'Model inputs'!B421,'Model inputs'!B422,'Model inputs'!B423)) -> 2839.5 | H8: =IF(SUM(IF(IF('Model inputs'!B424="",0,1)="",0,IF('Model inputs'!B424="",0,1)),IF(IF('Model inputs'!B425="",0,1)="",0,IF('Model inputs'!B425="",0,1)),IF(IF('Model inputs'!B426="",0,1)="",0,IF('Model inputs'!B426="",0,1)),IF(IF('Model inputs'!B427="",0,1)="",0,IF('Model inputs'!B427="",0,1)),IF(IF('Model inputs'!B428="",0,1)="",0,IF('Model inputs'!B428="",0,1)))=0,"",SUM('Model inputs'!B424,'Model inputs'!B425,'Model inputs'!B426,'Model inputs'!B427,'Model inputs'!B428)) -> 3312.75 | I8: =IF(SUM(IF(IF('Model inputs'!B429="",0,1)="",0,IF('Model inputs'!B429="",0,1)),IF(IF('Model inputs'!B430="",0,1)="",0,IF('Model inputs'!B430="",0,1)),IF(IF('Model inputs'!B431="",0,1)="",0,IF('Model inputs'!B431="",0,1)),IF(IF('Model inputs'!B432="",0,1)="",0,IF('Model inputs'!B432="",0,1)),IF(IF('Model inputs'!B433="",0,1)="",0,IF('Model inputs'!B433="",0,1)))=0,"",SUM('Model inputs'!B429,'Model inputs'!B430,'Model inputs'!B431,'Model inputs'!B432,'Model inputs'!B433)) -> 3786 | J8: =IF(SUM(IF(IF('Model inputs'!B434="",0,1)="",0,IF('Model inputs'!B434="",0,1)),IF(IF('Model inputs'!B435="",0,1)="",0,IF('Model inputs'!B435="",0,1)),IF(IF('Model inputs'!B436="",0,1)="",0,IF('Model inputs'!B436="",0,1)),IF(IF('Model inputs'!B437="",0,1)="",0,IF('Model inputs'!B437="",0,1)),IF(IF('Model inputs'!B438="",0,1)="",0,IF('Model inputs'!B438="",0,1)))=0,"",SUM('Model inputs'!B434,'Model inputs'!B435,'Model inputs'!B436,'Model inputs'!B437,'Model inputs'!B438)) -> 4259.25 | K8: =IF(SUM(IF(IF('Model inputs'!B439="",0,1)="",0,IF('Model inputs'!B439="",0,1)),IF(IF('Model inputs'!B440="",0,1)="",0,IF('Model inputs'!B440="",0,1)),IF(IF('Model inputs'!B441="",0,1)="",0,IF('Model inputs'!B441="",0,1)),IF(IF('Model inputs'!B442="",0,1)="",0,IF('Model inputs'!B442="",0,1)),IF(IF('Model inputs'!B443="",0,1)="",0,IF('Model inputs'!B443="",0,1)))=0,"",SUM('Model inputs'!B439,'Model inputs'!B440,'Model inputs'!B441,'Model inputs'!B442,'Model inputs'!B443)) -> 4732.5 | L8: =IF(SUM(IF(IF('Model inputs'!B444="",0,1)="",0,IF('Model inputs'!B444="",0,1)),IF(IF('Model inputs'!B445="",0,1)="",0,IF('Model inputs'!B445="",0,1)),IF(IF('Model inputs'!B446="",0,1)="",0,IF('Model inputs'!B446="",0,1)),IF(IF('Model inputs'!B447="",0,1)="",0,IF('Model inputs'!B447="",0,1)),IF(IF('Model inputs'!B448="",0,1)="",0,IF('Model inputs'!B448="",0,1)))=0,"",SUM('Model inputs'!B444,'Model inputs'!B445,'Model inputs'!B446,'Model inputs'!B447,'Model inputs'!B448)) -> 5205.75 | M8: =IF(SUM(IF(IF('Model inputs'!B449="",0,1)="",0,IF('Model inputs'!B449="",0,1)),IF(IF('Model inputs'!B450="",0,1)="",0,IF('Model inputs'!B450="",0,1)),IF(IF('Model inputs'!B451="",0,1)="",0,IF('Model inputs'!B451="",0,1)),IF(IF('Model inputs'!B452="",0,1)="",0,IF('Model inputs'!B452="",0,1)),IF(IF('Model inputs'!B453="",0,1)="",0,IF('Model inputs'!B453="",0,1)))=0,"",SUM('Model inputs'!B449,'Model inputs'!B450,'Model inputs'!B451,'Model inputs'!B452,'Model inputs'!B453)) -> 5679
A9: Plan Gross profit | B9: =IF(SUM(IF(IF('Model inputs'!B454="",0,1)="",0,IF('Model inputs'!B454="",0,1)),IF(IF('Model inputs'!B455="",0,1)="",0,IF('Model inputs'!B455="",0,1)),IF(IF('Model inputs'!B456="",0,1)="",0,IF('Model inputs'!B456="",0,1)),IF(IF('Model inputs'!B457="",0,1)="",0,IF('Model inputs'!B457="",0,1)),IF(IF('Model inputs'!B458="",0,1)="",0,IF('Model inputs'!B458="",0,1)))=0,"",SUM('Model inputs'!B454,'Model inputs'!B455,'Model inputs'!B456,'Model inputs'!B457,'Model inputs'!B458)) -> 4526.75 | C9: =IF(SUM(IF(IF('Model inputs'!B459="",0,1)="",0,IF('Model inputs'!B459="",0,1)),IF(IF('Model inputs'!B460="",0,1)="",0,IF('Model inputs'!B460="",0,1)),IF(IF('Model inputs'!B461="",0,1)="",0,IF('Model inputs'!B461="",0,1)),IF(IF('Model inputs'!B462="",0,1)="",0,IF('Model inputs'!B462="",0,1)),IF(IF('Model inputs'!B463="",0,1)="",0,IF('Model inputs'!B463="",0,1)))=0,"",SUM('Model inputs'!B459,'Model inputs'!B460,'Model inputs'!B461,'Model inputs'!B462,'Model inputs'!B463)) -> 9053.5 | D9: =IF(SUM(IF(IF('Model inputs'!B464="",0,1)="",0,IF('Model inputs'!B464="",0,1)),IF(IF('Model inputs'!B465="",0,1)="",0,IF('Model inputs'!B465="",0,1)),IF(IF('Model inputs'!B466="",0,1)="",0,IF('Model inputs'!B466="",0,1)),IF(IF('Model inputs'!B467="",0,1)="",0,IF('Model inputs'!B467="",0,1)),IF(IF('Model inputs'!B468="",0,1)="",0,IF('Model inputs'!B468="",0,1)))=0,"",SUM('Model inputs'!B464,'Model inputs'!B465,'Model inputs'!B466,'Model inputs'!B467,'Model inputs'!B468)) -> 13580.25 | E9: =IF(SUM(IF(IF('Model inputs'!B469="",0,1)="",0,IF('Model inputs'!B469="",0,1)),IF(IF('Model inputs'!B470="",0,1)="",0,IF('Model inputs'!B470="",0,1)),IF(IF('Model inputs'!B471="",0,1)="",0,IF('Model inputs'!B471="",0,1)),IF(IF('Model inputs'!B472="",0,1)="",0,IF('Model inputs'!B472="",0,1)),IF(IF('Model inputs'!B473="",0,1)="",0,IF('Model inputs'!B473="",0,1)))=0,"",SUM('Model inputs'!B469,'Model inputs'!B470,'Model inputs'!B471,'Model inputs'!B472,'Model inputs'!B473)) -> 18107 | F9: =IF(SUM(IF(IF('Model inputs'!B474="",0,1)="",0,IF('Model inputs'!B474="",0,1)),IF(IF('Model inputs'!B475="",0,1)="",0,IF('Model inputs'!B475="",0,1)),IF(IF('Model inputs'!B476="",0,1)="",0,IF('Model inputs'!B476="",0,1)),IF(IF('Model inputs'!B477="",0,1)="",0,IF('Model inputs'!B477="",0,1)),IF(IF('Model inputs'!B478="",0,1)="",0,IF('Model inputs'!B478="",0,1)))=0,"",SUM('Model inputs'!B474,'Model inputs'!B475,'Model inputs'!B476,'Model inputs'!B477,'Model inputs'!B478)) -> 22633.75 | G9: =IF(SUM(IF(IF('Model inputs'!B479="",0,1)="",0,IF('Model inputs'!B479="",0,1)),IF(IF('Model inputs'!B480="",0,1)="",0,IF('Model inputs'!B480="",0,1)),IF(IF('Model inputs'!B481="",0,1)="",0,IF('Model inputs'!B481="",0,1)),IF(IF('Model inputs'!B482="",0,1)="",0,IF('Model inputs'!B482="",0,1)),IF(IF('Model inputs'!B483="",0,1)="",0,IF('Model inputs'!B483="",0,1)))=0,"",SUM('Model inputs'!B479,'Model inputs'!B480,'Model inputs'!B481,'Model inputs'!B482,'Model inputs'!B483)) -> 27160.5 | H9: =IF(SUM(IF(IF('Model inputs'!B484="",0,1)="",0,IF('Model inputs'!B484="",0,1)),IF(IF('Model inputs'!B485="",0,1)="",0,IF('Model inputs'!B485="",0,1)),IF(IF('Model inputs'!B486="",0,1)="",0,IF('Model inputs'!B486="",0,1)),IF(IF('Model inputs'!B487="",0,1)="",0,IF('Model inputs'!B487="",0,1)),IF(IF('Model inputs'!B488="",0,1)="",0,IF('Model inputs'!B488="",0,1)))=0,"",SUM('Model inputs'!B484,'Model inputs'!B485,'Model inputs'!B486,'Model inputs'!B487,'Model inputs'!B488)) -> 31687.25 | I9: =IF(SUM(IF(IF('Model inputs'!B489="",0,1)="",0,IF('Model inputs'!B489="",0,1)),IF(IF('Model inputs'!B490="",0,1)="",0,IF('Model inputs'!B490="",0,1)),IF(IF('Model inputs'!B491="",0,1)="",0,IF('Model inputs'!B491="",0,1)),IF(IF('Model inputs'!B492="",0,1)="",0,IF('Model inputs'!B492="",0,1)),IF(IF('Model inputs'!B493="",0,1)="",0,IF('Model inputs'!B493="",0,1)))=0,"",SUM('Model inputs'!B489,'Model inputs'!B490,'Model inputs'!B491,'Model inputs'!B492,'Model inputs'!B493)) -> 36214 | J9: =IF(SUM(IF(IF('Model inputs'!B494="",0,1)="",0,IF('Model inputs'!B494="",0,1)),IF(IF('Model inputs'!B495="",0,1)="",0,IF('Model inputs'!B495="",0,1)),IF(IF('Model inputs'!B496="",0,1)="",0,IF('Model inputs'!B496="",0,1)),IF(IF('Model inputs'!B497="",0,1)="",0,IF('Model inputs'!B497="",0,1)),IF(IF('Model inputs'!B498="",0,1)="",0,IF('Model inputs'!B498="",0,1)))=0,"",SUM('Model inputs'!B494,'Model inputs'!B495,'Model inputs'!B496,'Model inputs'!B497,'Model inputs'!B498)) -> 40740.75 | K9: =IF(SUM(IF(IF('Model inputs'!B499="",0,1)="",0,IF('Model inputs'!B499="",0,1)),IF(IF('Model inputs'!B500="",0,1)="",0,IF('Model inputs'!B500="",0,1)),IF(IF('Model inputs'!B501="",0,1)="",0,IF('Model inputs'!B501="",0,1)),IF(IF('Model inputs'!B502="",0,1)="",0,IF('Model inputs'!B502="",0,1)),IF(IF('Model inputs'!B503="",0,1)="",0,IF('Model inputs'!B503="",0,1)))=0,"",SUM('Model inputs'!B499,'Model inputs'!B500,'Model inputs'!B501,'Model inputs'!B502,'Model inputs'!B503)) -> 45267.5 | L9: =IF(SUM(IF(IF('Model inputs'!B504="",0,1)="",0,IF('Model inputs'!B504="",0,1)),IF(IF('Model inputs'!B505="",0,1)="",0,IF('Model inputs'!B505="",0,1)),IF(IF('Model inputs'!B506="",0,1)="",0,IF('Model inputs'!B506="",0,1)),IF(IF('Model inputs'!B507="",0,1)="",0,IF('Model inputs'!B507="",0,1)),IF(IF('Model inputs'!B508="",0,1)="",0,IF('Model inputs'!B508="",0,1)))=0,"",SUM('Model inputs'!B504,'Model inputs'!B505,'Model inputs'!B506,'Model inputs'!B507,'Model inputs'!B508)) -> 49794.25 | M9: =IF(SUM(IF(IF('Model inputs'!B509="",0,1)="",0,IF('Model inputs'!B509="",0,1)),IF(IF('Model inputs'!B510="",0,1)="",0,IF('Model inputs'!B510="",0,1)),IF(IF('Model inputs'!B511="",0,1)="",0,IF('Model inputs'!B511="",0,1)),IF(IF('Model inputs'!B512="",0,1)="",0,IF('Model inputs'!B512="",0,1)),IF(IF('Model inputs'!B513="",0,1)="",0,IF('Model inputs'!B513="",0,1)))=0,"",SUM('Model inputs'!B509,'Model inputs'!B510,'Model inputs'!B511,'Model inputs'!B512,'Model inputs'!B513)) -> 54321
A10: Plan Gross margin by pricing | B10: =IF(SUM(IF(IF('Model inputs'!B514="",0,1)="",0,IF('Model inputs'!B514="",0,1)),IF(IF('Model inputs'!B515="",0,1)="",0,IF('Model inputs'!B515="",0,1)),IF(IF('Model inputs'!B516="",0,1)="",0,IF('Model inputs'!B516="",0,1)),IF(IF('Model inputs'!B517="",0,1)="",0,IF('Model inputs'!B517="",0,1)),IF(IF('Model inputs'!B518="",0,1)="",0,IF('Model inputs'!B518="",0,1)))=0,"",SUM('Model inputs'!B514,'Model inputs'!B515,'Model inputs'!B516,'Model inputs'!B517,'Model inputs'!B518)) -> 0.90535 | C10: =IF(SUM(IF(IF('Model inputs'!B519="",0,1)="",0,IF('Model inputs'!B519="",0,1)),IF(IF('Model inputs'!B520="",0,1)="",0,IF('Model inputs'!B520="",0,1)),IF(IF('Model inputs'!B521="",0,1)="",0,IF('Model inputs'!B521="",0,1)),IF(IF('Model inputs'!B522="",0,1)="",0,IF('Model inputs'!B522="",0,1)),IF(IF('Model inputs'!B523="",0,1)="",0,IF('Model inputs'!B523="",0,1)))=0,"",SUM('Model inputs'!B519,'Model inputs'!B520,'Model inputs'!B521,'Model inputs'!B522,'Model inputs'!B523)) -> 0.90535 | D10: =IF(SUM(IF(IF('Model inputs'!B524="",0,1)="",0,IF('Model inputs'!B524="",0,1)),IF(IF('Model inputs'!B525="",0,1)="",0,IF('Model inputs'!B525="",0,1)),IF(IF('Model inputs'!B526="",0,1)="",0,IF('Model inputs'!B526="",0,1)),IF(IF('Model inputs'!B527="",0,1)="",0,IF('Model inputs'!B527="",0,1)),IF(IF('Model inputs'!B528="",0,1)="",0,IF('Model inputs'!B528="",0,1)))=0,"",SUM('Model inputs'!B524,'Model inputs'!B525,'Model inputs'!B526,'Model inputs'!B527,'Model inputs'!B528)) -> 0.90535 | E10: =IF(SUM(IF(IF('Model inputs'!B529="",0,1)="",0,IF('Model inputs'!B529="",0,1)),IF(IF('Model inputs'!B530="",0,1)="",0,IF('Model inputs'!B530="",0,1)),IF(IF('Model inputs'!B531="",0,1)="",0,IF('Model inputs'!B531="",0,1)),IF(IF('Model inputs'!B532="",0,1)="",0,IF('Model inputs'!B532="",0,1)),IF(IF('Model inputs'!B533="",0,1)="",0,IF('Model inputs'!B533="",0,1)))=0,"",SUM('Model inputs'!B529,'Model inputs'!B530,'Model inputs'!B531,'Model inputs'!B532,'Model inputs'!B533)) -> 0.90535 | F10: =IF(SUM(IF(IF('Model inputs'!B534="",0,1)="",0,IF('Model inputs'!B534="",0,1)),IF(IF('Model inputs'!B535="",0,1)="",0,IF('Model inputs'!B535="",0,1)),IF(IF('Model inputs'!B536="",0,1)="",0,IF('Model inputs'!B536="",0,1)),IF(IF('Model inputs'!B537="",0,1)="",0,IF('Model inputs'!B537="",0,1)),IF(IF('Model inputs'!B538="",0,1)="",0,IF('Model inputs'!B538="",0,1)))=0,"",SUM('Model inputs'!B534,'Model inputs'!B535,'Model inputs'!B536,'Model inputs'!B537,'Model inputs'!B538)) -> 0.90535 | G10: =IF(SUM(IF(IF('Model inputs'!B539="",0,1)="",0,IF('Model inputs'!B539="",0,1)),IF(IF('Model inputs'!B540="",0,1)="",0,IF('Model inputs'!B540="",0,1)),IF(IF('Model inputs'!B541="",0,1)="",0,IF('Model inputs'!B541="",0,1)),IF(IF('Model inputs'!B542="",0,1)="",0,IF('Model inputs'!B542="",0,1)),IF(IF('Model inputs'!B543="",0,1)="",0,IF('Model inputs'!B543="",0,1)))=0,"",SUM('Model inputs'!B539,'Model inputs'!B540,'Model inputs'!B541,'Model inputs'!B542,'Model inputs'!B543)) -> 0.90535 | H10: =IF(SUM(IF(IF('Model inputs'!B544="",0,1)="",0,IF('Model inputs'!B544="",0,1)),IF(IF('Model inputs'!B545="",0,1)="",0,IF('Model inputs'!B545="",0,1)),IF(IF('Model inputs'!B546="",0,1)="",0,IF('Model inputs'!B546="",0,1)),IF(IF('Model inputs'!B547="",0,1)="",0,IF('Model inputs'!B547="",0,1)),IF(IF('Model inputs'!B548="",0,1)="",0,IF('Model inputs'!B548="",0,1)))=0,"",SUM('Model inputs'!B544,'Model inputs'!B545,'Model inputs'!B546,'Model inputs'!B547,'Model inputs'!B548)) -> 0.90535 | I10: =IF(SUM(IF(IF('Model inputs'!B549="",0,1)="",0,IF('Model inputs'!B549="",0,1)),IF(IF('Model inputs'!B550="",0,1)="",0,IF('Model inputs'!B550="",0,1)),IF(IF('Model inputs'!B551="",0,1)="",0,IF('Model inputs'!B551="",0,1)),IF(IF('Model inputs'!B552="",0,1)="",0,IF('Model inputs'!B552="",0,1)),IF(IF('Model inputs'!B553="",0,1)="",0,IF('Model inputs'!B553="",0,1)))=0,"",SUM('Model inputs'!B549,'Model inputs'!B550,'Model inputs'!B551,'Model inputs'!B552,'Model inputs'!B553)) -> 0.90535 | J10: =IF(SUM(IF(IF('Model inputs'!B554="",0,1)="",0,IF('Model inputs'!B554="",0,1)),IF(IF('Model inputs'!B555="",0,1)="",0,IF('Model inputs'!B555="",0,1)),IF(IF('Model inputs'!B556="",0,1)="",0,IF('Model inputs'!B556="",0,1)),IF(IF('Model inputs'!B557="",0,1)="",0,IF('Model inputs'!B557="",0,1)),IF(IF('Model inputs'!B558="",0,1)="",0,IF('Model inputs'!B558="",0,1)))=0,"",SUM('Model inputs'!B554,'Model inputs'!B555,'Model inputs'!B556,'Model inputs'!B557,'Model inputs'!B558)) -> 0.90535 | K10: =IF(SUM(IF(IF('Model inputs'!B559="",0,1)="",0,IF('Model inputs'!B559="",0,1)),IF(IF('Model inputs'!B560="",0,1)="",0,IF('Model inputs'!B560="",0,1)),IF(IF('Model inputs'!B561="",0,1)="",0,IF('Model inputs'!B561="",0,1)),IF(IF('Model inputs'!B562="",0,1)="",0,IF('Model inputs'!B562="",0,1)),IF(IF('Model inputs'!B563="",0,1)="",0,IF('Model inputs'!B563="",0,1)))=0,"",SUM('Model inputs'!B559,'Model inputs'!B560,'Model inputs'!B561,'Model inputs'!B562,'Model inputs'!B563)) -> 0.90535 | L10: =IF(SUM(IF(IF('Model inputs'!B564="",0,1)="",0,IF('Model inputs'!B564="",0,1)),IF(IF('Model inputs'!B565="",0,1)="",0,IF('Model inputs'!B565="",0,1)),IF(IF('Model inputs'!B566="",0,1)="",0,IF('Model inputs'!B566="",0,1)),IF(IF('Model inputs'!B567="",0,1)="",0,IF('Model inputs'!B567="",0,1)),IF(IF('Model inputs'!B568="",0,1)="",0,IF('Model inputs'!B568="",0,1)))=0,"",SUM('Model inputs'!B564,'Model inputs'!B565,'Model inputs'!B566,'Model inputs'!B567,'Model inputs'!B568)) -> 0.90535 | M10: =IF(SUM(IF(IF('Model inputs'!B569="",0,1)="",0,IF('Model inputs'!B569="",0,1)),IF(IF('Model inputs'!B570="",0,1)="",0,IF('Model inputs'!B570="",0,1)),IF(IF('Model inputs'!B571="",0,1)="",0,IF('Model inputs'!B571="",0,1)),IF(IF('Model inputs'!B572="",0,1)="",0,IF('Model inputs'!B572="",0,1)),IF(IF('Model inputs'!B573="",0,1)="",0,IF('Model inputs'!B573="",0,1)))=0,"",SUM('Model inputs'!B569,'Model inputs'!B570,'Model inputs'!B571,'Model inputs'!B572,'Model inputs'!B573)) -> 0.90535
A11: Plan Account support cost | B11: =IF(SUM(IF(IF('Model inputs'!B574="",0,1)="",0,IF('Model inputs'!B574="",0,1)),IF(IF('Model inputs'!B575="",0,1)="",0,IF('Model inputs'!B575="",0,1)),IF(IF('Model inputs'!B576="",0,1)="",0,IF('Model inputs'!B576="",0,1)),IF(IF('Model inputs'!B577="",0,1)="",0,IF('Model inputs'!B577="",0,1)),IF(IF('Model inputs'!B578="",0,1)="",0,IF('Model inputs'!B578="",0,1)))=0,"",SUM('Model inputs'!B574,'Model inputs'!B575,'Model inputs'!B576,'Model inputs'!B577,'Model inputs'!B578)) -> 37.5 | C11: =IF(SUM(IF(IF('Model inputs'!B579="",0,1)="",0,IF('Model inputs'!B579="",0,1)),IF(IF('Model inputs'!B580="",0,1)="",0,IF('Model inputs'!B580="",0,1)),IF(IF('Model inputs'!B581="",0,1)="",0,IF('Model inputs'!B581="",0,1)),IF(IF('Model inputs'!B582="",0,1)="",0,IF('Model inputs'!B582="",0,1)),IF(IF('Model inputs'!B583="",0,1)="",0,IF('Model inputs'!B583="",0,1)))=0,"",SUM('Model inputs'!B579,'Model inputs'!B580,'Model inputs'!B581,'Model inputs'!B582,'Model inputs'!B583)) -> 75 | D11: =IF(SUM(IF(IF('Model inputs'!B584="",0,1)="",0,IF('Model inputs'!B584="",0,1)),IF(IF('Model inputs'!B585="",0,1)="",0,IF('Model inputs'!B585="",0,1)),IF(IF('Model inputs'!B586="",0,1)="",0,IF('Model inputs'!B586="",0,1)),IF(IF('Model inputs'!B587="",0,1)="",0,IF('Model inputs'!B587="",0,1)),IF(IF('Model inputs'!B588="",0,1)="",0,IF('Model inputs'!B588="",0,1)))=0,"",SUM('Model inputs'!B584,'Model inputs'!B585,'Model inputs'!B586,'Model inputs'!B587,'Model inputs'!B588)) -> 112.5 | E11: =IF(SUM(IF(IF('Model inputs'!B589="",0,1)="",0,IF('Model inputs'!B589="",0,1)),IF(IF('Model inputs'!B590="",0,1)="",0,IF('Model inputs'!B590="",0,1)),IF(IF('Model inputs'!B591="",0,1)="",0,IF('Model inputs'!B591="",0,1)),IF(IF('Model inputs'!B592="",0,1)="",0,IF('Model inputs'!B592="",0,1)),IF(IF('Model inputs'!B593="",0,1)="",0,IF('Model inputs'!B593="",0,1)))=0,"",SUM('Model inputs'!B589,'Model inputs'!B590,'Model inputs'!B591,'Model inputs'!B592,'Model inputs'!B593)) -> 150 | F11: =IF(SUM(IF(IF('Model inputs'!B594="",0,1)="",0,IF('Model inputs'!B594="",0,1)),IF(IF('Model inputs'!B595="",0,1)="",0,IF('Model inputs'!B595="",0,1)),IF(IF('Model inputs'!B596="",0,1)="",0,IF('Model inputs'!B596="",0,1)),IF(IF('Model inputs'!B597="",0,1)="",0,IF('Model inputs'!B597="",0,1)),IF(IF('Model inputs'!B598="",0,1)="",0,IF('Model inputs'!B598="",0,1)))=0,"",SUM('Model inputs'!B594,'Model inputs'!B595,'Model inputs'!B596,'Model inputs'!B597,'Model inputs'!B598)) -> 187.5 | G11: =IF(SUM(IF(IF('Model inputs'!B599="",0,1)="",0,IF('Model inputs'!B599="",0,1)),IF(IF('Model inputs'!B600="",0,1)="",0,IF('Model inputs'!B600="",0,1)),IF(IF('Model inputs'!B601="",0,1)="",0,IF('Model inputs'!B601="",0,1)),IF(IF('Model inputs'!B602="",0,1)="",0,IF('Model inputs'!B602="",0,1)),IF(IF('Model inputs'!B603="",0,1)="",0,IF('Model inputs'!B603="",0,1)))=0,"",SUM('Model inputs'!B599,'Model inputs'!B600,'Model inputs'!B601,'Model inputs'!B602,'Model inputs'!B603)) -> 225 | H11: =IF(SUM(IF(IF('Model inputs'!B604="",0,1)="",0,IF('Model inputs'!B604="",0,1)),IF(IF('Model inputs'!B605="",0,1)="",0,IF('Model inputs'!B605="",0,1)),IF(IF('Model inputs'!B606="",0,1)="",0,IF('Model inputs'!B606="",0,1)),IF(IF('Model inputs'!B607="",0,1)="",0,IF('Model inputs'!B607="",0,1)),IF(IF('Model inputs'!B608="",0,1)="",0,IF('Model inputs'!B608="",0,1)))=0,"",SUM('Model inputs'!B604,'Model inputs'!B605,'Model inputs'!B606,'Model inputs'!B607,'Model inputs'!B608)) -> 262.5 | I11: =IF(SUM(IF(IF('Model inputs'!B609="",0,1)="",0,IF('Model inputs'!B609="",0,1)),IF(IF('Model inputs'!B610="",0,1)="",0,IF('Model inputs'!B610="",0,1)),IF(IF('Model inputs'!B611="",0,1)="",0,IF('Model inputs'!B611="",0,1)),IF(IF('Model inputs'!B612="",0,1)="",0,IF('Model inputs'!B612="",0,1)),IF(IF('Model inputs'!B613="",0,1)="",0,IF('Model inputs'!B613="",0,1)))=0,"",SUM('Model inputs'!B609,'Model inputs'!B610,'Model inputs'!B611,'Model inputs'!B612,'Model inputs'!B613)) -> 300 | J11: =IF(SUM(IF(IF('Model inputs'!B614="",0,1)="",0,IF('Model inputs'!B614="",0,1)),IF(IF('Model inputs'!B615="",0,1)="",0,IF('Model inputs'!B615="",0,1)),IF(IF('Model inputs'!B616="",0,1)="",0,IF('Model inputs'!B616="",0,1)),IF(IF('Model inputs'!B617="",0,1)="",0,IF('Model inputs'!B617="",0,1)),IF(IF('Model inputs'!B618="",0,1)="",0,IF('Model inputs'!B618="",0,1)))=0,"",SUM('Model inputs'!B614,'Model inputs'!B615,'Model inputs'!B616,'Model inputs'!B617,'Model inputs'!B618)) -> 337.5 | K11: =IF(SUM(IF(IF('Model inputs'!B619="",0,1)="",0,IF('Model inputs'!B619="",0,1)),IF(IF('Model inputs'!B620="",0,1)="",0,IF('Model inputs'!B620="",0,1)),IF(IF('Model inputs'!B621="",0,1)="",0,IF('Model inputs'!B621="",0,1)),IF(IF('Model inputs'!B622="",0,1)="",0,IF('Model inputs'!B622="",0,1)),IF(IF('Model inputs'!B623="",0,1)="",0,IF('Model inputs'!B623="",0,1)))=0,"",SUM('Model inputs'!B619,'Model inputs'!B620,'Model inputs'!B621,'Model inputs'!B622,'Model inputs'!B623)) -> 375 | L11: =IF(SUM(IF(IF('Model inputs'!B624="",0,1)="",0,IF('Model inputs'!B624="",0,1)),IF(IF('Model inputs'!B625="",0,1)="",0,IF('Model inputs'!B625="",0,1)),IF(IF('Model inputs'!B626="",0,1)="",0,IF('Model inputs'!B626="",0,1)),IF(IF('Model inputs'!B627="",0,1)="",0,IF('Model inputs'!B627="",0,1)),IF(IF('Model inputs'!B628="",0,1)="",0,IF('Model inputs'!B628="",0,1)))=0,"",SUM('Model inputs'!B624,'Model inputs'!B625,'Model inputs'!B626,'Model inputs'!B627,'Model inputs'!B628)) -> 412.5 | M11: =IF(SUM(IF(IF('Model inputs'!B629="",0,1)="",0,IF('Model inputs'!B629="",0,1)),IF(IF('Model inputs'!B630="",0,1)="",0,IF('Model inputs'!B630="",0,1)),IF(IF('Model inputs'!B631="",0,1)="",0,IF('Model inputs'!B631="",0,1)),IF(IF('Model inputs'!B632="",0,1)="",0,IF('Model inputs'!B632="",0,1)),IF(IF('Model inputs'!B633="",0,1)="",0,IF('Model inputs'!B633="",0,1)))=0,"",SUM('Model inputs'!B629,'Model inputs'!B630,'Model inputs'!B631,'Model inputs'!B632,'Model inputs'!B633)) -> 450
A12: Plan Contribution profit | B12: =IF(SUM(IF(IF('Model inputs'!B634="",0,1)="",0,IF('Model inputs'!B634="",0,1)),IF(IF('Model inputs'!B635="",0,1)="",0,IF('Model inputs'!B635="",0,1)),IF(IF('Model inputs'!B636="",0,1)="",0,IF('Model inputs'!B636="",0,1)),IF(IF('Model inputs'!B637="",0,1)="",0,IF('Model inputs'!B637="",0,1)),IF(IF('Model inputs'!B638="",0,1)="",0,IF('Model inputs'!B638="",0,1)))=0,"",SUM('Model inputs'!B634,'Model inputs'!B635,'Model inputs'!B636,'Model inputs'!B637,'Model inputs'!B638)) -> 4339.25 | C12: =IF(SUM(IF(IF('Model inputs'!B639="",0,1)="",0,IF('Model inputs'!B639="",0,1)),IF(IF('Model inputs'!B640="",0,1)="",0,IF('Model inputs'!B640="",0,1)),IF(IF('Model inputs'!B641="",0,1)="",0,IF('Model inputs'!B641="",0,1)),IF(IF('Model inputs'!B642="",0,1)="",0,IF('Model inputs'!B642="",0,1)),IF(IF('Model inputs'!B643="",0,1)="",0,IF('Model inputs'!B643="",0,1)))=0,"",SUM('Model inputs'!B639,'Model inputs'!B640,'Model inputs'!B641,'Model inputs'!B642,'Model inputs'!B643)) -> 8678.5 | D12: =IF(SUM(IF(IF('Model inputs'!B644="",0,1)="",0,IF('Model inputs'!B644="",0,1)),IF(IF('Model inputs'!B645="",0,1)="",0,IF('Model inputs'!B645="",0,1)),IF(IF('Model inputs'!B646="",0,1)="",0,IF('Model inputs'!B646="",0,1)),IF(IF('Model inputs'!B647="",0,1)="",0,IF('Model inputs'!B647="",0,1)),IF(IF('Model inputs'!B648="",0,1)="",0,IF('Model inputs'!B648="",0,1)))=0,"",SUM('Model inputs'!B644,'Model inputs'!B645,'Model inputs'!B646,'Model inputs'!B647,'Model inputs'!B648)) -> 13017.75 | E12: =IF(SUM(IF(IF('Model inputs'!B649="",0,1)="",0,IF('Model inputs'!B649="",0,1)),IF(IF('Model inputs'!B650="",0,1)="",0,IF('Model inputs'!B650="",0,1)),IF(IF('Model inputs'!B651="",0,1)="",0,IF('Model inputs'!B651="",0,1)),IF(IF('Model inputs'!B652="",0,1)="",0,IF('Model inputs'!B652="",0,1)),IF(IF('Model inputs'!B653="",0,1)="",0,IF('Model inputs'!B653="",0,1)))=0,"",SUM('Model inputs'!B649,'Model inputs'!B650,'Model inputs'!B651,'Model inputs'!B652,'Model inputs'!B653)) -> 17357 | F12: =IF(SUM(IF(IF('Model inputs'!B654="",0,1)="",0,IF('Model inputs'!B654="",0,1)),IF(IF('Model inputs'!B655="",0,1)="",0,IF('Model inputs'!B655="",0,1)),IF(IF('Model inputs'!B656="",0,1)="",0,IF('Model inputs'!B656="",0,1)),IF(IF('Model inputs'!B657="",0,1)="",0,IF('Model inputs'!B657="",0,1)),IF(IF('Model inputs'!B658="",0,1)="",0,IF('Model inputs'!B658="",0,1)))=0,"",SUM('Model inputs'!B654,'Model inputs'!B655,'Model inputs'!B656,'Model inputs'!B657,'Model inputs'!B658)) -> 21696.25 | G12: =IF(SUM(IF(IF('Model inputs'!B659="",0,1)="",0,IF('Model inputs'!B659="",0,1)),IF(IF('Model inputs'!B660="",0,1)="",0,IF('Model inputs'!B660="",0,1)),IF(IF('Model inputs'!B661="",0,1)="",0,IF('Model inputs'!B661="",0,1)),IF(IF('Model inputs'!B662="",0,1)="",0,IF('Model inputs'!B662="",0,1)),IF(IF('Model inputs'!B663="",0,1)="",0,IF('Model inputs'!B663="",0,1)))=0,"",SUM('Model inputs'!B659,'Model inputs'!B660,'Model inputs'!B661,'Model inputs'!B662,'Model inputs'!B663)) -> 26035.5 | H12: =IF(SUM(IF(IF('Model inputs'!B664="",0,1)="",0,IF('Model inputs'!B664="",0,1)),IF(IF('Model inputs'!B665="",0,1)="",0,IF('Model inputs'!B665="",0,1)),IF(IF('Model inputs'!B666="",0,1)="",0,IF('Model inputs'!B666="",0,1)),IF(IF('Model inputs'!B667="",0,1)="",0,IF('Model inputs'!B667="",0,1)),IF(IF('Model inputs'!B668="",0,1)="",0,IF('Model inputs'!B668="",0,1)))=0,"",SUM('Model inputs'!B664,'Model inputs'!B665,'Model inputs'!B666,'Model inputs'!B667,'Model inputs'!B668)) -> 30374.75 | I12: =IF(SUM(IF(IF('Model inputs'!B669="",0,1)="",0,IF('Model inputs'!B669="",0,1)),IF(IF('Model inputs'!B670="",0,1)="",0,IF('Model inputs'!B670="",0,1)),IF(IF('Model inputs'!B671="",0,1)="",0,IF('Model inputs'!B671="",0,1)),IF(IF('Model inputs'!B672="",0,1)="",0,IF('Model inputs'!B672="",0,1)),IF(IF('Model inputs'!B673="",0,1)="",0,IF('Model inputs'!B673="",0,1)))=0,"",SUM('Model inputs'!B669,'Model inputs'!B670,'Model inputs'!B671,'Model inputs'!B672,'Model inputs'!B673)) -> 34714 | J12: =IF(SUM(IF(IF('Model inputs'!B674="",0,1)="",0,IF('Model inputs'!B674="",0,1)),IF(IF('Model inputs'!B675="",0,1)="",0,IF('Model inputs'!B675="",0,1)),IF(IF('Model inputs'!B676="",0,1)="",0,IF('Model inputs'!B676="",0,1)),IF(IF('Model inputs'!B677="",0,1)="",0,IF('Model inputs'!B677="",0,1)),IF(IF('Model inputs'!B678="",0,1)="",0,IF('Model inputs'!B678="",0,1)))=0,"",SUM('Model inputs'!B674,'Model inputs'!B675,'Model inputs'!B676,'Model inputs'!B677,'Model inputs'!B678)) -> 39053.25 | K12: =IF(SUM(IF(IF('Model inputs'!B679="",0,1)="",0,IF('Model inputs'!B679="",0,1)),IF(IF('Model inputs'!B680="",0,1)="",0,IF('Model inputs'!B680="",0,1)),IF(IF('Model inputs'!B681="",0,1)="",0,IF('Model inputs'!B681="",0,1)),IF(IF('Model inputs'!B682="",0,1)="",0,IF('Model inputs'!B682="",0,1)),IF(IF('Model inputs'!B683="",0,1)="",0,IF('Model inputs'!B683="",0,1)))=0,"",SUM('Model inputs'!B679,'Model inputs'!B680,'Model inputs'!B681,'Model inputs'!B682,'Model inputs'!B683)) -> 43392.5 | L12: =IF(SUM(IF(IF('Model inputs'!B684="",0,1)="",0,IF('Model inputs'!B684="",0,1)),IF(IF('Model inputs'!B685="",0,1)="",0,IF('Model inputs'!B685="",0,1)),IF(IF('Model inputs'!B686="",0,1)="",0,IF('Model inputs'!B686="",0,1)),IF(IF('Model inputs'!B687="",0,1)="",0,IF('Model inputs'!B687="",0,1)),IF(IF('Model inputs'!B688="",0,1)="",0,IF('Model inputs'!B688="",0,1)))=0,"",SUM('Model inputs'!B684,'Model inputs'!B685,'Model inputs'!B686,'Model inputs'!B687,'Model inputs'!B688)) -> 47731.75 | M12: =IF(SUM(IF(IF('Model inputs'!B689="",0,1)="",0,IF('Model inputs'!B689="",0,1)),IF(IF('Model inputs'!B690="",0,1)="",0,IF('Model inputs'!B690="",0,1)),IF(IF('Model inputs'!B691="",0,1)="",0,IF('Model inputs'!B691="",0,1)),IF(IF('Model inputs'!B692="",0,1)="",0,IF('Model inputs'!B692="",0,1)),IF(IF('Model inputs'!B693="",0,1)="",0,IF('Model inputs'!B693="",0,1)))=0,"",SUM('Model inputs'!B689,'Model inputs'!B690,'Model inputs'!B691,'Model inputs'!B692,'Model inputs'!B693)) -> 52071
A13: Plan Contribution margin by pricing | B13: =IF(SUM(IF(IF('Model inputs'!B694="",0,1)="",0,IF('Model inputs'!B694="",0,1)),IF(IF('Model inputs'!B695="",0,1)="",0,IF('Model inputs'!B695="",0,1)),IF(IF('Model inputs'!B696="",0,1)="",0,IF('Model inputs'!B696="",0,1)),IF(IF('Model inputs'!B697="",0,1)="",0,IF('Model inputs'!B697="",0,1)),IF(IF('Model inputs'!B698="",0,1)="",0,IF('Model inputs'!B698="",0,1)))=0,"",SUM('Model inputs'!B694,'Model inputs'!B695,'Model inputs'!B696,'Model inputs'!B697,'Model inputs'!B698)) -> 0.86785 | C13: =IF(SUM(IF(IF('Model inputs'!B699="",0,1)="",0,IF('Model inputs'!B699="",0,1)),IF(IF('Model inputs'!B700="",0,1)="",0,IF('Model inputs'!B700="",0,1)),IF(IF('Model inputs'!B701="",0,1)="",0,IF('Model inputs'!B701="",0,1)),IF(IF('Model inputs'!B702="",0,1)="",0,IF('Model inputs'!B702="",0,1)),IF(IF('Model inputs'!B703="",0,1)="",0,IF('Model inputs'!B703="",0,1)))=0,"",SUM('Model inputs'!B699,'Model inputs'!B700,'Model inputs'!B701,'Model inputs'!B702,'Model inputs'!B703)) -> 0.86785 | D13: =IF(SUM(IF(IF('Model inputs'!B704="",0,1)="",0,IF('Model inputs'!B704="",0,1)),IF(IF('Model inputs'!B705="",0,1)="",0,IF('Model inputs'!B705="",0,1)),IF(IF('Model inputs'!B706="",0,1)="",0,IF('Model inputs'!B706="",0,1)),IF(IF('Model inputs'!B707="",0,1)="",0,IF('Model inputs'!B707="",0,1)),IF(IF('Model inputs'!B708="",0,1)="",0,IF('Model inputs'!B708="",0,1)))=0,"",SUM('Model inputs'!B704,'Model inputs'!B705,'Model inputs'!B706,'Model inputs'!B707,'Model inputs'!B708)) -> 0.86785 | E13: =IF(SUM(IF(IF('Model inputs'!B709="",0,1)="",0,IF('Model inputs'!B709="",0,1)),IF(IF('Model inputs'!B710="",0,1)="",0,IF('Model inputs'!B710="",0,1)),IF(IF('Model inputs'!B711="",0,1)="",0,IF('Model inputs'!B711="",0,1)),IF(IF('Model inputs'!B712="",0,1)="",0,IF('Model inputs'!B712="",0,1)),IF(IF('Model inputs'!B713="",0,1)="",0,IF('Model inputs'!B713="",0,1)))=0,"",SUM('Model inputs'!B709,'Model inputs'!B710,'Model inputs'!B711,'Model inputs'!B712,'Model inputs'!B713)) -> 0.86785 | F13: =IF(SUM(IF(IF('Model inputs'!B714="",0,1)="",0,IF('Model inputs'!B714="",0,1)),IF(IF('Model inputs'!B715="",0,1)="",0,IF('Model inputs'!B715="",0,1)),IF(IF('Model inputs'!B716="",0,1)="",0,IF('Model inputs'!B716="",0,1)),IF(IF('Model inputs'!B717="",0,1)="",0,IF('Model inputs'!B717="",0,1)),IF(IF('Model inputs'!B718="",0,1)="",0,IF('Model inputs'!B718="",0,1)))=0,"",SUM('Model inputs'!B714,'Model inputs'!B715,'Model inputs'!B716,'Model inputs'!B717,'Model inputs'!B718)) -> 0.86785 | G13: =IF(SUM(IF(IF('Model inputs'!B719="",0,1)="",0,IF('Model inputs'!B719="",0,1)),IF(IF('Model inputs'!B720="",0,1)="",0,IF('Model inputs'!B720="",0,1)),IF(IF('Model inputs'!B721="",0,1)="",0,IF('Model inputs'!B721="",0,1)),IF(IF('Model inputs'!B722="",0,1)="",0,IF('Model inputs'!B722="",0,1)),IF(IF('Model inputs'!B723="",0,1)="",0,IF('Model inputs'!B723="",0,1)))=0,"",SUM('Model inputs'!B719,'Model inputs'!B720,'Model inputs'!B721,'Model inputs'!B722,'Model inputs'!B723)) -> 0.86785 | H13: =IF(SUM(IF(IF('Model inputs'!B724="",0,1)="",0,IF('Model inputs'!B724="",0,1)),IF(IF('Model inputs'!B725="",0,1)="",0,IF('Model inputs'!B725="",0,1)),IF(IF('Model inputs'!B726="",0,1)="",0,IF('Model inputs'!B726="",0,1)),IF(IF('Model inputs'!B727="",0,1)="",0,IF('Model inputs'!B727="",0,1)),IF(IF('Model inputs'!B728="",0,1)="",0,IF('Model inputs'!B728="",0,1)))=0,"",SUM('Model inputs'!B724,'Model inputs'!B725,'Model inputs'!B726,'Model inputs'!B727,'Model inputs'!B728)) -> 0.86785 | I13: =IF(SUM(IF(IF('Model inputs'!B729="",0,1)="",0,IF('Model inputs'!B729="",0,1)),IF(IF('Model inputs'!B730="",0,1)="",0,IF('Model inputs'!B730="",0,1)),IF(IF('Model inputs'!B731="",0,1)="",0,IF('Model inputs'!B731="",0,1)),IF(IF('Model inputs'!B732="",0,1)="",0,IF('Model inputs'!B732="",0,1)),IF(IF('Model inputs'!B733="",0,1)="",0,IF('Model inputs'!B733="",0,1)))=0,"",SUM('Model inputs'!B729,'Model inputs'!B730,'Model inputs'!B731,'Model inputs'!B732,'Model inputs'!B733)) -> 0.86785 | J13: =IF(SUM(IF(IF('Model inputs'!B734="",0,1)="",0,IF('Model inputs'!B734="",0,1)),IF(IF('Model inputs'!B735="",0,1)="",0,IF('Model inputs'!B735="",0,1)),IF(IF('Model inputs'!B736="",0,1)="",0,IF('Model inputs'!B736="",0,1)),IF(IF('Model inputs'!B737="",0,1)="",0,IF('Model inputs'!B737="",0,1)),IF(IF('Model inputs'!B738="",0,1)="",0,IF('Model inputs'!B738="",0,1)))=0,"",SUM('Model inputs'!B734,'Model inputs'!B735,'Model inputs'!B736,'Model inputs'!B737,'Model inputs'!B738)) -> 0.86785 | K13: =IF(SUM(IF(IF('Model inputs'!B739="",0,1)="",0,IF('Model inputs'!B739="",0,1)),IF(IF('Model inputs'!B740="",0,1)="",0,IF('Model inputs'!B740="",0,1)),IF(IF('Model inputs'!B741="",0,1)="",0,IF('Model inputs'!B741="",0,1)),IF(IF('Model inputs'!B742="",0,1)="",0,IF('Model inputs'!B742="",0,1)),IF(IF('Model inputs'!B743="",0,1)="",0,IF('Model inputs'!B743="",0,1)))=0,"",SUM('Model inputs'!B739,'Model inputs'!B740,'Model inputs'!B741,'Model inputs'!B742,'Model inputs'!B743)) -> 0.86785 | L13: =IF(SUM(IF(IF('Model inputs'!B744="",0,1)="",0,IF('Model inputs'!B744="",0,1)),IF(IF('Model inputs'!B745="",0,1)="",0,IF('Model inputs'!B745="",0,1)),IF(IF('Model inputs'!B746="",0,1)="",0,IF('Model inputs'!B746="",0,1)),IF(IF('Model inputs'!B747="",0,1)="",0,IF('Model inputs'!B747="",0,1)),IF(IF('Model inputs'!B748="",0,1)="",0,IF('Model inputs'!B748="",0,1)))=0,"",SUM('Model inputs'!B744,'Model inputs'!B745,'Model inputs'!B746,'Model inputs'!B747,'Model inputs'!B748)) -> 0.86785 | M13: =IF(SUM(IF(IF('Model inputs'!B749="",0,1)="",0,IF('Model inputs'!B749="",0,1)),IF(IF('Model inputs'!B750="",0,1)="",0,IF('Model inputs'!B750="",0,1)),IF(IF('Model inputs'!B751="",0,1)="",0,IF('Model inputs'!B751="",0,1)),IF(IF('Model inputs'!B752="",0,1)="",0,IF('Model inputs'!B752="",0,1)),IF(IF('Model inputs'!B753="",0,1)="",0,IF('Model inputs'!B753="",0,1)))=0,"",SUM('Model inputs'!B749,'Model inputs'!B750,'Model inputs'!B751,'Model inputs'!B752,'Model inputs'!B753)) -> 0.86785
