Workbook

Sheet DealScope monthly model and pri
A1: DealScope monthly model and pricing alternatives
A2: DealScope — Model formulas · Main Scenario
A4: Variable / dimension | B4: 2026-10 | C4: 2026-11 | D4: 2026-12 | E4: 2027-01 | F4: 2027-02 | G4: 2027-03 | H4: 2027-04 | I4: 2027-05 | J4: 2027-06 | K4: 2027-07 | L4: 2027-08 | M4: 2027-09
A5: Projection month | B5: =DATEDIF('Model inputs'!O58,DATE(2026,10,1),"M")+1 -> 1 | C5: =DATEDIF('Model inputs'!O58,DATE(2026,11,1),"M")+1 -> 2 | D5: =DATEDIF('Model inputs'!O58,DATE(2026,12,1),"M")+1 -> 3 | E5: =DATEDIF('Model inputs'!O58,DATE(2027,1,1),"M")+1 -> 4 | F5: =DATEDIF('Model inputs'!O58,DATE(2027,2,1),"M")+1 -> 5 | G5: =DATEDIF('Model inputs'!O58,DATE(2027,3,1),"M")+1 -> 6 | H5: =DATEDIF('Model inputs'!O58,DATE(2027,4,1),"M")+1 -> 7 | I5: =DATEDIF('Model inputs'!O58,DATE(2027,5,1),"M")+1 -> 8 | J5: =DATEDIF('Model inputs'!O58,DATE(2027,6,1),"M")+1 -> 9 | K5: =DATEDIF('Model inputs'!O58,DATE(2027,7,1),"M")+1 -> 10 | L5: =DATEDIF('Model inputs'!O58,DATE(2027,8,1),"M")+1 -> 11 | M5: =DATEDIF('Model inputs'!O58,DATE(2027,9,1),"M")+1 -> 12
A6: Paying customer equivalents | B6: =IF(IF(IF(ISERROR('Model inputs'!O94=1),'Model inputs'!O94=1,IF('Model inputs'!O94="","",'Model inputs'!O94=1))="",FALSE,IF(ISERROR('Model inputs'!O94=1),'Model inputs'!O94=1,IF('Model inputs'!O94="","",'Model inputs'!O94=1))),'Model inputs'!O96*MIN(MAX(('DealScope monthly model and pri'!B5-'Model inputs'!O95)/'Model inputs'!O93,0),1),IF(IF(IF(ISERROR('DealScope monthly model and pri'!B5>'Model inputs'!O95),'DealScope monthly model and pri'!B5>'Model inputs'!O95,IF(OR('DealScope monthly model and pri'!B5="",'Model inputs'!O95=""),"",'DealScope monthly model and pri'!B5>'Model inputs'!O95))="",FALSE,IF(ISERROR('DealScope monthly model and pri'!B5>'Model inputs'!O95),'DealScope monthly model and pri'!B5>'Model inputs'!O95,IF(OR('DealScope monthly model and pri'!B5="",'Model inputs'!O95=""),"",'DealScope monthly model and pri'!B5>'Model inputs'!O95))),IF('Model inputs'!O96="","",'Model inputs'!O96),0)) -> 5 | C6: =IF(IF(IF(ISERROR('Model inputs'!O94=1),'Model inputs'!O94=1,IF('Model inputs'!O94="","",'Model inputs'!O94=1))="",FALSE,IF(ISERROR('Model inputs'!O94=1),'Model inputs'!O94=1,IF('Model inputs'!O94="","",'Model inputs'!O94=1))),'Model inputs'!O96*MIN(MAX(('DealScope monthly model and pri'!C5-'Model inputs'!O95)/'Model inputs'!O93,0),1),IF(IF(IF(ISERROR('DealScope monthly model and pri'!C5>'Model inputs'!O95),'DealScope monthly model and pri'!C5>'Model inputs'!O95,IF(OR('DealScope monthly model and pri'!C5="",'Model inputs'!O95=""),"",'DealScope monthly model and pri'!C5>'Model inputs'!O95))="",FALSE,IF(ISERROR('DealScope monthly model and pri'!C5>'Model inputs'!O95),'DealScope monthly model and pri'!C5>'Model inputs'!O95,IF(OR('DealScope monthly model and pri'!C5="",'Model inputs'!O95=""),"",'DealScope monthly model and pri'!C5>'Model inputs'!O95))),IF('Model inputs'!O96="","",'Model inputs'!O96),0)) -> 5 | D6: =IF(IF(IF(ISERROR('Model inputs'!O94=1),'Model inputs'!O94=1,IF('Model inputs'!O94="","",'Model inputs'!O94=1))="",FALSE,IF(ISERROR('Model inputs'!O94=1),'Model inputs'!O94=1,IF('Model inputs'!O94="","",'Model inputs'!O94=1))),'Model inputs'!O96*MIN(MAX(('DealScope monthly model and pri'!D5-'Model inputs'!O95)/'Model inputs'!O93,0),1),IF(IF(IF(ISERROR('DealScope monthly model and pri'!D5>'Model inputs'!O95),'DealScope monthly model and pri'!D5>'Model inputs'!O95,IF(OR('DealScope monthly model and pri'!D5="",'Model inputs'!O95=""),"",'DealScope monthly model and pri'!D5>'Model inputs'!O95))="",FALSE,IF(ISERROR('DealScope monthly model and pri'!D5>'Model inputs'!O95),'DealScope monthly model and pri'!D5>'Model inputs'!O95,IF(OR('DealScope monthly model and pri'!D5="",'Model inputs'!O95=""),"",'DealScope monthly model and pri'!D5>'Model inputs'!O95))),IF('Model inputs'!O96="","",'Model inputs'!O96),0)) -> 5 | E6: =IF(IF(IF(ISERROR('Model inputs'!O94=1),'Model inputs'!O94=1,IF('Model inputs'!O94="","",'Model inputs'!O94=1))="",FALSE,IF(ISERROR('Model inputs'!O94=1),'Model inputs'!O94=1,IF('Model inputs'!O94="","",'Model inputs'!O94=1))),'Model inputs'!O96*MIN(MAX(('DealScope monthly model and pri'!E5-'Model inputs'!O95)/'Model inputs'!O93,0),1),IF(IF(IF(ISERROR('DealScope monthly model and pri'!E5>'Model inputs'!O95),'DealScope monthly model and pri'!E5>'Model inputs'!O95,IF(OR('DealScope monthly model and pri'!E5="",'Model inputs'!O95=""),"",'DealScope monthly model and pri'!E5>'Model inputs'!O95))="",FALSE,IF(ISERROR('DealScope monthly model and pri'!E5>'Model inputs'!O95),'DealScope monthly model and pri'!E5>'Model inputs'!O95,IF(OR('DealScope monthly model and pri'!E5="",'Model inputs'!O95=""),"",'DealScope monthly model and pri'!E5>'Model inputs'!O95))),IF('Model inputs'!O96="","",'Model inputs'!O96),0)) -> 5 | F6: =IF(IF(IF(ISERROR('Model inputs'!O94=1),'Model inputs'!O94=1,IF('Model inputs'!O94="","",'Model inputs'!O94=1))="",FALSE,IF(ISERROR('Model inputs'!O94=1),'Model inputs'!O94=1,IF('Model inputs'!O94="","",'Model inputs'!O94=1))),'Model inputs'!O96*MIN(MAX(('DealScope monthly model and pri'!F5-'Model inputs'!O95)/'Model inputs'!O93,0),1),IF(IF(IF(ISERROR('DealScope monthly model and pri'!F5>'Model inputs'!O95),'DealScope monthly model and pri'!F5>'Model inputs'!O95,IF(OR('DealScope monthly model and pri'!F5="",'Model inputs'!O95=""),"",'DealScope monthly model and pri'!F5>'Model inputs'!O95))="",FALSE,IF(ISERROR('DealScope monthly model and pri'!F5>'Model inputs'!O95),'DealScope monthly model and pri'!F5>'Model inputs'!O95,IF(OR('DealScope monthly model and pri'!F5="",'Model inputs'!O95=""),"",'DealScope monthly model and pri'!F5>'Model inputs'!O95))),IF('Model inputs'!O96="","",'Model inputs'!O96),0)) -> 5 | G6: =IF(IF(IF(ISERROR('Model inputs'!O94=1),'Model inputs'!O94=1,IF('Model inputs'!O94="","",'Model inputs'!O94=1))="",FALSE,IF(ISERROR('Model inputs'!O94=1),'Model inputs'!O94=1,IF('Model inputs'!O94="","",'Model inputs'!O94=1))),'Model inputs'!O96*MIN(MAX(('DealScope monthly model and pri'!G5-'Model inputs'!O95)/'Model inputs'!O93,0),1),IF(IF(IF(ISERROR('DealScope monthly model and pri'!G5>'Model inputs'!O95),'DealScope monthly model and pri'!G5>'Model inputs'!O95,IF(OR('DealScope monthly model and pri'!G5="",'Model inputs'!O95=""),"",'DealScope monthly model and pri'!G5>'Model inputs'!O95))="",FALSE,IF(ISERROR('DealScope monthly model and pri'!G5>'Model inputs'!O95),'DealScope monthly model and pri'!G5>'Model inputs'!O95,IF(OR('DealScope monthly model and pri'!G5="",'Model inputs'!O95=""),"",'DealScope monthly model and pri'!G5>'Model inputs'!O95))),IF('Model inputs'!O96="","",'Model inputs'!O96),0)) -> 5 | H6: =IF(IF(IF(ISERROR('Model inputs'!O94=1),'Model inputs'!O94=1,IF('Model inputs'!O94="","",'Model inputs'!O94=1))="",FALSE,IF(ISERROR('Model inputs'!O94=1),'Model inputs'!O94=1,IF('Model inputs'!O94="","",'Model inputs'!O94=1))),'Model inputs'!O96*MIN(MAX(('DealScope monthly model and pri'!H5-'Model inputs'!O95)/'Model inputs'!O93,0),1),IF(IF(IF(ISERROR('DealScope monthly model and pri'!H5>'Model inputs'!O95),'DealScope monthly model and pri'!H5>'Model inputs'!O95,IF(OR('DealScope monthly model and pri'!H5="",'Model inputs'!O95=""),"",'DealScope monthly model and pri'!H5>'Model inputs'!O95))="",FALSE,IF(ISERROR('DealScope monthly model and pri'!H5>'Model inputs'!O95),'DealScope monthly model and pri'!H5>'Model inputs'!O95,IF(OR('DealScope monthly model and pri'!H5="",'Model inputs'!O95=""),"",'DealScope monthly model and pri'!H5>'Model inputs'!O95))),IF('Model inputs'!O96="","",'Model inputs'!O96),0)) -> 5 | I6: =IF(IF(IF(ISERROR('Model inputs'!O94=1),'Model inputs'!O94=1,IF('Model inputs'!O94="","",'Model inputs'!O94=1))="",FALSE,IF(ISERROR('Model inputs'!O94=1),'Model inputs'!O94=1,IF('Model inputs'!O94="","",'Model inputs'!O94=1))),'Model inputs'!O96*MIN(MAX(('DealScope monthly model and pri'!I5-'Model inputs'!O95)/'Model inputs'!O93,0),1),IF(IF(IF(ISERROR('DealScope monthly model and pri'!I5>'Model inputs'!O95),'DealScope monthly model and pri'!I5>'Model inputs'!O95,IF(OR('DealScope monthly model and pri'!I5="",'Model inputs'!O95=""),"",'DealScope monthly model and pri'!I5>'Model inputs'!O95))="",FALSE,IF(ISERROR('DealScope monthly model and pri'!I5>'Model inputs'!O95),'DealScope monthly model and pri'!I5>'Model inputs'!O95,IF(OR('DealScope monthly model and pri'!I5="",'Model inputs'!O95=""),"",'DealScope monthly model and pri'!I5>'Model inputs'!O95))),IF('Model inputs'!O96="","",'Model inputs'!O96),0)) -> 5 | J6: =IF(IF(IF(ISERROR('Model inputs'!O94=1),'Model inputs'!O94=1,IF('Model inputs'!O94="","",'Model inputs'!O94=1))="",FALSE,IF(ISERROR('Model inputs'!O94=1),'Model inputs'!O94=1,IF('Model inputs'!O94="","",'Model inputs'!O94=1))),'Model inputs'!O96*MIN(MAX(('DealScope monthly model and pri'!J5-'Model inputs'!O95)/'Model inputs'!O93,0),1),IF(IF(IF(ISERROR('DealScope monthly model and pri'!J5>'Model inputs'!O95),'DealScope monthly model and pri'!J5>'Model inputs'!O95,IF(OR('DealScope monthly model and pri'!J5="",'Model inputs'!O95=""),"",'DealScope monthly model and pri'!J5>'Model inputs'!O95))="",FALSE,IF(ISERROR('DealScope monthly model and pri'!J5>'Model inputs'!O95),'DealScope monthly model and pri'!J5>'Model inputs'!O95,IF(OR('DealScope monthly model and pri'!J5="",'Model inputs'!O95=""),"",'DealScope monthly model and pri'!J5>'Model inputs'!O95))),IF('Model inputs'!O96="","",'Model inputs'!O96),0)) -> 5 | K6: =IF(IF(IF(ISERROR('Model inputs'!O94=1),'Model inputs'!O94=1,IF('Model inputs'!O94="","",'Model inputs'!O94=1))="",FALSE,IF(ISERROR('Model inputs'!O94=1),'Model inputs'!O94=1,IF('Model inputs'!O94="","",'Model inputs'!O94=1))),'Model inputs'!O96*MIN(MAX(('DealScope monthly model and pri'!K5-'Model inputs'!O95)/'Model inputs'!O93,0),1),IF(IF(IF(ISERROR('DealScope monthly model and pri'!K5>'Model inputs'!O95),'DealScope monthly model and pri'!K5>'Model inputs'!O95,IF(OR('DealScope monthly model and pri'!K5="",'Model inputs'!O95=""),"",'DealScope monthly model and pri'!K5>'Model inputs'!O95))="",FALSE,IF(ISERROR('DealScope monthly model and pri'!K5>'Model inputs'!O95),'DealScope monthly model and pri'!K5>'Model inputs'!O95,IF(OR('DealScope monthly model and pri'!K5="",'Model inputs'!O95=""),"",'DealScope monthly model and pri'!K5>'Model inputs'!O95))),IF('Model inputs'!O96="","",'Model inputs'!O96),0)) -> 5 | L6: =IF(IF(IF(ISERROR('Model inputs'!O94=1),'Model inputs'!O94=1,IF('Model inputs'!O94="","",'Model inputs'!O94=1))="",FALSE,IF(ISERROR('Model inputs'!O94=1),'Model inputs'!O94=1,IF('Model inputs'!O94="","",'Model inputs'!O94=1))),'Model inputs'!O96*MIN(MAX(('DealScope monthly model and pri'!L5-'Model inputs'!O95)/'Model inputs'!O93,0),1),IF(IF(IF(ISERROR('DealScope monthly model and pri'!L5>'Model inputs'!O95),'DealScope monthly model and pri'!L5>'Model inputs'!O95,IF(OR('DealScope monthly model and pri'!L5="",'Model inputs'!O95=""),"",'DealScope monthly model and pri'!L5>'Model inputs'!O95))="",FALSE,IF(ISERROR('DealScope monthly model and pri'!L5>'Model inputs'!O95),'DealScope monthly model and pri'!L5>'Model inputs'!O95,IF(OR('DealScope monthly model and pri'!L5="",'Model inputs'!O95=""),"",'DealScope monthly model and pri'!L5>'Model inputs'!O95))),IF('Model inputs'!O96="","",'Model inputs'!O96),0)) -> 5 | M6: =IF(IF(IF(ISERROR('Model inputs'!O94=1),'Model inputs'!O94=1,IF('Model inputs'!O94="","",'Model inputs'!O94=1))="",FALSE,IF(ISERROR('Model inputs'!O94=1),'Model inputs'!O94=1,IF('Model inputs'!O94="","",'Model inputs'!O94=1))),'Model inputs'!O96*MIN(MAX(('DealScope monthly model and pri'!M5-'Model inputs'!O95)/'Model inputs'!O93,0),1),IF(IF(IF(ISERROR('DealScope monthly model and pri'!M5>'Model inputs'!O95),'DealScope monthly model and pri'!M5>'Model inputs'!O95,IF(OR('DealScope monthly model and pri'!M5="",'Model inputs'!O95=""),"",'DealScope monthly model and pri'!M5>'Model inputs'!O95))="",FALSE,IF(ISERROR('DealScope monthly model and pri'!M5>'Model inputs'!O95),'DealScope monthly model and pri'!M5>'Model inputs'!O95,IF(OR('DealScope monthly model and pri'!M5="",'Model inputs'!O95=""),"",'DealScope monthly model and pri'!M5>'Model inputs'!O95))),IF('Model inputs'!O96="","",'Model inputs'!O96),0)) -> 5
A7: New customer equivalents | B7: =MAX('DealScope monthly model and pri'!B6-IF(IF(IF(IF(ISERROR('DealScope monthly model and pri'!B5=1),'DealScope monthly model and pri'!B5=1,IF('DealScope monthly model and pri'!B5="","",'DealScope monthly model and pri'!B5=1))="",FALSE,IF(ISERROR('DealScope monthly model and pri'!B5=1),'DealScope monthly model and pri'!B5=1,IF('DealScope monthly model and pri'!B5="","",'DealScope monthly model and pri'!B5=1))),0,IF('Model inputs'!B68="","",'Model inputs'!B68))="",0,IF(IF(IF(ISERROR('DealScope monthly model and pri'!B5=1),'DealScope monthly model and pri'!B5=1,IF('DealScope monthly model and pri'!B5="","",'DealScope monthly model and pri'!B5=1))="",FALSE,IF(ISERROR('DealScope monthly model and pri'!B5=1),'DealScope monthly model and pri'!B5=1,IF('DealScope monthly model and pri'!B5="","",'DealScope monthly model and pri'!B5=1))),0,IF('Model inputs'!B68="","",'Model inputs'!B68))),0) -> 5 | C7: =MAX('DealScope monthly model and pri'!C6-IF(IF(IF(IF(ISERROR('DealScope monthly model and pri'!C5=1),'DealScope monthly model and pri'!C5=1,IF('DealScope monthly model and pri'!C5="","",'DealScope monthly model and pri'!C5=1))="",FALSE,IF(ISERROR('DealScope monthly model and pri'!C5=1),'DealScope monthly model and pri'!C5=1,IF('DealScope monthly model and pri'!C5="","",'DealScope monthly model and pri'!C5=1))),0,IF('DealScope monthly model and pri'!B6="","",'DealScope monthly model and pri'!B6))="",0,IF(IF(IF(ISERROR('DealScope monthly model and pri'!C5=1),'DealScope monthly model and pri'!C5=1,IF('DealScope monthly model and pri'!C5="","",'DealScope monthly model and pri'!C5=1))="",FALSE,IF(ISERROR('DealScope monthly model and pri'!C5=1),'DealScope monthly model and pri'!C5=1,IF('DealScope monthly model and pri'!C5="","",'DealScope monthly model and pri'!C5=1))),0,IF('DealScope monthly model and pri'!B6="","",'DealScope monthly model and pri'!B6))),0) -> 0 | D7: =MAX('DealScope monthly model and pri'!D6-IF(IF(IF(IF(ISERROR('DealScope monthly model and pri'!D5=1),'DealScope monthly model and pri'!D5=1,IF('DealScope monthly model and pri'!D5="","",'DealScope monthly model and pri'!D5=1))="",FALSE,IF(ISERROR('DealScope monthly model and pri'!D5=1),'DealScope monthly model and pri'!D5=1,IF('DealScope monthly model and pri'!D5="","",'DealScope monthly model and pri'!D5=1))),0,IF('DealScope monthly model and pri'!C6="","",'DealScope monthly model and pri'!C6))="",0,IF(IF(IF(ISERROR('DealScope monthly model and pri'!D5=1),'DealScope monthly model and pri'!D5=1,IF('DealScope monthly model and pri'!D5="","",'DealScope monthly model and pri'!D5=1))="",FALSE,IF(ISERROR('DealScope monthly model and pri'!D5=1),'DealScope monthly model and pri'!D5=1,IF('DealScope monthly model and pri'!D5="","",'DealScope monthly model and pri'!D5=1))),0,IF('DealScope monthly model and pri'!C6="","",'DealScope monthly model and pri'!C6))),0) -> 0 | E7: =MAX('DealScope monthly model and pri'!E6-IF(IF(IF(IF(ISERROR('DealScope monthly model and pri'!E5=1),'DealScope monthly model and pri'!E5=1,IF('DealScope monthly model and pri'!E5="","",'DealScope monthly model and pri'!E5=1))="",FALSE,IF(ISERROR('DealScope monthly model and pri'!E5=1),'DealScope monthly model and pri'!E5=1,IF('DealScope monthly model and pri'!E5="","",'DealScope monthly model and pri'!E5=1))),0,IF('DealScope monthly model and pri'!D6="","",'DealScope monthly model and pri'!D6))="",0,IF(IF(IF(ISERROR('DealScope monthly model and pri'!E5=1),'DealScope monthly model and pri'!E5=1,IF('DealScope monthly model and pri'!E5="","",'DealScope monthly model and pri'!E5=1))="",FALSE,IF(ISERROR('DealScope monthly model and pri'!E5=1),'DealScope monthly model and pri'!E5=1,IF('DealScope monthly model and pri'!E5="","",'DealScope monthly model and pri'!E5=1))),0,IF('DealScope monthly model and pri'!D6="","",'DealScope monthly model and pri'!D6))),0) -> 0 | F7: =MAX('DealScope monthly model and pri'!F6-IF(IF(IF(IF(ISERROR('DealScope monthly model and pri'!F5=1),'DealScope monthly model and pri'!F5=1,IF('DealScope monthly model and pri'!F5="","",'DealScope monthly model and pri'!F5=1))="",FALSE,IF(ISERROR('DealScope monthly model and pri'!F5=1),'DealScope monthly model and pri'!F5=1,IF('DealScope monthly model and pri'!F5="","",'DealScope monthly model and pri'!F5=1))),0,IF('DealScope monthly model and pri'!E6="","",'DealScope monthly model and pri'!E6))="",0,IF(IF(IF(ISERROR('DealScope monthly model and pri'!F5=1),'DealScope monthly model and pri'!F5=1,IF('DealScope monthly model and pri'!F5="","",'DealScope monthly model and pri'!F5=1))="",FALSE,IF(ISERROR('DealScope monthly model and pri'!F5=1),'DealScope monthly model and pri'!F5=1,IF('DealScope monthly model and pri'!F5="","",'DealScope monthly model and pri'!F5=1))),0,IF('DealScope monthly model and pri'!E6="","",'DealScope monthly model and pri'!E6))),0) -> 0 | G7: =MAX('DealScope monthly model and pri'!G6-IF(IF(IF(IF(ISERROR('DealScope monthly model and pri'!G5=1),'DealScope monthly model and pri'!G5=1,IF('DealScope monthly model and pri'!G5="","",'DealScope monthly model and pri'!G5=1))="",FALSE,IF(ISERROR('DealScope monthly model and pri'!G5=1),'DealScope monthly model and pri'!G5=1,IF('DealScope monthly model and pri'!G5="","",'DealScope monthly model and pri'!G5=1))),0,IF('DealScope monthly model and pri'!F6="","",'DealScope monthly model and pri'!F6))="",0,IF(IF(IF(ISERROR('DealScope monthly model and pri'!G5=1),'DealScope monthly model and pri'!G5=1,IF('DealScope monthly model and pri'!G5="","",'DealScope monthly model and pri'!G5=1))="",FALSE,IF(ISERROR('DealScope monthly model and pri'!G5=1),'DealScope monthly model and pri'!G5=1,IF('DealScope monthly model and pri'!G5="","",'DealScope monthly model and pri'!G5=1))),0,IF('DealScope monthly model and pri'!F6="","",'DealScope monthly model and pri'!F6))),0) -> 0 | H7: =MAX('DealScope monthly model and pri'!H6-IF(IF(IF(IF(ISERROR('DealScope monthly model and pri'!H5=1),'DealScope monthly model and pri'!H5=1,IF('DealScope monthly model and pri'!H5="","",'DealScope monthly model and pri'!H5=1))="",FALSE,IF(ISERROR('DealScope monthly model and pri'!H5=1),'DealScope monthly model and pri'!H5=1,IF('DealScope monthly model and pri'!H5="","",'DealScope monthly model and pri'!H5=1))),0,IF('DealScope monthly model and pri'!G6="","",'DealScope monthly model and pri'!G6))="",0,IF(IF(IF(ISERROR('DealScope monthly model and pri'!H5=1),'DealScope monthly model and pri'!H5=1,IF('DealScope monthly model and pri'!H5="","",'DealScope monthly model and pri'!H5=1))="",FALSE,IF(ISERROR('DealScope monthly model and pri'!H5=1),'DealScope monthly model and pri'!H5=1,IF('DealScope monthly model and pri'!H5="","",'DealScope monthly model and pri'!H5=1))),0,IF('DealScope monthly model and pri'!G6="","",'DealScope monthly model and pri'!G6))),0) -> 0 | I7: =MAX('DealScope monthly model and pri'!I6-IF(IF(IF(IF(ISERROR('DealScope monthly model and pri'!I5=1),'DealScope monthly model and pri'!I5=1,IF('DealScope monthly model and pri'!I5="","",'DealScope monthly model and pri'!I5=1))="",FALSE,IF(ISERROR('DealScope monthly model and pri'!I5=1),'DealScope monthly model and pri'!I5=1,IF('DealScope monthly model and pri'!I5="","",'DealScope monthly model and pri'!I5=1))),0,IF('DealScope monthly model and pri'!H6="","",'DealScope monthly model and pri'!H6))="",0,IF(IF(IF(ISERROR('DealScope monthly model and pri'!I5=1),'DealScope monthly model and pri'!I5=1,IF('DealScope monthly model and pri'!I5="","",'DealScope monthly model and pri'!I5=1))="",FALSE,IF(ISERROR('DealScope monthly model and pri'!I5=1),'DealScope monthly model and pri'!I5=1,IF('DealScope monthly model and pri'!I5="","",'DealScope monthly model and pri'!I5=1))),0,IF('DealScope monthly model and pri'!H6="","",'DealScope monthly model and pri'!H6))),0) -> 0 | J7: =MAX('DealScope monthly model and pri'!J6-IF(IF(IF(IF(ISERROR('DealScope monthly model and pri'!J5=1),'DealScope monthly model and pri'!J5=1,IF('DealScope monthly model and pri'!J5="","",'DealScope monthly model and pri'!J5=1))="",FALSE,IF(ISERROR('DealScope monthly model and pri'!J5=1),'DealScope monthly model and pri'!J5=1,IF('DealScope monthly model and pri'!J5="","",'DealScope monthly model and pri'!J5=1))),0,IF('DealScope monthly model and pri'!I6="","",'DealScope monthly model and pri'!I6))="",0,IF(IF(IF(ISERROR('DealScope monthly model and pri'!J5=1),'DealScope monthly model and pri'!J5=1,IF('DealScope monthly model and pri'!J5="","",'DealScope monthly model and pri'!J5=1))="",FALSE,IF(ISERROR('DealScope monthly model and pri'!J5=1),'DealScope monthly model and pri'!J5=1,IF('DealScope monthly model and pri'!J5="","",'DealScope monthly model and pri'!J5=1))),0,IF('DealScope monthly model and pri'!I6="","",'DealScope monthly model and pri'!I6))),0) -> 0 | ... M7: =MAX('DealScope monthly model and pri'!M6-IF(IF(IF(IF(ISERROR('DealScope monthly model and pri'!M5=1),'DealScope monthly model and pri'!M5=1,IF('DealScope monthly model and pri'!M5="","",'DealScope monthly model and pri'!M5=1))="",FALSE,IF(ISERROR('DealScope monthly model and pri'!M5=1),'DealScope monthly model and pri'!M5=1,IF('DealScope monthly model and pri'!M5="","",'DealScope monthly model and pri'!M5=1))),0,IF('DealScope monthly model and pri'!L6="","",'DealScope monthly model and pri'!L6))="",0,IF(IF(IF(ISERROR('DealScope monthly model and pri'!M5=1),'DealScope monthly model and pri'!M5=1,IF('DealScope monthly model and pri'!M5="","",'DealScope monthly model and pri'!M5=1))="",FALSE,IF(ISERROR('DealScope monthly model and pri'!M5=1),'DealScope monthly model and pri'!M5=1,IF('DealScope monthly model and pri'!M5="","",'DealScope monthly model and pri'!M5=1))),0,IF('DealScope monthly model and pri'!L6="","",'DealScope monthly model and pri'!L6))),0) -> 0
A8: Fixed costs | B8: ='Model inputs'!O60+'Model inputs'!O84+'Model inputs'!O42+'Model inputs'!O59+'Model inputs'!O82+IF(IF(IF(IF(ISERROR('DealScope monthly model and pri'!B5>='Model inputs'!O27),'DealScope monthly model and pri'!B5>='Model inputs'!O27,IF(OR('DealScope monthly model and pri'!B5="",'Model inputs'!O27=""),"",'DealScope monthly model and pri'!B5>='Model inputs'!O27))="",FALSE,IF(ISERROR('DealScope monthly model and pri'!B5>='Model inputs'!O27),'DealScope monthly model and pri'!B5>='Model inputs'!O27,IF(OR('DealScope monthly model and pri'!B5="",'Model inputs'!O27=""),"",'DealScope monthly model and pri'!B5>='Model inputs'!O27))),IF('Model inputs'!O26="","",'Model inputs'!O26),0)="",0,IF(IF(IF(ISERROR('DealScope monthly model and pri'!B5>='Model inputs'!O27),'DealScope monthly model and pri'!B5>='Model inputs'!O27,IF(OR('DealScope monthly model and pri'!B5="",'Model inputs'!O27=""),"",'DealScope monthly model and pri'!B5>='Model inputs'!O27))="",FALSE,IF(ISERROR('DealScope monthly model and pri'!B5>='Model inputs'!O27),'DealScope monthly model and pri'!B5>='Model inputs'!O27,IF(OR('DealScope monthly model and pri'!B5="",'Model inputs'!O27=""),"",'DealScope monthly model and pri'!B5>='Model inputs'!O27))),IF('Model inputs'!O26="","",'Model inputs'!O26),0)) -> 750 | C8: ='Model inputs'!O60+'Model inputs'!O84+'Model inputs'!O42+'Model inputs'!O59+'Model inputs'!O82+IF(IF(IF(IF(ISERROR('DealScope monthly model and pri'!C5>='Model inputs'!O27),'DealScope monthly model and pri'!C5>='Model inputs'!O27,IF(OR('DealScope monthly model and pri'!C5="",'Model inputs'!O27=""),"",'DealScope monthly model and pri'!C5>='Model inputs'!O27))="",FALSE,IF(ISERROR('DealScope monthly model and pri'!C5>='Model inputs'!O27),'DealScope monthly model and pri'!C5>='Model inputs'!O27,IF(OR('DealScope monthly model and pri'!C5="",'Model inputs'!O27=""),"",'DealScope monthly model and pri'!C5>='Model inputs'!O27))),IF('Model inputs'!O26="","",'Model inputs'!O26),0)="",0,IF(IF(IF(ISERROR('DealScope monthly model and pri'!C5>='Model inputs'!O27),'DealScope monthly model and pri'!C5>='Model inputs'!O27,IF(OR('DealScope monthly model and pri'!C5="",'Model inputs'!O27=""),"",'DealScope monthly model and pri'!C5>='Model inputs'!O27))="",FALSE,IF(ISERROR('DealScope monthly model and pri'!C5>='Model inputs'!O27),'DealScope monthly model and pri'!C5>='Model inputs'!O27,IF(OR('DealScope monthly model and pri'!C5="",'Model inputs'!O27=""),"",'DealScope monthly model and pri'!C5>='Model inputs'!O27))),IF('Model inputs'!O26="","",'Model inputs'!O26),0)) -> 750 | D8: ='Model inputs'!O60+'Model inputs'!O84+'Model inputs'!O42+'Model inputs'!O59+'Model inputs'!O82+IF(IF(IF(IF(ISERROR('DealScope monthly model and pri'!D5>='Model inputs'!O27),'DealScope monthly model and pri'!D5>='Model inputs'!O27,IF(OR('DealScope monthly model and pri'!D5="",'Model inputs'!O27=""),"",'DealScope monthly model and pri'!D5>='Model inputs'!O27))="",FALSE,IF(ISERROR('DealScope monthly model and pri'!D5>='Model inputs'!O27),'DealScope monthly model and pri'!D5>='Model inputs'!O27,IF(OR('DealScope monthly model and pri'!D5="",'Model inputs'!O27=""),"",'DealScope monthly model and pri'!D5>='Model inputs'!O27))),IF('Model inputs'!O26="","",'Model inputs'!O26),0)="",0,IF(IF(IF(ISERROR('DealScope monthly model and pri'!D5>='Model inputs'!O27),'DealScope monthly model and pri'!D5>='Model inputs'!O27,IF(OR('DealScope monthly model and pri'!D5="",'Model inputs'!O27=""),"",'DealScope monthly model and pri'!D5>='Model inputs'!O27))="",FALSE,IF(ISERROR('DealScope monthly model and pri'!D5>='Model inputs'!O27),'DealScope monthly model and pri'!D5>='Model inputs'!O27,IF(OR('DealScope monthly model and pri'!D5="",'Model inputs'!O27=""),"",'DealScope monthly model and pri'!D5>='Model inputs'!O27))),IF('Model inputs'!O26="","",'Model inputs'!O26),0)) -> 750 | E8: ='Model inputs'!O60+'Model inputs'!O84+'Model inputs'!O42+'Model inputs'!O59+'Model inputs'!O82+IF(IF(IF(IF(ISERROR('DealScope monthly model and pri'!E5>='Model inputs'!O27),'DealScope monthly model and pri'!E5>='Model inputs'!O27,IF(OR('DealScope monthly model and pri'!E5="",'Model inputs'!O27=""),"",'DealScope monthly model and pri'!E5>='Model inputs'!O27))="",FALSE,IF(ISERROR('DealScope monthly model and pri'!E5>='Model inputs'!O27),'DealScope monthly model and pri'!E5>='Model inputs'!O27,IF(OR('DealScope monthly model and pri'!E5="",'Model inputs'!O27=""),"",'DealScope monthly model and pri'!E5>='Model inputs'!O27))),IF('Model inputs'!O26="","",'Model inputs'!O26),0)="",0,IF(IF(IF(ISERROR('DealScope monthly model and pri'!E5>='Model inputs'!O27),'DealScope monthly model and pri'!E5>='Model inputs'!O27,IF(OR('DealScope monthly model and pri'!E5="",'Model inputs'!O27=""),"",'DealScope monthly model and pri'!E5>='Model inputs'!O27))="",FALSE,IF(ISERROR('DealScope monthly model and pri'!E5>='Model inputs'!O27),'DealScope monthly model and pri'!E5>='Model inputs'!O27,IF(OR('DealScope monthly model and pri'!E5="",'Model inputs'!O27=""),"",'DealScope monthly model and pri'!E5>='Model inputs'!O27))),IF('Model inputs'!O26="","",'Model inputs'!O26),0)) -> 750 | F8: ='Model inputs'!O60+'Model inputs'!O84+'Model inputs'!O42+'Model inputs'!O59+'Model inputs'!O82+IF(IF(IF(IF(ISERROR('DealScope monthly model and pri'!F5>='Model inputs'!O27),'DealScope monthly model and pri'!F5>='Model inputs'!O27,IF(OR('DealScope monthly model and pri'!F5="",'Model inputs'!O27=""),"",'DealScope monthly model and pri'!F5>='Model inputs'!O27))="",FALSE,IF(ISERROR('DealScope monthly model and pri'!F5>='Model inputs'!O27),'DealScope monthly model and pri'!F5>='Model inputs'!O27,IF(OR('DealScope monthly model and pri'!F5="",'Model inputs'!O27=""),"",'DealScope monthly model and pri'!F5>='Model inputs'!O27))),IF('Model inputs'!O26="","",'Model inputs'!O26),0)="",0,IF(IF(IF(ISERROR('DealScope monthly model and pri'!F5>='Model inputs'!O27),'DealScope monthly model and pri'!F5>='Model inputs'!O27,IF(OR('DealScope monthly model and pri'!F5="",'Model inputs'!O27=""),"",'DealScope monthly model and pri'!F5>='Model inputs'!O27))="",FALSE,IF(ISERROR('DealScope monthly model and pri'!F5>='Model inputs'!O27),'DealScope monthly model and pri'!F5>='Model inputs'!O27,IF(OR('DealScope monthly model and pri'!F5="",'Model inputs'!O27=""),"",'DealScope monthly model and pri'!F5>='Model inputs'!O27))),IF('Model inputs'!O26="","",'Model inputs'!O26),0)) -> 750 | G8: ='Model inputs'!O60+'Model inputs'!O84+'Model inputs'!O42+'Model inputs'!O59+'Model inputs'!O82+IF(IF(IF(IF(ISERROR('DealScope monthly model and pri'!G5>='Model inputs'!O27),'DealScope monthly model and pri'!G5>='Model inputs'!O27,IF(OR('DealScope monthly model and pri'!G5="",'Model inputs'!O27=""),"",'DealScope monthly model and pri'!G5>='Model inputs'!O27))="",FALSE,IF(ISERROR('DealScope monthly model and pri'!G5>='Model inputs'!O27),'DealScope monthly model and pri'!G5>='Model inputs'!O27,IF(OR('DealScope monthly model and pri'!G5="",'Model inputs'!O27=""),"",'DealScope monthly model and pri'!G5>='Model inputs'!O27))),IF('Model inputs'!O26="","",'Model inputs'!O26),0)="",0,IF(IF(IF(ISERROR('DealScope monthly model and pri'!G5>='Model inputs'!O27),'DealScope monthly model and pri'!G5>='Model inputs'!O27,IF(OR('DealScope monthly model and pri'!G5="",'Model inputs'!O27=""),"",'DealScope monthly model and pri'!G5>='Model inputs'!O27))="",FALSE,IF(ISERROR('DealScope monthly model and pri'!G5>='Model inputs'!O27),'DealScope monthly model and pri'!G5>='Model inputs'!O27,IF(OR('DealScope monthly model and pri'!G5="",'Model inputs'!O27=""),"",'DealScope monthly model and pri'!G5>='Model inputs'!O27))),IF('Model inputs'!O26="","",'Model inputs'!O26),0)) -> 1250 | H8: ='Model inputs'!O60+'Model inputs'!O84+'Model inputs'!O42+'Model inputs'!O59+'Model inputs'!O82+IF(IF(IF(IF(ISERROR('DealScope monthly model and pri'!H5>='Model inputs'!O27),'DealScope monthly model and pri'!H5>='Model inputs'!O27,IF(OR('DealScope monthly model and pri'!H5="",'Model inputs'!O27=""),"",'DealScope monthly model and pri'!H5>='Model inputs'!O27))="",FALSE,IF(ISERROR('DealScope monthly model and pri'!H5>='Model inputs'!O27),'DealScope monthly model and pri'!H5>='Model inputs'!O27,IF(OR('DealScope monthly model and pri'!H5="",'Model inputs'!O27=""),"",'DealScope monthly model and pri'!H5>='Model inputs'!O27))),IF('Model inputs'!O26="","",'Model inputs'!O26),0)="",0,IF(IF(IF(ISERROR('DealScope monthly model and pri'!H5>='Model inputs'!O27),'DealScope monthly model and pri'!H5>='Model inputs'!O27,IF(OR('DealScope monthly model and pri'!H5="",'Model inputs'!O27=""),"",'DealScope monthly model and pri'!H5>='Model inputs'!O27))="",FALSE,IF(ISERROR('DealScope monthly model and pri'!H5>='Model inputs'!O27),'DealScope monthly model and pri'!H5>='Model inputs'!O27,IF(OR('DealScope monthly model and pri'!H5="",'Model inputs'!O27=""),"",'DealScope monthly model and pri'!H5>='Model inputs'!O27))),IF('Model inputs'!O26="","",'Model inputs'!O26),0)) -> 1250 | I8: ='Model inputs'!O60+'Model inputs'!O84+'Model inputs'!O42+'Model inputs'!O59+'Model inputs'!O82+IF(IF(IF(IF(ISERROR('DealScope monthly model and pri'!I5>='Model inputs'!O27),'DealScope monthly model and pri'!I5>='Model inputs'!O27,IF(OR('DealScope monthly model and pri'!I5="",'Model inputs'!O27=""),"",'DealScope monthly model and pri'!I5>='Model inputs'!O27))="",FALSE,IF(ISERROR('DealScope monthly model and pri'!I5>='Model inputs'!O27),'DealScope monthly model and pri'!I5>='Model inputs'!O27,IF(OR('DealScope monthly model and pri'!I5="",'Model inputs'!O27=""),"",'DealScope monthly model and pri'!I5>='Model inputs'!O27))),IF('Model inputs'!O26="","",'Model inputs'!O26),0)="",0,IF(IF(IF(ISERROR('DealScope monthly model and pri'!I5>='Model inputs'!O27),'DealScope monthly model and pri'!I5>='Model inputs'!O27,IF(OR('DealScope monthly model and pri'!I5="",'Model inputs'!O27=""),"",'DealScope monthly model and pri'!I5>='Model inputs'!O27))="",FALSE,IF(ISERROR('DealScope monthly model and pri'!I5>='Model inputs'!O27),'DealScope monthly model and pri'!I5>='Model inputs'!O27,IF(OR('DealScope monthly model and pri'!I5="",'Model inputs'!O27=""),"",'DealScope monthly model and pri'!I5>='Model inputs'!O27))),IF('Model inputs'!O26="","",'Model inputs'!O26),0)) -> 1250 | J8: ='Model inputs'!O60+'Model inputs'!O84+'Model inputs'!O42+'Model inputs'!O59+'Model inputs'!O82+IF(IF(IF(IF(ISERROR('DealScope monthly model and pri'!J5>='Model inputs'!O27),'DealScope monthly model and pri'!J5>='Model inputs'!O27,IF(OR('DealScope monthly model and pri'!J5="",'Model inputs'!O27=""),"",'DealScope monthly model and pri'!J5>='Model inputs'!O27))="",FALSE,IF(ISERROR('DealScope monthly model and pri'!J5>='Model inputs'!O27),'DealScope monthly model and pri'!J5>='Model inputs'!O27,IF(OR('DealScope monthly model and pri'!J5="",'Model inputs'!O27=""),"",'DealScope monthly model and pri'!J5>='Model inputs'!O27))),IF('Model inputs'!O26="","",'Model inputs'!O26),0)="",0,IF(IF(IF(ISERROR('DealScope monthly model and pri'!J5>='Model inputs'!O27),'DealScope monthly model and pri'!J5>='Model inputs'!O27,IF(OR('DealScope monthly model and pri'!J5="",'Model inputs'!O27=""),"",'DealScope monthly model and pri'!J5>='Model inputs'!O27))="",FALSE,IF(ISERROR('DealScope monthly model and pri'!J5>='Model inputs'!O27),'DealScope monthly model and pri'!J5>='Model inputs'!O27,IF(OR('DealScope monthly model and pri'!J5="",'Model inputs'!O27=""),"",'DealScope monthly model and pri'!J5>='Model inputs'!O27))),IF('Model inputs'!O26="","",'Model inputs'!O26),0)) -> 1250 | K8: ='Model inputs'!O60+'Model inputs'!O84+'Model inputs'!O42+'Model inputs'!O59+'Model inputs'!O82+IF(IF(IF(IF(ISERROR('DealScope monthly model and pri'!K5>='Model inputs'!O27),'DealScope monthly model and pri'!K5>='Model inputs'!O27,IF(OR('DealScope monthly model and pri'!K5="",'Model inputs'!O27=""),"",'DealScope monthly model and pri'!K5>='Model inputs'!O27))="",FALSE,IF(ISERROR('DealScope monthly model and pri'!K5>='Model inputs'!O27),'DealScope monthly model and pri'!K5>='Model inputs'!O27,IF(OR('DealScope monthly model and pri'!K5="",'Model inputs'!O27=""),"",'DealScope monthly model and pri'!K5>='Model inputs'!O27))),IF('Model inputs'!O26="","",'Model inputs'!O26),0)="",0,IF(IF(IF(ISERROR('DealScope monthly model and pri'!K5>='Model inputs'!O27),'DealScope monthly model and pri'!K5>='Model inputs'!O27,IF(OR('DealScope monthly model and pri'!K5="",'Model inputs'!O27=""),"",'DealScope monthly model and pri'!K5>='Model inputs'!O27))="",FALSE,IF(ISERROR('DealScope monthly model and pri'!K5>='Model inputs'!O27),'DealScope monthly model and pri'!K5>='Model inputs'!O27,IF(OR('DealScope monthly model and pri'!K5="",'Model inputs'!O27=""),"",'DealScope monthly model and pri'!K5>='Model inputs'!O27))),IF('Model inputs'!O26="","",'Model inputs'!O26),0)) -> 1250 | L8: ='Model inputs'!O60+'Model inputs'!O84+'Model inputs'!O42+'Model inputs'!O59+'Model inputs'!O82+IF(IF(IF(IF(ISERROR('DealScope monthly model and pri'!L5>='Model inputs'!O27),'DealScope monthly model and pri'!L5>='Model inputs'!O27,IF(OR('DealScope monthly model and pri'!L5="",'Model inputs'!O27=""),"",'DealScope monthly model and pri'!L5>='Model inputs'!O27))="",FALSE,IF(ISERROR('DealScope monthly model and pri'!L5>='Model inputs'!O27),'DealScope monthly model and pri'!L5>='Model inputs'!O27,IF(OR('DealScope monthly model and pri'!L5="",'Model inputs'!O27=""),"",'DealScope monthly model and pri'!L5>='Model inputs'!O27))),IF('Model inputs'!O26="","",'Model inputs'!O26),0)="",0,IF(IF(IF(ISERROR('DealScope monthly model and pri'!L5>='Model inputs'!O27),'DealScope monthly model and pri'!L5>='Model inputs'!O27,IF(OR('DealScope monthly model and pri'!L5="",'Model inputs'!O27=""),"",'DealScope monthly model and pri'!L5>='Model inputs'!O27))="",FALSE,IF(ISERROR('DealScope monthly model and pri'!L5>='Model inputs'!O27),'DealScope monthly model and pri'!L5>='Model inputs'!O27,IF(OR('DealScope monthly model and pri'!L5="",'Model inputs'!O27=""),"",'DealScope monthly model and pri'!L5>='Model inputs'!O27))),IF('Model inputs'!O26="","",'Model inputs'!O26),0)) -> 1250 | M8: ='Model inputs'!O60+'Model inputs'!O84+'Model inputs'!O42+'Model inputs'!O59+'Model inputs'!O82+IF(IF(IF(IF(ISERROR('DealScope monthly model and pri'!M5>='Model inputs'!O27),'DealScope monthly model and pri'!M5>='Model inputs'!O27,IF(OR('DealScope monthly model and pri'!M5="",'Model inputs'!O27=""),"",'DealScope monthly model and pri'!M5>='Model inputs'!O27))="",FALSE,IF(ISERROR('DealScope monthly model and pri'!M5>='Model inputs'!O27),'DealScope monthly model and pri'!M5>='Model inputs'!O27,IF(OR('DealScope monthly model and pri'!M5="",'Model inputs'!O27=""),"",'DealScope monthly model and pri'!M5>='Model inputs'!O27))),IF('Model inputs'!O26="","",'Model inputs'!O26),0)="",0,IF(IF(IF(ISERROR('DealScope monthly model and pri'!M5>='Model inputs'!O27),'DealScope monthly model and pri'!M5>='Model inputs'!O27,IF(OR('DealScope monthly model and pri'!M5="",'Model inputs'!O27=""),"",'DealScope monthly model and pri'!M5>='Model inputs'!O27))="",FALSE,IF(ISERROR('DealScope monthly model and pri'!M5>='Model inputs'!O27),'DealScope monthly model and pri'!M5>='Model inputs'!O27,IF(OR('DealScope monthly model and pri'!M5="",'Model inputs'!O27=""),"",'DealScope monthly model and pri'!M5>='Model inputs'!O27))),IF('Model inputs'!O26="","",'Model inputs'!O26),0)) -> 1250
A9: Audits delivered | B9: ="" | C9: ="" | D9: ="" | E9: ="" | F9: ="" | G9: ="" | H9: ="" | I9: ="" | ... M9: =""
A10: Annual deal-team | B10: ='DealScope monthly model and pri'!B6*'Model inputs'!O31 -> 15 | C10: ='DealScope monthly model and pri'!C6*'Model inputs'!O31 -> 15 | D10: ='DealScope monthly model and pri'!D6*'Model inputs'!O31 -> 15 | E10: ='DealScope monthly model and pri'!E6*'Model inputs'!O31 -> 15 | F10: ='DealScope monthly model and pri'!F6*'Model inputs'!O31 -> 15 | G10: ='DealScope monthly model and pri'!G6*'Model inputs'!O31 -> 15 | H10: ='DealScope monthly model and pri'!H6*'Model inputs'!O31 -> 15 | I10: ='DealScope monthly model and pri'!I6*'Model inputs'!O31 -> 15 | J10: ='DealScope monthly model and pri'!J6*'Model inputs'!O31 -> 15 | K10: ='DealScope monthly model and pri'!K6*'Model inputs'!O31 -> 15 | L10: ='DealScope monthly model and pri'!L6*'Model inputs'!O31 -> 15 | M10: ='DealScope monthly model and pri'!M6*'Model inputs'!O31 -> 15
A11: Hybrid | B11: ='DealScope monthly model and pri'!B6*'Model inputs'!O32 -> 15 | C11: ='DealScope monthly model and pri'!C6*'Model inputs'!O32 -> 15 | D11: ='DealScope monthly model and pri'!D6*'Model inputs'!O32 -> 15 | E11: ='DealScope monthly model and pri'!E6*'Model inputs'!O32 -> 15 | F11: ='DealScope monthly model and pri'!F6*'Model inputs'!O32 -> 15 | G11: ='DealScope monthly model and pri'!G6*'Model inputs'!O32 -> 15 | H11: ='DealScope monthly model and pri'!H6*'Model inputs'!O32 -> 15 | I11: ='DealScope monthly model and pri'!I6*'Model inputs'!O32 -> 15 | J11: ='DealScope monthly model and pri'!J6*'Model inputs'!O32 -> 15 | K11: ='DealScope monthly model and pri'!K6*'Model inputs'!O32 -> 15 | L11: ='DealScope monthly model and pri'!L6*'Model inputs'!O32 -> 15 | M11: ='DealScope monthly model and pri'!M6*'Model inputs'!O32 -> 15
A12: Per audit — base | B12: ='DealScope monthly model and pri'!B6*'Model inputs'!O33 -> 15 | C12: ='DealScope monthly model and pri'!C6*'Model inputs'!O33 -> 15 | D12: ='DealScope monthly model and pri'!D6*'Model inputs'!O33 -> 15 | E12: ='DealScope monthly model and pri'!E6*'Model inputs'!O33 -> 15 | F12: ='DealScope monthly model and pri'!F6*'Model inputs'!O33 -> 15 | G12: ='DealScope monthly model and pri'!G6*'Model inputs'!O33 -> 15 | H12: ='DealScope monthly model and pri'!H6*'Model inputs'!O33 -> 15 | I12: ='DealScope monthly model and pri'!I6*'Model inputs'!O33 -> 15 | J12: ='DealScope monthly model and pri'!J6*'Model inputs'!O33 -> 15 | K12: ='DealScope monthly model and pri'!K6*'Model inputs'!O33 -> 15 | L12: ='DealScope monthly model and pri'!L6*'Model inputs'!O33 -> 15 | M12: ='DealScope monthly model and pri'!M6*'Model inputs'!O33 -> 15
A13: Per audit — high | B13: ='DealScope monthly model and pri'!B6*'Model inputs'!O34 -> 15 | C13: ='DealScope monthly model and pri'!C6*'Model inputs'!O34 -> 15 | D13: ='DealScope monthly model and pri'!D6*'Model inputs'!O34 -> 15 | E13: ='DealScope monthly model and pri'!E6*'Model inputs'!O34 -> 15 | F13: ='DealScope monthly model and pri'!F6*'Model inputs'!O34 -> 15 | G13: ='DealScope monthly model and pri'!G6*'Model inputs'!O34 -> 15 | H13: ='DealScope monthly model and pri'!H6*'Model inputs'!O34 -> 15 | I13: ='DealScope monthly model and pri'!I6*'Model inputs'!O34 -> 15 | J13: ='DealScope monthly model and pri'!J6*'Model inputs'!O34 -> 15 | K13: ='DealScope monthly model and pri'!K6*'Model inputs'!O34 -> 15 | L13: ='DealScope monthly model and pri'!L6*'Model inputs'!O34 -> 15 | M13: ='DealScope monthly model and pri'!M6*'Model inputs'!O34 -> 15
A14: Per audit — low | B14: ='DealScope monthly model and pri'!B6*'Model inputs'!O35 -> 15 | C14: ='DealScope monthly model and pri'!C6*'Model inputs'!O35 -> 15 | D14: ='DealScope monthly model and pri'!D6*'Model inputs'!O35 -> 15 | E14: ='DealScope monthly model and pri'!E6*'Model inputs'!O35 -> 15 | F14: ='DealScope monthly model and pri'!F6*'Model inputs'!O35 -> 15 | G14: ='DealScope monthly model and pri'!G6*'Model inputs'!O35 -> 15 | H14: ='DealScope monthly model and pri'!H6*'Model inputs'!O35 -> 15 | I14: ='DealScope monthly model and pri'!I6*'Model inputs'!O35 -> 15 | J14: ='DealScope monthly model and pri'!J6*'Model inputs'!O35 -> 15 | K14: ='DealScope monthly model and pri'!K6*'Model inputs'!O35 -> 15 | L14: ='DealScope monthly model and pri'!L6*'Model inputs'!O35 -> 15 | M14: ='DealScope monthly model and pri'!M6*'Model inputs'!O35 -> 15
A15: Earned revenue | B15: ="" | C15: ="" | D15: ="" | E15: ="" | F15: ="" | G15: ="" | H15: ="" | I15: ="" | ... M15: =""
A16: Annual deal-team | B16: ='DealScope monthly model and pri'!B6*'Model inputs'!O37 -> 15000 | C16: ='DealScope monthly model and pri'!C6*'Model inputs'!O37 -> 15000 | D16: ='DealScope monthly model and pri'!D6*'Model inputs'!O37 -> 15000 | E16: ='DealScope monthly model and pri'!E6*'Model inputs'!O37 -> 15000 | F16: ='DealScope monthly model and pri'!F6*'Model inputs'!O37 -> 15000 | G16: ='DealScope monthly model and pri'!G6*'Model inputs'!O37 -> 15000 | H16: ='DealScope monthly model and pri'!H6*'Model inputs'!O37 -> 15000 | I16: ='DealScope monthly model and pri'!I6*'Model inputs'!O37 -> 15000 | J16: ='DealScope monthly model and pri'!J6*'Model inputs'!O37 -> 15000 | K16: ='DealScope monthly model and pri'!K6*'Model inputs'!O37 -> 15000 | L16: ='DealScope monthly model and pri'!L6*'Model inputs'!O37 -> 15000 | M16: ='DealScope monthly model and pri'!M6*'Model inputs'!O37 -> 15000
A17: Hybrid | B17: ='DealScope monthly model and pri'!B6*'Model inputs'!O38 -> 17500 | C17: ='DealScope monthly model and pri'!C6*'Model inputs'!O38 -> 17500 | D17: ='DealScope monthly model and pri'!D6*'Model inputs'!O38 -> 17500 | E17: ='DealScope monthly model and pri'!E6*'Model inputs'!O38 -> 17500 | F17: ='DealScope monthly model and pri'!F6*'Model inputs'!O38 -> 17500 | G17: ='DealScope monthly model and pri'!G6*'Model inputs'!O38 -> 17500 | H17: ='DealScope monthly model and pri'!H6*'Model inputs'!O38 -> 17500 | I17: ='DealScope monthly model and pri'!I6*'Model inputs'!O38 -> 17500 | J17: ='DealScope monthly model and pri'!J6*'Model inputs'!O38 -> 17500 | K17: ='DealScope monthly model and pri'!K6*'Model inputs'!O38 -> 17500 | L17: ='DealScope monthly model and pri'!L6*'Model inputs'!O38 -> 17500 | M17: ='DealScope monthly model and pri'!M6*'Model inputs'!O38 -> 17500
A18: Per audit — base | B18: ='DealScope monthly model and pri'!B6*'Model inputs'!O39 -> 22500 | C18: ='DealScope monthly model and pri'!C6*'Model inputs'!O39 -> 22500 | D18: ='DealScope monthly model and pri'!D6*'Model inputs'!O39 -> 22500 | E18: ='DealScope monthly model and pri'!E6*'Model inputs'!O39 -> 22500 | F18: ='DealScope monthly model and pri'!F6*'Model inputs'!O39 -> 22500 | G18: ='DealScope monthly model and pri'!G6*'Model inputs'!O39 -> 22500 | H18: ='DealScope monthly model and pri'!H6*'Model inputs'!O39 -> 22500 | I18: ='DealScope monthly model and pri'!I6*'Model inputs'!O39 -> 22500 | J18: ='DealScope monthly model and pri'!J6*'Model inputs'!O39 -> 22500 | K18: ='DealScope monthly model and pri'!K6*'Model inputs'!O39 -> 22500 | L18: ='DealScope monthly model and pri'!L6*'Model inputs'!O39 -> 22500 | M18: ='DealScope monthly model and pri'!M6*'Model inputs'!O39 -> 22500
A19: Per audit — high | B19: ='DealScope monthly model and pri'!B6*'Model inputs'!O40 -> 45000 | C19: ='DealScope monthly model and pri'!C6*'Model inputs'!O40 -> 45000 | D19: ='DealScope monthly model and pri'!D6*'Model inputs'!O40 -> 45000 | E19: ='DealScope monthly model and pri'!E6*'Model inputs'!O40 -> 45000 | F19: ='DealScope monthly model and pri'!F6*'Model inputs'!O40 -> 45000 | G19: ='DealScope monthly model and pri'!G6*'Model inputs'!O40 -> 45000 | H19: ='DealScope monthly model and pri'!H6*'Model inputs'!O40 -> 45000 | I19: ='DealScope monthly model and pri'!I6*'Model inputs'!O40 -> 45000 | J19: ='DealScope monthly model and pri'!J6*'Model inputs'!O40 -> 45000 | K19: ='DealScope monthly model and pri'!K6*'Model inputs'!O40 -> 45000 | L19: ='DealScope monthly model and pri'!L6*'Model inputs'!O40 -> 45000 | M19: ='DealScope monthly model and pri'!M6*'Model inputs'!O40 -> 45000
A20: Per audit — low | B20: ='DealScope monthly model and pri'!B6*'Model inputs'!O41 -> 11250 | C20: ='DealScope monthly model and pri'!C6*'Model inputs'!O41 -> 11250 | D20: ='DealScope monthly model and pri'!D6*'Model inputs'!O41 -> 11250 | E20: ='DealScope monthly model and pri'!E6*'Model inputs'!O41 -> 11250 | F20: ='DealScope monthly model and pri'!F6*'Model inputs'!O41 -> 11250 | G20: ='DealScope monthly model and pri'!G6*'Model inputs'!O41 -> 11250 | H20: ='DealScope monthly model and pri'!H6*'Model inputs'!O41 -> 11250 | I20: ='DealScope monthly model and pri'!I6*'Model inputs'!O41 -> 11250 | J20: ='DealScope monthly model and pri'!J6*'Model inputs'!O41 -> 11250 | K20: ='DealScope monthly model and pri'!K6*'Model inputs'!O41 -> 11250 | L20: ='DealScope monthly model and pri'!L6*'Model inputs'!O41 -> 11250 | M20: ='DealScope monthly model and pri'!M6*'Model inputs'!O41 -> 11250
A21: Cash collections | B21: ="" | C21: ="" | D21: ="" | E21: ="" | F21: ="" | G21: ="" | H21: ="" | I21: ="" | ... M21: =""
A22: Annual deal-team | B22: ='DealScope monthly model and pri'!B7*'Model inputs'!O88*(1-'Model inputs'!O78)+'DealScope monthly model and pri'!B16-'DealScope monthly model and pri'!B6*'Model inputs'!O88/12*(1-'Model inputs'!O78) -> 125000 | C22: ='DealScope monthly model and pri'!C7*'Model inputs'!O88*(1-'Model inputs'!O78)+'DealScope monthly model and pri'!C16-'DealScope monthly model and pri'!C6*'Model inputs'!O88/12*(1-'Model inputs'!O78) -> 5000 | D22: ='DealScope monthly model and pri'!D7*'Model inputs'!O88*(1-'Model inputs'!O78)+'DealScope monthly model and pri'!D16-'DealScope monthly model and pri'!D6*'Model inputs'!O88/12*(1-'Model inputs'!O78) -> 5000 | E22: ='DealScope monthly model and pri'!E7*'Model inputs'!O88*(1-'Model inputs'!O78)+'DealScope monthly model and pri'!E16-'DealScope monthly model and pri'!E6*'Model inputs'!O88/12*(1-'Model inputs'!O78) -> 5000 | F22: ='DealScope monthly model and pri'!F7*'Model inputs'!O88*(1-'Model inputs'!O78)+'DealScope monthly model and pri'!F16-'DealScope monthly model and pri'!F6*'Model inputs'!O88/12*(1-'Model inputs'!O78) -> 5000 | G22: ='DealScope monthly model and pri'!G7*'Model inputs'!O88*(1-'Model inputs'!O78)+'DealScope monthly model and pri'!G16-'DealScope monthly model and pri'!G6*'Model inputs'!O88/12*(1-'Model inputs'!O78) -> 5000 | H22: ='DealScope monthly model and pri'!H7*'Model inputs'!O88*(1-'Model inputs'!O78)+'DealScope monthly model and pri'!H16-'DealScope monthly model and pri'!H6*'Model inputs'!O88/12*(1-'Model inputs'!O78) -> 5000 | I22: ='DealScope monthly model and pri'!I7*'Model inputs'!O88*(1-'Model inputs'!O78)+'DealScope monthly model and pri'!I16-'DealScope monthly model and pri'!I6*'Model inputs'!O88/12*(1-'Model inputs'!O78) -> 5000 | J22: ='DealScope monthly model and pri'!J7*'Model inputs'!O88*(1-'Model inputs'!O78)+'DealScope monthly model and pri'!J16-'DealScope monthly model and pri'!J6*'Model inputs'!O88/12*(1-'Model inputs'!O78) -> 5000 | K22: ='DealScope monthly model and pri'!K7*'Model inputs'!O88*(1-'Model inputs'!O78)+'DealScope monthly model and pri'!K16-'DealScope monthly model and pri'!K6*'Model inputs'!O88/12*(1-'Model inputs'!O78) -> 5000 | L22: ='DealScope monthly model and pri'!L7*'Model inputs'!O88*(1-'Model inputs'!O78)+'DealScope monthly model and pri'!L16-'DealScope monthly model and pri'!L6*'Model inputs'!O88/12*(1-'Model inputs'!O78) -> 5000 | M22: ='DealScope monthly model and pri'!M7*'Model inputs'!O88*(1-'Model inputs'!O78)+'DealScope monthly model and pri'!M16-'DealScope monthly model and pri'!M6*'Model inputs'!O88/12*(1-'Model inputs'!O78) -> 5000
A23: Hybrid | B23: ='DealScope monthly model and pri'!B7*'Model inputs'!O89*(1-'Model inputs'!O78)+'DealScope monthly model and pri'!B17-'DealScope monthly model and pri'!B6*'Model inputs'!O89/12*(1-'Model inputs'!O78) -> 45000 | C23: ='DealScope monthly model and pri'!C7*'Model inputs'!O89*(1-'Model inputs'!O78)+'DealScope monthly model and pri'!C17-'DealScope monthly model and pri'!C6*'Model inputs'!O89/12*(1-'Model inputs'!O78) -> 15000 | D23: ='DealScope monthly model and pri'!D7*'Model inputs'!O89*(1-'Model inputs'!O78)+'DealScope monthly model and pri'!D17-'DealScope monthly model and pri'!D6*'Model inputs'!O89/12*(1-'Model inputs'!O78) -> 15000 | E23: ='DealScope monthly model and pri'!E7*'Model inputs'!O89*(1-'Model inputs'!O78)+'DealScope monthly model and pri'!E17-'DealScope monthly model and pri'!E6*'Model inputs'!O89/12*(1-'Model inputs'!O78) -> 15000 | F23: ='DealScope monthly model and pri'!F7*'Model inputs'!O89*(1-'Model inputs'!O78)+'DealScope monthly model and pri'!F17-'DealScope monthly model and pri'!F6*'Model inputs'!O89/12*(1-'Model inputs'!O78) -> 15000 | G23: ='DealScope monthly model and pri'!G7*'Model inputs'!O89*(1-'Model inputs'!O78)+'DealScope monthly model and pri'!G17-'DealScope monthly model and pri'!G6*'Model inputs'!O89/12*(1-'Model inputs'!O78) -> 15000 | H23: ='DealScope monthly model and pri'!H7*'Model inputs'!O89*(1-'Model inputs'!O78)+'DealScope monthly model and pri'!H17-'DealScope monthly model and pri'!H6*'Model inputs'!O89/12*(1-'Model inputs'!O78) -> 15000 | I23: ='DealScope monthly model and pri'!I7*'Model inputs'!O89*(1-'Model inputs'!O78)+'DealScope monthly model and pri'!I17-'DealScope monthly model and pri'!I6*'Model inputs'!O89/12*(1-'Model inputs'!O78) -> 15000 | J23: ='DealScope monthly model and pri'!J7*'Model inputs'!O89*(1-'Model inputs'!O78)+'DealScope monthly model and pri'!J17-'DealScope monthly model and pri'!J6*'Model inputs'!O89/12*(1-'Model inputs'!O78) -> 15000 | K23: ='DealScope monthly model and pri'!K7*'Model inputs'!O89*(1-'Model inputs'!O78)+'DealScope monthly model and pri'!K17-'DealScope monthly model and pri'!K6*'Model inputs'!O89/12*(1-'Model inputs'!O78) -> 15000 | L23: ='DealScope monthly model and pri'!L7*'Model inputs'!O89*(1-'Model inputs'!O78)+'DealScope monthly model and pri'!L17-'DealScope monthly model and pri'!L6*'Model inputs'!O89/12*(1-'Model inputs'!O78) -> 15000 | M23: ='DealScope monthly model and pri'!M7*'Model inputs'!O89*(1-'Model inputs'!O78)+'DealScope monthly model and pri'!M17-'DealScope monthly model and pri'!M6*'Model inputs'!O89/12*(1-'Model inputs'!O78) -> 15000
A24: Per audit — base | B24: ='DealScope monthly model and pri'!B7*'Model inputs'!O90*(1-'Model inputs'!O78)+'DealScope monthly model and pri'!B18-'DealScope monthly model and pri'!B6*'Model inputs'!O90/12*(1-'Model inputs'!O78) -> 22500 | C24: ='DealScope monthly model and pri'!C7*'Model inputs'!O90*(1-'Model inputs'!O78)+'DealScope monthly model and pri'!C18-'DealScope monthly model and pri'!C6*'Model inputs'!O90/12*(1-'Model inputs'!O78) -> 22500 | D24: ='DealScope monthly model and pri'!D7*'Model inputs'!O90*(1-'Model inputs'!O78)+'DealScope monthly model and pri'!D18-'DealScope monthly model and pri'!D6*'Model inputs'!O90/12*(1-'Model inputs'!O78) -> 22500 | E24: ='DealScope monthly model and pri'!E7*'Model inputs'!O90*(1-'Model inputs'!O78)+'DealScope monthly model and pri'!E18-'DealScope monthly model and pri'!E6*'Model inputs'!O90/12*(1-'Model inputs'!O78) -> 22500 | F24: ='DealScope monthly model and pri'!F7*'Model inputs'!O90*(1-'Model inputs'!O78)+'DealScope monthly model and pri'!F18-'DealScope monthly model and pri'!F6*'Model inputs'!O90/12*(1-'Model inputs'!O78) -> 22500 | G24: ='DealScope monthly model and pri'!G7*'Model inputs'!O90*(1-'Model inputs'!O78)+'DealScope monthly model and pri'!G18-'DealScope monthly model and pri'!G6*'Model inputs'!O90/12*(1-'Model inputs'!O78) -> 22500 | H24: ='DealScope monthly model and pri'!H7*'Model inputs'!O90*(1-'Model inputs'!O78)+'DealScope monthly model and pri'!H18-'DealScope monthly model and pri'!H6*'Model inputs'!O90/12*(1-'Model inputs'!O78) -> 22500 | I24: ='DealScope monthly model and pri'!I7*'Model inputs'!O90*(1-'Model inputs'!O78)+'DealScope monthly model and pri'!I18-'DealScope monthly model and pri'!I6*'Model inputs'!O90/12*(1-'Model inputs'!O78) -> 22500 | J24: ='DealScope monthly model and pri'!J7*'Model inputs'!O90*(1-'Model inputs'!O78)+'DealScope monthly model and pri'!J18-'DealScope monthly model and pri'!J6*'Model inputs'!O90/12*(1-'Model inputs'!O78) -> 22500 | K24: ='DealScope monthly model and pri'!K7*'Model inputs'!O90*(1-'Model inputs'!O78)+'DealScope monthly model and pri'!K18-'DealScope monthly model and pri'!K6*'Model inputs'!O90/12*(1-'Model inputs'!O78) -> 22500 | L24: ='DealScope monthly model and pri'!L7*'Model inputs'!O90*(1-'Model inputs'!O78)+'DealScope monthly model and pri'!L18-'DealScope monthly model and pri'!L6*'Model inputs'!O90/12*(1-'Model inputs'!O78) -> 22500 | M24: ='DealScope monthly model and pri'!M7*'Model inputs'!O90*(1-'Model inputs'!O78)+'DealScope monthly model and pri'!M18-'DealScope monthly model and pri'!M6*'Model inputs'!O90/12*(1-'Model inputs'!O78) -> 22500
A25: Per audit — high | B25: ='DealScope monthly model and pri'!B7*'Model inputs'!O91*(1-'Model inputs'!O78)+'DealScope monthly model and pri'!B19-'DealScope monthly model and pri'!B6*'Model inputs'!O91/12*(1-'Model inputs'!O78) -> 45000 | C25: ='DealScope monthly model and pri'!C7*'Model inputs'!O91*(1-'Model inputs'!O78)+'DealScope monthly model and pri'!C19-'DealScope monthly model and pri'!C6*'Model inputs'!O91/12*(1-'Model inputs'!O78) -> 45000 | D25: ='DealScope monthly model and pri'!D7*'Model inputs'!O91*(1-'Model inputs'!O78)+'DealScope monthly model and pri'!D19-'DealScope monthly model and pri'!D6*'Model inputs'!O91/12*(1-'Model inputs'!O78) -> 45000 | E25: ='DealScope monthly model and pri'!E7*'Model inputs'!O91*(1-'Model inputs'!O78)+'DealScope monthly model and pri'!E19-'DealScope monthly model and pri'!E6*'Model inputs'!O91/12*(1-'Model inputs'!O78) -> 45000 | F25: ='DealScope monthly model and pri'!F7*'Model inputs'!O91*(1-'Model inputs'!O78)+'DealScope monthly model and pri'!F19-'DealScope monthly model and pri'!F6*'Model inputs'!O91/12*(1-'Model inputs'!O78) -> 45000 | G25: ='DealScope monthly model and pri'!G7*'Model inputs'!O91*(1-'Model inputs'!O78)+'DealScope monthly model and pri'!G19-'DealScope monthly model and pri'!G6*'Model inputs'!O91/12*(1-'Model inputs'!O78) -> 45000 | H25: ='DealScope monthly model and pri'!H7*'Model inputs'!O91*(1-'Model inputs'!O78)+'DealScope monthly model and pri'!H19-'DealScope monthly model and pri'!H6*'Model inputs'!O91/12*(1-'Model inputs'!O78) -> 45000 | I25: ='DealScope monthly model and pri'!I7*'Model inputs'!O91*(1-'Model inputs'!O78)+'DealScope monthly model and pri'!I19-'DealScope monthly model and pri'!I6*'Model inputs'!O91/12*(1-'Model inputs'!O78) -> 45000 | J25: ='DealScope monthly model and pri'!J7*'Model inputs'!O91*(1-'Model inputs'!O78)+'DealScope monthly model and pri'!J19-'DealScope monthly model and pri'!J6*'Model inputs'!O91/12*(1-'Model inputs'!O78) -> 45000 | K25: ='DealScope monthly model and pri'!K7*'Model inputs'!O91*(1-'Model inputs'!O78)+'DealScope monthly model and pri'!K19-'DealScope monthly model and pri'!K6*'Model inputs'!O91/12*(1-'Model inputs'!O78) -> 45000 | L25: ='DealScope monthly model and pri'!L7*'Model inputs'!O91*(1-'Model inputs'!O78)+'DealScope monthly model and pri'!L19-'DealScope monthly model and pri'!L6*'Model inputs'!O91/12*(1-'Model inputs'!O78) -> 45000 | M25: ='DealScope monthly model and pri'!M7*'Model inputs'!O91*(1-'Model inputs'!O78)+'DealScope monthly model and pri'!M19-'DealScope monthly model and pri'!M6*'Model inputs'!O91/12*(1-'Model inputs'!O78) -> 45000
A26: Per audit — low | B26: ='DealScope monthly model and pri'!B7*'Model inputs'!O92*(1-'Model inputs'!O78)+'DealScope monthly model and pri'!B20-'DealScope monthly model and pri'!B6*'Model inputs'!O92/12*(1-'Model inputs'!O78) -> 11250 | C26: ='DealScope monthly model and pri'!C7*'Model inputs'!O92*(1-'Model inputs'!O78)+'DealScope monthly model and pri'!C20-'DealScope monthly model and pri'!C6*'Model inputs'!O92/12*(1-'Model inputs'!O78) -> 11250 | D26: ='DealScope monthly model and pri'!D7*'Model inputs'!O92*(1-'Model inputs'!O78)+'DealScope monthly model and pri'!D20-'DealScope monthly model and pri'!D6*'Model inputs'!O92/12*(1-'Model inputs'!O78) -> 11250 | E26: ='DealScope monthly model and pri'!E7*'Model inputs'!O92*(1-'Model inputs'!O78)+'DealScope monthly model and pri'!E20-'DealScope monthly model and pri'!E6*'Model inputs'!O92/12*(1-'Model inputs'!O78) -> 11250 | F26: ='DealScope monthly model and pri'!F7*'Model inputs'!O92*(1-'Model inputs'!O78)+'DealScope monthly model and pri'!F20-'DealScope monthly model and pri'!F6*'Model inputs'!O92/12*(1-'Model inputs'!O78) -> 11250 | G26: ='DealScope monthly model and pri'!G7*'Model inputs'!O92*(1-'Model inputs'!O78)+'DealScope monthly model and pri'!G20-'DealScope monthly model and pri'!G6*'Model inputs'!O92/12*(1-'Model inputs'!O78) -> 11250 | H26: ='DealScope monthly model and pri'!H7*'Model inputs'!O92*(1-'Model inputs'!O78)+'DealScope monthly model and pri'!H20-'DealScope monthly model and pri'!H6*'Model inputs'!O92/12*(1-'Model inputs'!O78) -> 11250 | I26: ='DealScope monthly model and pri'!I7*'Model inputs'!O92*(1-'Model inputs'!O78)+'DealScope monthly model and pri'!I20-'DealScope monthly model and pri'!I6*'Model inputs'!O92/12*(1-'Model inputs'!O78) -> 11250 | J26: ='DealScope monthly model and pri'!J7*'Model inputs'!O92*(1-'Model inputs'!O78)+'DealScope monthly model and pri'!J20-'DealScope monthly model and pri'!J6*'Model inputs'!O92/12*(1-'Model inputs'!O78) -> 11250 | K26: ='DealScope monthly model and pri'!K7*'Model inputs'!O92*(1-'Model inputs'!O78)+'DealScope monthly model and pri'!K20-'DealScope monthly model and pri'!K6*'Model inputs'!O92/12*(1-'Model inputs'!O78) -> 11250 | L26: ='DealScope monthly model and pri'!L7*'Model inputs'!O92*(1-'Model inputs'!O78)+'DealScope monthly model and pri'!L20-'DealScope monthly model and pri'!L6*'Model inputs'!O92/12*(1-'Model inputs'!O78) -> 11250 | M26: ='DealScope monthly model and pri'!M7*'Model inputs'!O92*(1-'Model inputs'!O78)+'DealScope monthly model and pri'!M20-'DealScope monthly model and pri'!M6*'Model inputs'!O92/12*(1-'Model inputs'!O78) -> 11250
A27: Delivery COGS | B27: ="" | C27: ="" | D27: ="" | E27: ="" | F27: ="" | G27: ="" | H27: ="" | I27: ="" | ... M27: =""
